<?xml version="1.0" ?>
<!-- =================================================================================== -->
<!-- |    This document was autogenerated by xacro from /home/ccs/ros2/teleop_ws/install/robot_description/share/robot_description/urdf/robot.xacro | -->
<!-- |    EDITING THIS FILE BY HAND IS NOT RECOMMENDED                                 | -->
<!-- =================================================================================== -->
<robot name="robot">
  <mujoco>
    <compiler meshdir="../.." discardvisual="false" strippath="false"/>
  </mujoco>
  <link name="main_base_link"/>
  <!-- This URDF was automatically created by SolidWorks to URDF Exporter! Originally created by Stephen Brawner (brawner@gmail.com) 
     Commit Version: 1.5.1-0-g916b5db  Build Version: 1.5.7152.31018
     For more information, please see http://wiki.ros.org/sw_urdf_exporter -->
  <link name="Base_L">
    <inertial>
      <origin rpy="0 0 0" xyz="0.00032267 4.798E-05 0.04066353"/>
      <mass value="1.1962"/>
      <inertia ixx="0.00107329" ixy="-1.68E-06" ixz="-1.05E-05" iyy="0.00107003" iyz="-3.43E-06" izz="0.00127315"/>
    </inertial>
    <visual>
      <origin rpy="0 0 0" xyz="0 0 0"/>
      <geometry>
        <mesh filename="marvin_description/meshes/left/Base_L.STL"/>
      </geometry>
      <material name="">
        <color rgba="1 0 0 1"/>
      </material>
    </visual>
    <collision>
      <origin rpy="0 0 0" xyz="0 0 0"/>
      <geometry>
        <mesh filename="marvin_description/meshes/left/Base_L.STL"/>
      </geometry>
    </collision>
  </link>
  <link name="Link1_L">
    <inertial>
      <origin rpy="0 0 0" xyz="0.00002347 0.00557150 -0.03075998"/>
      <mass value="1.9705"/>
      <inertia ixx="0.00492293" ixy="0.00000550" ixz="0.00000193" iyy="0.00526513" iyz="0.00033232" izz="0.00188107"/>
    </inertial>
    <visual>
      <origin rpy="0 0 0" xyz="0 0 0"/>
      <geometry>
        <mesh filename="marvin_description/meshes/left/Link1_L.STL"/>
      </geometry>
      <material name="">
        <color rgba="0 1 0 1"/>
      </material>
    </visual>
    <collision>
      <origin rpy="0 0 0" xyz="0 0 0"/>
      <geometry>
        <mesh filename="marvin_description/meshes/left/Link1_L.STL"/>
      </geometry>
    </collision>
  </link>
  <joint name="Joint1_L" type="revolute">
    <origin rpy="0 0 0" xyz="0 0 0.1745"/>
    <parent link="Base_L"/>
    <child link="Link1_L"/>
    <axis xyz="0 0 1"/>
    <limit effort="108" lower="-3.1067" upper="3.1067" velocity="3.1416"/>
  </joint>
  <link name="Link2_L">
    <inertial>
      <origin rpy="0 0 0" xyz="0.00013483 0.06170460 0.00950639"/>
      <mass value="2.24398"/>
      <inertia ixx="0.01194933" ixy="0.00000336" ixz="0.00000091" iyy="0.00361581" iyz="-0.00132804" izz="0.01098356"/>
    </inertial>
    <visual>
      <origin rpy="0 0 0" xyz="0 0 0"/>
      <geometry>
        <mesh filename="marvin_description/meshes/left/Link2_L.STL"/>
      </geometry>
      <material name="">
        <color rgba="0 0 1 1"/>
      </material>
    </visual>
    <collision>
      <origin rpy="0 0 0" xyz="0 0 0"/>
      <geometry>
        <mesh filename="marvin_description/meshes/left/Link2_L.STL"/>
      </geometry>
    </collision>
  </link>
  <joint name="Joint2_L" type="revolute">
    <origin rpy="1.5708 0 0" xyz="0 0 0"/>
    <parent link="Link1_L"/>
    <child link="Link2_L"/>
    <axis xyz="0 0 1"/>
    <limit effort="108" lower="-2.0944" upper="2.0944" velocity="3.1416"/>
  </joint>
  <link name="Link3_L">
    <inertial>
      <origin rpy="0 0 0" xyz="0.00968562 0.00246599 -0.04627302"/>
      <mass value="1.9242"/>
      <inertia ixx="0.00718224" ixy="0.00004413" ixz="0.00089552" iyy="0.00762563" iyz="0.00022096" izz="0.00178597"/>
    </inertial>
    <visual>
      <origin rpy="0 0 0" xyz="0 0 0"/>
      <geometry>
        <mesh filename="marvin_description/meshes/left/Link3_L.STL"/>
      </geometry>
      <material name="">
        <color rgba="1 0 0 1"/>
      </material>
    </visual>
    <collision>
      <origin rpy="0 0 0" xyz="0 0 0"/>
      <geometry>
        <mesh filename="marvin_description/meshes/left/Link3_L.STL"/>
      </geometry>
    </collision>
  </link>
  <joint name="Joint3_L" type="revolute">
    <origin rpy="-1.5708 0 0" xyz="0 0.287 0"/>
    <parent link="Link2_L"/>
    <child link="Link3_L"/>
    <axis xyz="0 0 1"/>
    <limit effort="66" lower="-3.1067" upper="3.1067" velocity="3.1416"/>
  </joint>
  <link name="Link4_L">
    <inertial>
      <origin rpy="0 0 0" xyz="0.00850411 -0.04718223 0.00941509"/>
      <mass value="1.6085"/>
      <inertia ixx="0.00580480" ixy="-0.00066669" ixz="-0.00012722" iyy="0.00223807" iyz="0.00070523" izz="0.00533060"/>
    </inertial>
    <visual>
      <origin rpy="0 0 0" xyz="0 0 0"/>
      <geometry>
        <mesh filename="marvin_description/meshes/left/Link4_L.STL"/>
      </geometry>
      <material name="">
        <color rgba="0 1 0 1"/>
      </material>
    </visual>
    <collision>
      <origin rpy="0 0 0" xyz="0 0 0"/>
      <geometry>
        <mesh filename="marvin_description/meshes/left/Link4_L.STL"/>
      </geometry>
    </collision>
  </link>
  <joint name="Joint4_L" type="revolute">
    <origin rpy="-1.5708 0 3.1416" xyz="0.018 0 0"/>
    <parent link="Link3_L"/>
    <child link="Link4_L"/>
    <axis xyz="0 0 1"/>
    <limit effort="66" lower="-2.5307" upper="1.0472" velocity="3.1416"/>
  </joint>
  <link name="Link5_L">
    <inertial>
      <origin rpy="0 0 0" xyz="0.00051127 0.00101064 -0.11271739"/>
      <mass value="2.0883"/>
      <inertia ixx="0.00626603" ixy="0.00004009" ixz="0.00005338" iyy="0.00564387" iyz="-0.00006193" izz="0.00243632"/>
    </inertial>
    <visual>
      <origin rpy="0 0 0" xyz="0 0 0"/>
      <geometry>
        <mesh filename="marvin_description/meshes/left/Link5_L.STL"/>
      </geometry>
      <material name="">
        <color rgba="0 0 1 1"/>
      </material>
    </visual>
    <collision>
      <origin rpy="0 0 0" xyz="0 0 0"/>
      <geometry>
        <mesh filename="marvin_description/meshes/left/Link5_L.STL"/>
      </geometry>
    </collision>
  </link>
  <joint name="Joint5_L" type="revolute">
    <origin rpy="-1.5708 0 3.1416" xyz="0.018 -0.314 0"/>
    <parent link="Link4_L"/>
    <child link="Link5_L"/>
    <axis xyz="0 0 1"/>
    <limit effort="18" lower="-3.1067" upper="3.1067" velocity="3.1416"/>
  </joint>
  <link name="Link6_L">
    <inertial>
      <origin rpy="0 0 0" xyz="0.00032659 0.00531336 -0.00030182"/>
      <mass value="0.72496"/>
      <inertia ixx="0.00046040" ixy="0.00000189" ixz="0.00000083" iyy="0.00051716" iyz="-0.00000346" izz="0.00042521"/>
    </inertial>
    <visual>
      <origin rpy="0 0 0" xyz="0 0 0"/>
      <geometry>
        <mesh filename="marvin_description/meshes/left/Link6_L.STL"/>
      </geometry>
      <material name="">
        <color rgba="1 0 0 1"/>
      </material>
    </visual>
    <collision>
      <origin rpy="0 0 0" xyz="0 0 0"/>
      <geometry>
        <mesh filename="marvin_description/meshes/left/Link6_L.STL"/>
      </geometry>
    </collision>
  </link>
  <joint name="Joint6_L" type="revolute">
    <origin rpy="1.5708 -1.5708 0" xyz="0 0 0"/>
    <parent link="Link5_L"/>
    <child link="Link6_L"/>
    <axis xyz="0 0 1"/>
    <limit effort="18" lower="-1.0472" upper="1.0472" velocity="3.1416"/>
  </joint>
  <link name="Link7_L">
    <inertial>
      <origin rpy="0 0 0" xyz="-0.00009108 -0.03153255 0.00889371"/>
      <mass value="0.68606"/>
      <inertia ixx="0.00173687" ixy="-0.00000345" ixz="-0.00000116" iyy="0.00089035" iyz="0.00030680" izz="0.00139406"/>
    </inertial>
    <visual>
      <origin rpy="0 0 0" xyz="0 0 0"/>
      <geometry>
        <mesh filename="marvin_description/meshes/left/Link7_L.STL"/>
      </geometry>
      <material name="">
        <color rgba="0 1 0 1"/>
      </material>
    </visual>
    <collision>
      <origin rpy="0 0 0" xyz="0 0 0"/>
      <geometry>
        <mesh filename="marvin_description/meshes/left/Link7_L.STL"/>
      </geometry>
    </collision>
  </link>
  <joint name="Joint7_L" type="revolute">
    <origin rpy="1.5708 -1.5708 0" xyz="0 0 0"/>
    <parent link="Link6_L"/>
    <child link="Link7_L"/>
    <axis xyz="0 0 1"/>
    <limit effort="18" lower="-1.5708" upper="1.5708" velocity="3.1416"/>
  </joint>
  <!-- This URDF was automatically created by SolidWorks to URDF Exporter! Originally created by Stephen Brawner (brawner@gmail.com) 
     Commit Version: 1.5.1-0-g916b5db  Build Version: 1.5.7152.31018
     For more information, please see http://wiki.ros.org/sw_urdf_exporter -->
  <link name="Base_R">
    <inertial>
      <origin rpy="0 0 0" xyz="0.00032267 4.798E-05 0.04066353"/>
      <mass value="1.1962"/>
      <inertia ixx="0.00107329" ixy="-1.68E-06" ixz="-1.05E-05" iyy="0.00107003" iyz="-3.43E-06" izz="0.00127315"/>
    </inertial>
    <visual>
      <origin rpy="0 0 0" xyz="0 0 0"/>
      <geometry>
        <mesh filename="marvin_description/meshes/right/Base_R.STL"/>
      </geometry>
      <material name="">
        <color rgba="1 0 0 1"/>
      </material>
    </visual>
    <collision>
      <origin rpy="0 0 0" xyz="0 0 0"/>
      <geometry>
        <mesh filename="marvin_description/meshes/right/Base_R.STL"/>
      </geometry>
    </collision>
  </link>
  <link name="Link1_R">
    <inertial>
      <origin rpy="0 0 0" xyz="0.00002347 0.00557150 -0.03075998"/>
      <mass value="1.9705"/>
      <inertia ixx="0.00492293" ixy="0.00000550" ixz="0.00000193" iyy="0.00526513" iyz="0.00033232" izz="0.00188107"/>
    </inertial>
    <visual>
      <origin rpy="0 0 0" xyz="0 0 0"/>
      <geometry>
        <mesh filename="marvin_description/meshes/right/Link1_R.STL"/>
      </geometry>
      <material name="">
        <color rgba="0 1 0 1"/>
      </material>
    </visual>
    <collision>
      <origin rpy="0 0 0" xyz="0 0 0"/>
      <geometry>
        <mesh filename="marvin_description/meshes/right/Link1_R.STL"/>
      </geometry>
    </collision>
  </link>
  <joint name="Joint1_R" type="revolute">
    <origin rpy="0 0 0" xyz="0 0 0.1745"/>
    <parent link="Base_R"/>
    <child link="Link1_R"/>
    <axis xyz="0 0 1"/>
    <limit effort="108" lower="-3.1067" upper="3.1067" velocity="3.1416"/>
  </joint>
  <link name="Link2_R">
    <inertial>
      <origin rpy="0 0 0" xyz="0.00013483 0.06170460 0.00950639"/>
      <mass value="2.24398"/>
      <inertia ixx="0.01194933" ixy="0.00000336" ixz="0.00000091" iyy="0.00361581" iyz="-0.00132804" izz="0.01098356"/>
    </inertial>
    <visual>
      <origin rpy="0 0 0" xyz="0 0 0"/>
      <geometry>
        <mesh filename="marvin_description/meshes/right/Link2_R.STL"/>
      </geometry>
      <material name="">
        <color rgba="0 0 1 1"/>
      </material>
    </visual>
    <collision>
      <origin rpy="0 0 0" xyz="0 0 0"/>
      <geometry>
        <mesh filename="marvin_description/meshes/right/Link2_R.STL"/>
      </geometry>
    </collision>
  </link>
  <joint name="Joint2_R" type="revolute">
    <origin rpy="1.5708 0 0" xyz="0 0 0"/>
    <parent link="Link1_R"/>
    <child link="Link2_R"/>
    <axis xyz="0 0 1"/>
    <limit effort="108" lower="-2.0944" upper="2.0944" velocity="3.1416"/>
  </joint>
  <link name="Link3_R">
    <inertial>
      <origin rpy="0 0 0" xyz="0.00968562 0.00246599 -0.04627302"/>
      <mass value="1.9242"/>
      <inertia ixx="0.00718224" ixy="0.00004413" ixz="0.00089552" iyy="0.00762563" iyz="0.00022096" izz="0.00178597"/>
    </inertial>
    <visual>
      <origin rpy="0 0 0" xyz="0 0 0"/>
      <geometry>
        <mesh filename="marvin_description/meshes/right/Link3_R.STL"/>
      </geometry>
      <material name="">
        <color rgba="1 0 0 1"/>
      </material>
    </visual>
    <collision>
      <origin rpy="0 0 0" xyz="0 0 0"/>
      <geometry>
        <mesh filename="marvin_description/meshes/right/Link3_R.STL"/>
      </geometry>
    </collision>
  </link>
  <joint name="Joint3_R" type="revolute">
    <origin rpy="-1.5708 0 0" xyz="0 0.287 0"/>
    <parent link="Link2_R"/>
    <child link="Link3_R"/>
    <axis xyz="0 0 1"/>
    <limit effort="66" lower="-3.1067" upper="3.1067" velocity="3.1416"/>
  </joint>
  <link name="Link4_R">
    <inertial>
      <origin rpy="0 0 0" xyz="0.00850411 -0.04718223 0.00941509"/>
      <mass value="1.6085"/>
      <inertia ixx="0.00580480" ixy="-0.00066669" ixz="-0.00012722" iyy="0.00223807" iyz="0.00070523" izz="0.00533060"/>
    </inertial>
    <visual>
      <origin rpy="0 0 0" xyz="0 0 0"/>
      <geometry>
        <mesh filename="marvin_description/meshes/right/Link4_R.STL"/>
      </geometry>
      <material name="">
        <color rgba="0 1 0 1"/>
      </material>
    </visual>
    <collision>
      <origin rpy="0 0 0" xyz="0 0 0"/>
      <geometry>
        <mesh filename="marvin_description/meshes/right/Link4_R.STL"/>
      </geometry>
    </collision>
  </link>
  <joint name="Joint4_R" type="revolute">
    <origin rpy="-1.5708 0 3.1416" xyz="0.018 0 0"/>
    <parent link="Link3_R"/>
    <child link="Link4_R"/>
    <axis xyz="0 0 1"/>
    <limit effort="66" lower="-2.5307" upper="1.0472" velocity="3.1416"/>
  </joint>
  <link name="Link5_R">
    <inertial>
      <origin rpy="0 0 0" xyz="-0.00051127 -0.00101064 -0.11271739"/>
      <mass value="2.0883"/>
      <inertia ixx="0.00626603" ixy="0.00004009" ixz="-0.00005338" iyy="0.00564387" iyz="0.00006193" izz="0.00243632"/>
    </inertial>
    <visual>
      <origin rpy="0 0 0" xyz="0 0 0"/>
      <geometry>
        <mesh filename="marvin_description/meshes/right/Link5_R.STL"/>
      </geometry>
      <material name="">
        <color rgba="0 0 1 1"/>
      </material>
    </visual>
    <collision>
      <origin rpy="0 0 0" xyz="0 0 0"/>
      <geometry>
        <mesh filename="marvin_description/meshes/right/Link5_R.STL"/>
      </geometry>
    </collision>
  </link>
  <joint name="Joint5_R" type="revolute">
    <origin rpy="-1.5708 0 3.1416" xyz="0.018 -0.314 0"/>
    <parent link="Link4_R"/>
    <child link="Link5_R"/>
    <axis xyz="0 0 1"/>
    <limit effort="18" lower="-3.1067" upper="3.1067" velocity="3.1416"/>
  </joint>
  <link name="Link6_R">
    <inertial>
      <origin rpy="0 0 0" xyz="0.00032659 -0.00531336 0.00030182"/>
      <mass value="0.72496"/>
      <inertia ixx="0.00046040" ixy="-0.00000189" ixz="-0.00000083" iyy="0.00051716" iyz="-0.00000346" izz="0.00042521"/>
    </inertial>
    <visual>
      <origin rpy="0 0 0" xyz="0 0 0"/>
      <geometry>
        <mesh filename="marvin_description/meshes/right/Link6_R.STL"/>
      </geometry>
      <material name="">
        <color rgba="1 0 0 1"/>
      </material>
    </visual>
    <collision>
      <origin rpy="0 0 0" xyz="0 0 0"/>
      <geometry>
        <mesh filename="marvin_description/meshes/right/Link6_R.STL"/>
      </geometry>
    </collision>
  </link>
  <joint name="Joint6_R" type="revolute">
    <origin rpy="1.5708 -1.5708 0" xyz="0 0 0"/>
    <parent link="Link5_R"/>
    <child link="Link6_R"/>
    <axis xyz="0 0 1"/>
    <limit effort="18" lower="-1.0472" upper="1.0472" velocity="3.1416"/>
  </joint>
  <link name="Link7_R">
    <inertial>
      <origin rpy="0 0 0" xyz="-0.00009108 -0.03153255 0.00889371"/>
      <mass value="0.68606"/>
      <inertia ixx="0.00173687" ixy="-0.00000345" ixz="-0.00000116" iyy="0.00089035" iyz="0.00030680" izz="0.00139406"/>
    </inertial>
    <visual>
      <origin rpy="0 0 0" xyz="0 0 0"/>
      <geometry>
        <mesh filename="marvin_description/meshes/right/Link7_R.STL"/>
      </geometry>
      <material name="">
        <color rgba="0 1 0 1"/>
      </material>
    </visual>
    <collision>
      <origin rpy="0 0 0" xyz="0 0 0"/>
      <geometry>
        <mesh filename="marvin_description/meshes/right/Link7_R.STL"/>
      </geometry>
    </collision>
  </link>
  <joint name="Joint7_R" type="revolute">
    <origin rpy="1.5708 -1.5708 0" xyz="0 0 0"/>
    <parent link="Link6_R"/>
    <child link="Link7_R"/>
    <axis xyz="0 0 1"/>
    <limit effort="18" lower="-1.5708" upper="1.5708" velocity="3.1416"/>
  </joint>
  <!-- This URDF was automatically created by SolidWorks to URDF Exporter! Originally created by Stephen Brawner (brawner@gmail.com) 
     Commit Version: 1.6.0-4-g7f85cfe  Build Version: 1.6.7995.38578
     For more information, please see http://wiki.ros.org/sw_urdf_exporter -->
  <link name="left_palm_link">
    <inertial>
      <origin rpy="0 0 0" xyz="0.001524452695 -0.002642346221 0.03766991642"/>
      <mass value="0.16914"/>
      <inertia ixx="0.00014" ixy="-2.5400000000e-06" ixz="6.9100000000e-06" iyy="9.4700000000e-05" iyz="6.6300000000e-06" izz="6.0000000000e-05"/>
    </inertial>
    <visual>
      <origin rpy="0 0 0" xyz="0 0 0"/>
      <geometry>
        <mesh filename="wuji_description/meshes/left/left_palm_link.STL"/>
      </geometry>
      <material name="">
        <color rgba="0.627450980392157 0.627450980392157 0.627450980392157 1"/>
      </material>
    </visual>
    <collision>
      <origin rpy="0 0 0" xyz="0 0 0"/>
      <geometry>
        <mesh filename="wuji_description/meshes/left/left_palm_link.STL"/>
      </geometry>
    </collision>
  </link>
  <link name="left_finger1_link1">
    <inertial>
      <origin rpy="0 0 0" xyz="-0.0024615524303357 0.00144069374200097 0.00778554348019733"/>
      <mass value="0.0075"/>
      <inertia ixx="3.2e-07" ixy="-2e-08" ixz="0.0" iyy="3e-07" iyz="4e-08" izz="2.3e-07"/>
    </inertial>
    <visual>
      <origin rpy="0 0 0" xyz="0 0 0"/>
      <geometry>
        <mesh filename="wuji_description/meshes/left/left_finger1_link1.STL"/>
      </geometry>
      <material name="">
        <color rgba="0.792156862745098 0.819607843137255 0.933333333333333 1"/>
      </material>
    </visual>
    <collision>
      <origin rpy="0 0 0" xyz="0 0 0"/>
      <geometry>
        <mesh filename="wuji_description/meshes/left/left_finger1_link1.STL"/>
      </geometry>
    </collision>
  </link>
  <joint name="left_finger1_joint1" type="revolute">
    <origin rpy="1.32802443797267 -0.371613529401197 0.730700470955738" xyz="0.00852444051536975 -0.0205754004992105 0.0287119465316217"/>
    <parent link="left_palm_link"/>
    <child link="left_finger1_link1"/>
    <axis xyz="0 1 0"/>
    <limit effort="0.4452" lower="0.0475" upper="1.6033" velocity="8.587"/>
  </joint>
  <link name="left_finger1_link2">
    <inertial>
      <origin rpy="0 0 0" xyz="0.00111963550828794 1.2422525696977e-05 0.0156635719767285"/>
      <mass value="0.0248"/>
      <inertia ixx="2.76e-06" ixy="2e-08" ixz="1e-08" iyy="2.81e-06" iyz="2e-08" izz="6.8e-07"/>
    </inertial>
    <visual>
      <origin rpy="0 0 0" xyz="0 0 0"/>
      <geometry>
        <mesh filename="wuji_description/meshes/left/left_finger1_link2.STL"/>
      </geometry>
      <material name="">
        <color rgba="0.792156862745098 0.819607843137255 0.933333333333333 1"/>
      </material>
    </visual>
    <collision>
      <origin rpy="0 0 0" xyz="0 0 0"/>
      <geometry>
        <mesh filename="wuji_description/meshes/left/left_finger1_link2.STL"/>
      </geometry>
    </collision>
  </link>
  <joint name="left_finger1_joint2" type="revolute">
    <origin rpy="0.574275022681126 -0.236773489515584 -1.80339765401539" xyz="-0.00475490019601625 0.00601913767529276 0.0141321010458163"/>
    <parent link="left_finger1_link1"/>
    <child link="left_finger1_link2"/>
    <axis xyz="0 -1 0"/>
    <limit effort="0.4259" lower="-0.1387" upper="0.9324" velocity="11.1"/>
  </joint>
  <link name="left_finger1_link3">
    <inertial>
      <origin rpy="0 0 0" xyz="0.00077454408687112 1.11938530247685e-05 0.0127700261138504"/>
      <mass value="0.0165"/>
      <inertia ixx="1.46e-06" ixy="0.0" ixz="-2e-08" iyy="1.42e-06" iyz="0.0" izz="4.5e-07"/>
    </inertial>
    <visual>
      <origin rpy="0 0 0" xyz="0 0 0"/>
      <geometry>
        <mesh filename="wuji_description/meshes/left/left_finger1_link3.STL"/>
      </geometry>
      <material name="">
        <color rgba="0.792156862745098 0.819607843137255 0.933333333333333 1"/>
      </material>
    </visual>
    <collision>
      <origin rpy="0 0 0" xyz="0 0 0"/>
      <geometry>
        <mesh filename="wuji_description/meshes/left/left_finger1_link3.STL"/>
      </geometry>
    </collision>
  </link>
  <joint name="left_finger1_joint3" type="revolute">
    <origin rpy="-0.0490494507294668 0.0173112454437048 1.90854041504522" xyz="0.000188721711752275 0.000991601088376131 0.0346635877340516"/>
    <parent link="left_finger1_link2"/>
    <child link="left_finger1_link3"/>
    <axis xyz="0 1 0"/>
    <limit effort="0.1888" lower="-0.4642" upper="1.5623" velocity="12.863"/>
  </joint>
  <link name="left_finger1_link4">
    <inertial>
      <origin rpy="0 0 0" xyz="0.00049275495992733 0.000153669063593681 0.014902599152214"/>
      <mass value="0.0165"/>
      <inertia ixx="1.18e-06" ixy="0.0" ixz="1.2e-07" iyy="1.25e-06" iyz="0.0" izz="5.1e-07"/>
    </inertial>
    <visual>
      <origin rpy="0 0 0" xyz="0 0 0"/>
      <geometry>
        <mesh filename="wuji_description/meshes/left/left_finger1_link4.STL"/>
      </geometry>
      <material name="">
        <color rgba="0.792156862745098 0.819607843137255 0.933333333333333 1"/>
      </material>
    </visual>
    <collision>
      <origin rpy="0 0 0" xyz="0 0 0"/>
      <geometry>
        <mesh filename="wuji_description/meshes/left/left_finger1_link4.STL"/>
      </geometry>
    </collision>
  </link>
  <joint name="left_finger1_joint4" type="revolute">
    <origin rpy="0 0 0" xyz="0 -0.000200000007014314 0.0294999999999978"/>
    <parent link="left_finger1_link3"/>
    <child link="left_finger1_link4"/>
    <axis xyz="0 1 0"/>
    <limit effort="0.1468" lower="-0.4699" upper="1.5568" velocity="13.578"/>
  </joint>
  <link name="left_finger1_tip_link">
    <inertial>
      <origin rpy="0 0 0" xyz="0.00049275495992732 0.00015366906359366 -0.0179109350979917"/>
      <mass value="0.0041"/>
      <inertia ixx="5.5e-07" ixy="0.0" ixz="2e-08" iyy="5.2e-07" iyz="0.0" izz="2.7e-07"/>
    </inertial>
    <visual>
      <origin rpy="0 0 0" xyz="0 0 0"/>
      <geometry>
        <mesh filename="wuji_description/meshes/left/left_finger1_tip_link.STL"/>
      </geometry>
      <material name="">
        <color rgba="0.792156862745098 0.819607843137255 0.933333333333333 1"/>
      </material>
    </visual>
    <collision>
      <origin rpy="0 0 0" xyz="0 0 0"/>
      <geometry>
        <mesh filename="wuji_description/meshes/left/left_finger1_tip_link.STL"/>
      </geometry>
    </collision>
  </link>
  <joint name="left_finger1_tip_fixed" type="fixed">
    <origin rpy="0 0 0" xyz="0 0 0.0328135342502058"/>
    <parent link="left_finger1_link4"/>
    <child link="left_finger1_tip_link"/>
  </joint>
  <link name="left_finger1_link2_softbody">
    <inertial>
      <origin rpy="0 0 0" xyz="0.00206035961741463 -0.000368007925571599 0.0130970545908327"/>
      <mass value="0.00855125947562382"/>
      <inertia ixx="1.32021792236623E-06" ixy="-5.19248324993719E-08" ixz="1.58091152460037E-07" iyy="1.27896030289614E-06" iyz="-6.78023386063668E-08" izz="1.52765436554901E-06"/>
    </inertial>
    <visual>
      <origin rpy="0 0 0" xyz="0 0 0"/>
      <geometry>
        <mesh filename="wuji_description/meshes/left/left_finger1_link2_softbody.STL"/>
      </geometry>
      <material name="">
        <color rgba="0.792156862745098 0.819607843137255 0.933333333333333 1"/>
      </material>
    </visual>
    <collision>
      <origin rpy="0 0 0" xyz="0 0 0"/>
      <geometry>
        <mesh filename="wuji_description/meshes/left/left_finger1_link2_softbody.STL"/>
      </geometry>
    </collision>
  </link>
  <joint name="left_finger1_joint2_softbody" type="fixed">
    <origin rpy="0 0 0" xyz="0 0 0"/>
    <parent link="left_finger1_link2"/>
    <child link="left_finger1_link2_softbody"/>
  </joint>
  <link name="left_finger2_link1">
    <inertial>
      <origin rpy="0 0 0" xyz="-0.00132905478500867 4.18014498917985e-08 0.000320068299356491"/>
      <mass value="0.0032"/>
      <inertia ixx="8e-08" ixy="0.0" ixz="-3e-08" iyy="7e-08" iyz="0.0" izz="8e-08"/>
    </inertial>
    <visual>
      <origin rpy="0 0 0" xyz="0 0 0"/>
      <geometry>
        <mesh filename="wuji_description/meshes/left/left_finger2_link1.STL"/>
      </geometry>
      <material name="">
        <color rgba="0.792156862745098 0.819607843137255 0.933333333333333 1"/>
      </material>
    </visual>
    <collision>
      <origin rpy="0 0 0" xyz="0 0 0"/>
      <geometry>
        <mesh filename="wuji_description/meshes/left/left_finger2_link1.STL"/>
      </geometry>
    </collision>
  </link>
  <joint name="left_finger2_joint1" type="revolute">
    <origin rpy="0.110709295802648 -0.0711392445043966 0.2182248468378" xyz="-0.00587008921482409 -0.029433863280916 0.0919165306699386"/>
    <parent link="left_palm_link"/>
    <child link="left_finger2_link1"/>
    <axis xyz="0 1 0"/>
    <limit effort="0.6188" lower="-0.1585" upper="1.5604" velocity="8.203"/>
  </joint>
  <link name="left_finger2_link2">
    <inertial>
      <origin rpy="0 0 0" xyz="-1.7856494413486e-06 0.00370948408651015 0.0184836524010587"/>
      <mass value="0.033"/>
      <inertia ixx="6.31e-06" ixy="0.0" ixz="-1.6e-07" iyy="6.34e-06" iyz="0.0" izz="8.9e-07"/>
    </inertial>
    <visual>
      <origin rpy="0 0 0" xyz="0 0 0"/>
      <geometry>
        <mesh filename="wuji_description/meshes/left/left_finger2_link2.STL"/>
      </geometry>
      <material name="">
        <color rgba="0.792156862745098 0.819607843137255 0.933333333333333 1"/>
      </material>
    </visual>
    <collision>
      <origin rpy="0 0 0" xyz="0 0 0"/>
      <geometry>
        <mesh filename="wuji_description/meshes/left/left_finger2_link2.STL"/>
      </geometry>
    </collision>
  </link>
  <joint name="left_finger2_joint2" type="revolute">
    <origin rpy="0 0 1.57079631622159" xyz="0.00220000010775039 0 0.00400000569416051"/>
    <parent link="left_finger2_link1"/>
    <child link="left_finger2_link2"/>
    <axis xyz="0 1 0"/>
    <limit effort="0.1822" lower="-0.3700" upper="0.3700" velocity="8.115"/>
  </joint>
  <link name="left_finger2_link3">
    <inertial>
      <origin rpy="0 0 0" xyz="0.000341914296305118 -1.4091102688879e-05 0.0134812483075538"/>
      <mass value="0.0165"/>
      <inertia ixx="1.47e-06" ixy="0.0" ixz="3e-08" iyy="1.44e-06" iyz="0.0" izz="4.5e-07"/>
    </inertial>
    <visual>
      <origin rpy="0 0 0" xyz="0 0 0"/>
      <geometry>
        <mesh filename="wuji_description/meshes/left/left_finger2_link3.STL"/>
      </geometry>
      <material name="">
        <color rgba="0.792156862745098 0.819607843137255 0.933333333333333 1"/>
      </material>
    </visual>
    <collision>
      <origin rpy="0 0 0" xyz="0 0 0"/>
      <geometry>
        <mesh filename="wuji_description/meshes/left/left_finger2_link3.STL"/>
      </geometry>
    </collision>
  </link>
  <joint name="left_finger2_joint3" type="revolute">
    <origin rpy="0 0 -1.5705277140771" xyz="0 0.00474999943075159 0.0436176874784124"/>
    <parent link="left_finger2_link2"/>
    <child link="left_finger2_link3"/>
    <axis xyz="0 1 0"/>
    <limit effort="0.2251" lower="-0.4777" upper="1.5485" velocity="12.863"/>
  </joint>
  <link name="left_finger2_link4">
    <inertial>
      <origin rpy="0 0 0" xyz="-0.000815133126519599 -1.3528504665794e-05 0.0107846826380346"/>
      <mass value="0.014"/>
      <inertia ixx="9.5e-07" ixy="0.0" ixz="1.4e-07" iyy="8.6e-07" iyz="-1e-08" izz="3e-07"/>
    </inertial>
    <visual>
      <origin rpy="0 0 0" xyz="0 0 0"/>
      <geometry>
        <mesh filename="wuji_description/meshes/left/left_finger2_link4.STL"/>
      </geometry>
      <material name="">
        <color rgba="0.792156862745098 0.819607843137255 0.933333333333333 1"/>
      </material>
    </visual>
    <collision>
      <origin rpy="0 0 0" xyz="0 0 0"/>
      <geometry>
        <mesh filename="wuji_description/meshes/left/left_finger2_link4.STL"/>
      </geometry>
    </collision>
  </link>
  <joint name="left_finger2_joint4" type="revolute">
    <origin rpy="0 0 0" xyz="0 0 0.0295000000000001"/>
    <parent link="left_finger2_link3"/>
    <child link="left_finger2_link4"/>
    <axis xyz="0 1 0"/>
    <limit effort="0.2170" lower="-0.4683" upper="1.5753" velocity="13.578"/>
  </joint>
  <link name="left_finger2_tip_link">
    <inertial>
      <origin rpy="0 0 0" xyz="-0.000815133126519601 -1.35285046657906e-05 -0.0132153173546802"/>
      <mass value="0.00318"/>
      <inertia ixx="2e-07" ixy="0.0" ixz="0.0" iyy="2.1e-07" iyz="0.0" izz="1.3e-07"/>
    </inertial>
    <visual>
      <origin rpy="0 0 0" xyz="0 0 0"/>
      <geometry>
        <mesh filename="wuji_description/meshes/left/left_finger2_tip_link.STL"/>
      </geometry>
      <material name="">
        <color rgba="0.792156862745098 0.819607843137255 0.933333333333333 1"/>
      </material>
    </visual>
    <collision>
      <origin rpy="0 0 0" xyz="0 0 0"/>
      <geometry>
        <mesh filename="wuji_description/meshes/left/left_finger2_tip_link.STL"/>
      </geometry>
    </collision>
  </link>
  <joint name="left_finger2_tip_fixed" type="fixed">
    <origin rpy="0 0 0" xyz="0 0 0.0239999999927148"/>
    <parent link="left_finger2_link4"/>
    <child link="left_finger2_tip_link"/>
  </joint>
  <link name="left_finger3_link1">
    <inertial>
      <origin rpy="0 0 0" xyz="-0.0013290993356934 3.85118281692048e-08 0.000319975583838061"/>
      <mass value="0.0032"/>
      <inertia ixx="8e-08" ixy="0.0" ixz="-3e-08" iyy="7e-08" iyz="0.0" izz="8e-08"/>
    </inertial>
    <visual>
      <origin rpy="0 0 0" xyz="0 0 0"/>
      <geometry>
        <mesh filename="wuji_description/meshes/left/left_finger3_link1.STL"/>
      </geometry>
      <material name="">
        <color rgba="0.792156862745098 0.819607843137255 0.933333333333333 1"/>
      </material>
    </visual>
    <collision>
      <origin rpy="0 0 0" xyz="0 0 0"/>
      <geometry>
        <mesh filename="wuji_description/meshes/left/left_finger3_link1.STL"/>
      </geometry>
    </collision>
  </link>
  <joint name="left_finger3_joint1" type="revolute">
    <origin rpy="5.08943571260114E-05 -0.0872664620461584 -0.000583871739019229" xyz="-0.0104597238611325 -0.00746146014384909 0.0895435117703725"/>
    <parent link="left_palm_link"/>
    <child link="left_finger3_link1"/>
    <axis xyz="0 1 0"/>
    <limit effort="0.6494" lower="-0.1644" upper="1.5516" velocity="8.203"/>
  </joint>
  <link name="left_finger3_link2">
    <inertial>
      <origin rpy="0 0 0" xyz="-1.8289057734126e-06 0.00370964740843763 0.0184836990863896"/>
      <mass value="0.033"/>
      <inertia ixx="6.31e-06" ixy="0.0" ixz="-1.6e-07" iyy="6.34e-06" iyz="0.0" izz="8.9e-07"/>
    </inertial>
    <visual>
      <origin rpy="0 0 0" xyz="0 0 0"/>
      <geometry>
        <mesh filename="wuji_description/meshes/left/left_finger3_link2.STL"/>
      </geometry>
      <material name="">
        <color rgba="0.792156862745098 0.819607843137255 0.933333333333333 1"/>
      </material>
    </visual>
    <collision>
      <origin rpy="0 0 0" xyz="0 0 0"/>
      <geometry>
        <mesh filename="wuji_description/meshes/left/left_finger3_link2.STL"/>
      </geometry>
    </collision>
  </link>
  <joint name="left_finger3_joint2" type="revolute">
    <origin rpy="0 0 1.57079631622012" xyz="0.00220000043512786 0 0.0040000055763954"/>
    <parent link="left_finger3_link1"/>
    <child link="left_finger3_link2"/>
    <axis xyz="0 1 0"/>
    <limit effort="0.1827" lower="-0.3700" upper="0.3700" velocity="8.115"/>
  </joint>
  <link name="left_finger3_link3">
    <inertial>
      <origin rpy="0 0 0" xyz="0.00033374181277775 -1.05568444524057e-05 0.013486570719813"/>
      <mass value="0.0165"/>
      <inertia ixx="1.47e-06" ixy="0.0" ixz="3e-08" iyy="1.44e-06" iyz="0.0" izz="4.5e-07"/>
    </inertial>
    <visual>
      <origin rpy="0 0 0" xyz="0 0 0"/>
      <geometry>
        <mesh filename="wuji_description/meshes/left/left_finger3_link3.STL"/>
      </geometry>
      <material name="">
        <color rgba="0.792156862745098 0.819607843137255 0.933333333333333 1"/>
      </material>
    </visual>
    <collision>
      <origin rpy="0 0 0" xyz="0 0 0"/>
      <geometry>
        <mesh filename="wuji_description/meshes/left/left_finger3_link3.STL"/>
      </geometry>
    </collision>
  </link>
  <joint name="left_finger3_joint3" type="revolute">
    <origin rpy="0 0 -1.57052771407713" xyz="0 0.00474999938483462 0.0436176874784127"/>
    <parent link="left_finger3_link2"/>
    <child link="left_finger3_link3"/>
    <axis xyz="0 1 0"/>
    <limit effort="0.2078" lower="-0.4739" upper="1.5512" velocity="12.863"/>
  </joint>
  <link name="left_finger3_link4">
    <inertial>
      <origin rpy="0 0 0" xyz="-0.000815614639668593 -1.34653170952761e-05 0.0107846289017102"/>
      <mass value="0.014"/>
      <inertia ixx="9.5e-07" ixy="0.0" ixz="1.4e-07" iyy="8.6e-07" iyz="-1e-08" izz="3e-07"/>
    </inertial>
    <visual>
      <origin rpy="0 0 0" xyz="0 0 0"/>
      <geometry>
        <mesh filename="wuji_description/meshes/left/left_finger3_link4.STL"/>
      </geometry>
      <material name="">
        <color rgba="0.792156862745098 0.819607843137255 0.933333333333333 1"/>
      </material>
    </visual>
    <collision>
      <origin rpy="0 0 0" xyz="0 0 0"/>
      <geometry>
        <mesh filename="wuji_description/meshes/left/left_finger3_link4.STL"/>
      </geometry>
    </collision>
  </link>
  <joint name="left_finger3_joint4" type="revolute">
    <origin rpy="0 0 0" xyz="0 0 0.0295000000000001"/>
    <parent link="left_finger3_link3"/>
    <child link="left_finger3_link4"/>
    <axis xyz="0 1 0"/>
    <limit effort="0.2018" lower="-0.4684" upper="1.5745" velocity="13.578"/>
  </joint>
  <link name="left_finger3_tip_link">
    <inertial>
      <origin rpy="0 0 0" xyz="-0.00081561463966859 -1.3465317095277e-05 -0.0132153710915341"/>
      <mass value="0.00318"/>
      <inertia ixx="2e-07" ixy="0.0" ixz="0.0" iyy="2.1e-07" iyz="0.0" izz="1.3e-07"/>
    </inertial>
    <visual>
      <origin rpy="0 0 0" xyz="0 0 0"/>
      <geometry>
        <mesh filename="wuji_description/meshes/left/left_finger3_tip_link.STL"/>
      </geometry>
      <material name="">
        <color rgba="0.792156862745098 0.819607843137255 0.933333333333333 1"/>
      </material>
    </visual>
    <collision>
      <origin rpy="0 0 0" xyz="0 0 0"/>
      <geometry>
        <mesh filename="wuji_description/meshes/left/left_finger3_tip_link.STL"/>
      </geometry>
    </collision>
  </link>
  <joint name="left_finger3_tip_fixed" type="fixed">
    <origin rpy="0 0 0" xyz="0 0 0.0239999999932443"/>
    <parent link="left_finger3_link4"/>
    <child link="left_finger3_tip_link"/>
  </joint>
  <link name="left_finger4_link1">
    <inertial>
      <origin rpy="0 0 0" xyz="-0.00132910843853947 4.5618136124484e-08 0.000319940988547276"/>
      <mass value="0.0032"/>
      <inertia ixx="8e-08" ixy="0.0" ixz="-3e-08" iyy="7e-08" iyz="0.0" izz="8e-08"/>
    </inertial>
    <visual>
      <origin rpy="0 0 0" xyz="0 0 0"/>
      <geometry>
        <mesh filename="wuji_description/meshes/left/left_finger4_link1.STL"/>
      </geometry>
      <material name="">
        <color rgba="0.792156862745098 0.819607843137255 0.933333333333333 1"/>
      </material>
    </visual>
    <collision>
      <origin rpy="0 0 0" xyz="0 0 0"/>
      <geometry>
        <mesh filename="wuji_description/meshes/left/left_finger4_link1.STL"/>
      </geometry>
    </collision>
  </link>
  <joint name="left_finger4_joint1" type="revolute">
    <origin rpy="-0.0903746152622084 -0.0834355016926524 -0.0471266291476881" xyz="-0.00766485992847336 0.0137122383759899 0.0844286945863843"/>
    <parent link="left_palm_link"/>
    <child link="left_finger4_link1"/>
    <axis xyz="0 1 0"/>
    <limit effort="0.6389" lower="-0.1554" upper="1.5585" velocity="8.203"/>
  </joint>
  <link name="left_finger4_link2">
    <inertial>
      <origin rpy="0 0 0" xyz="-1.82335870431601e-06 0.00371493393588807 0.0185138380651074"/>
      <mass value="0.033"/>
      <inertia ixx="6.31e-06" ixy="0.0" ixz="-1.6e-07" iyy="6.34e-06" iyz="0.0" izz="8.9e-07"/>
    </inertial>
    <visual>
      <origin rpy="0 0 0" xyz="0 0 0"/>
      <geometry>
        <mesh filename="wuji_description/meshes/left/left_finger4_link2.STL"/>
      </geometry>
      <material name="">
        <color rgba="0.792156862745098 0.819607843137255 0.933333333333333 1"/>
      </material>
    </visual>
    <collision>
      <origin rpy="0 0 0" xyz="0 0 0"/>
      <geometry>
        <mesh filename="wuji_description/meshes/left/left_finger4_link2.STL"/>
      </geometry>
    </collision>
  </link>
  <joint name="left_finger4_joint2" type="revolute">
    <origin rpy="0 0 1.57079632679031" xyz="0.00220000041055242 0 0.0040000054390515"/>
    <parent link="left_finger4_link1"/>
    <child link="left_finger4_link2"/>
    <axis xyz="0 1 0"/>
    <limit effort="0.1832" lower="-0.3700" upper="0.3700" velocity="8.115"/>
  </joint>
  <link name="left_finger4_link3">
    <inertial>
      <origin rpy="0 0 0" xyz="0.000318919988381043 -1.03296717174663e-05 0.0135407428989596"/>
      <mass value="0.0165"/>
      <inertia ixx="1.47e-06" ixy="0.0" ixz="3e-08" iyy="1.44e-06" iyz="0.0" izz="4.5e-07"/>
    </inertial>
    <visual>
      <origin rpy="0 0 0" xyz="0 0 0"/>
      <geometry>
        <mesh filename="wuji_description/meshes/left/left_finger4_link3.STL"/>
      </geometry>
      <material name="">
        <color rgba="0.792156862745098 0.819607843137255 0.933333333333333 1"/>
      </material>
    </visual>
    <collision>
      <origin rpy="0 0 0" xyz="0 0 0"/>
      <geometry>
        <mesh filename="wuji_description/meshes/left/left_finger4_link3.STL"/>
      </geometry>
    </collision>
  </link>
  <joint name="left_finger4_joint3" type="revolute">
    <origin rpy="0 0 -1.57052771407713" xyz="0 0.0047499994200319 0.0436176874895471"/>
    <parent link="left_finger4_link2"/>
    <child link="left_finger4_link3"/>
    <axis xyz="0 1 0"/>
    <limit effort="0.2249" lower="-0.4765" upper="1.5487" velocity="12.863"/>
  </joint>
  <link name="left_finger4_link4">
    <inertial>
      <origin rpy="0 0 0" xyz="-0.000864591608603405 -1.02216849121577e-05 0.0108394093146864"/>
      <mass value="0.014"/>
      <inertia ixx="9.5e-07" ixy="0.0" ixz="1.4e-07" iyy="8.6e-07" iyz="-1e-08" izz="3e-07"/>
    </inertial>
    <visual>
      <origin rpy="0 0 0" xyz="0 0 0"/>
      <geometry>
        <mesh filename="wuji_description/meshes/left/left_finger4_link4.STL"/>
      </geometry>
      <material name="">
        <color rgba="0.792156862745098 0.819607843137255 0.933333333333333 1"/>
      </material>
    </visual>
    <collision>
      <origin rpy="0 0 0" xyz="0 0 0"/>
      <geometry>
        <mesh filename="wuji_description/meshes/left/left_finger4_link4.STL"/>
      </geometry>
    </collision>
  </link>
  <joint name="left_finger4_joint4" type="revolute">
    <origin rpy="0 0 0" xyz="0 0 0.0294999999999994"/>
    <parent link="left_finger4_link3"/>
    <child link="left_finger4_link4"/>
    <axis xyz="0 1 0"/>
    <limit effort="0.2044" lower="-0.4777" upper="1.5634" velocity="13.578"/>
  </joint>
  <link name="left_finger4_tip_link">
    <inertial>
      <origin rpy="0 0 0" xyz="-0.000864591608603407 -1.02216849121595e-05 -0.0131605906853139"/>
      <mass value="0.00318"/>
      <inertia ixx="2e-07" ixy="0.0" ixz="0.0" iyy="2.1e-07" iyz="0.0" izz="1.3e-07"/>
    </inertial>
    <visual>
      <origin rpy="0 0 0" xyz="0 0 0"/>
      <geometry>
        <mesh filename="wuji_description/meshes/left/left_finger4_tip_link.STL"/>
      </geometry>
      <material name="">
        <color rgba="0.792156862745098 0.819607843137255 0.933333333333333 1"/>
      </material>
    </visual>
    <collision>
      <origin rpy="0 0 0" xyz="0 0 0"/>
      <geometry>
        <mesh filename="wuji_description/meshes/left/left_finger4_tip_link.STL"/>
      </geometry>
    </collision>
  </link>
  <joint name="left_finger4_tip_fixed" type="fixed">
    <origin rpy="0 0 0" xyz="0 0 0.0240000000000004"/>
    <parent link="left_finger4_link4"/>
    <child link="left_finger4_tip_link"/>
  </joint>
  <link name="left_finger5_link1">
    <inertial>
      <origin rpy="0 0 0" xyz="-0.00132911898780765 3.31411356829792e-08 0.000319866559089207"/>
      <mass value="0.0032"/>
      <inertia ixx="8e-08" ixy="0.0" ixz="-3e-08" iyy="7e-08" iyz="0.0" izz="8e-08"/>
    </inertial>
    <visual>
      <origin rpy="0 0 0" xyz="0 0 0"/>
      <geometry>
        <mesh filename="wuji_description/meshes/left/left_finger5_link1.STL"/>
      </geometry>
      <material name="">
        <color rgba="0.792156862745098 0.819607843137255 0.933333333333333 1"/>
      </material>
    </visual>
    <collision>
      <origin rpy="0 0 0" xyz="0 0 0"/>
      <geometry>
        <mesh filename="wuji_description/meshes/left/left_finger5_link1.STL"/>
      </geometry>
    </collision>
  </link>
  <joint name="left_finger5_joint1" type="revolute">
    <origin rpy="-0.192483650752989 -0.092517232452551 -0.15767281892221" xyz="-0.00226865106057992 0.0340011106648632 0.0742813381427129"/>
    <parent link="left_palm_link"/>
    <child link="left_finger5_link1"/>
    <axis xyz="0 1 0"/>
    <limit effort="0.6441" lower="-0.1626" upper="1.5585" velocity="8.203"/>
  </joint>
  <link name="left_finger5_link2">
    <inertial>
      <origin rpy="0 0 0" xyz="-1.8210957353007e-06 0.00371683916602625 0.019333383934551"/>
      <mass value="0.033"/>
      <inertia ixx="6.31e-06" ixy="0.0" ixz="-1.6e-07" iyy="6.34e-06" iyz="0.0" izz="8.9e-07"/>
    </inertial>
    <visual>
      <origin rpy="0 0 0" xyz="0 0 0"/>
      <geometry>
        <mesh filename="wuji_description/meshes/left/left_finger5_link2.STL"/>
      </geometry>
      <material name="">
        <color rgba="0.792156862745098 0.819607843137255 0.933333333333333 1"/>
      </material>
    </visual>
    <collision>
      <origin rpy="0 0 0" xyz="0 0 0"/>
      <geometry>
        <mesh filename="wuji_description/meshes/left/left_finger5_link2.STL"/>
      </geometry>
    </collision>
  </link>
  <joint name="left_finger5_joint2" type="revolute">
    <origin rpy="0 0 1.57079631621958" xyz="0.0022000006397591 0 0.00400000525009432"/>
    <parent link="left_finger5_link1"/>
    <child link="left_finger5_link2"/>
    <axis xyz="0 1 0"/>
    <limit effort="0.1798" lower="-0.3700" upper="0.3700" velocity="8.115"/>
  </joint>
  <link name="left_finger5_link3">
    <inertial>
      <origin rpy="0 0 0" xyz="0.000353513671067502 -5.0899786138911e-06 0.0139267790546316"/>
      <mass value="0.0165"/>
      <inertia ixx="1.47e-06" ixy="0.0" ixz="3e-08" iyy="1.44e-06" iyz="0.0" izz="4.5e-07"/>
    </inertial>
    <visual>
      <origin rpy="0 0 0" xyz="0 0 0"/>
      <geometry>
        <mesh filename="wuji_description/meshes/left/left_finger5_link3.STL"/>
      </geometry>
      <material name="">
        <color rgba="0.792156862745098 0.819607843137255 0.933333333333333 1"/>
      </material>
    </visual>
    <collision>
      <origin rpy="0 0 0" xyz="0 0 0"/>
      <geometry>
        <mesh filename="wuji_description/meshes/left/left_finger5_link3.STL"/>
      </geometry>
    </collision>
  </link>
  <joint name="left_finger5_joint3" type="revolute">
    <origin rpy="0 0 -1.57052771407712" xyz="0 0.00474999942762067 0.0436176874784121"/>
    <parent link="left_finger5_link2"/>
    <child link="left_finger5_link3"/>
    <axis xyz="0 1 0"/>
    <limit effort="0.2384" lower="-0.4768" upper="1.5490" velocity="12.863"/>
  </joint>
  <link name="left_finger5_link4">
    <inertial>
      <origin rpy="0 0 0" xyz="-0.000906048247514996 1.8428176561492e-05 0.012275906650563"/>
      <mass value="0.014"/>
      <inertia ixx="9.5e-07" ixy="0.0" ixz="1.4e-07" iyy="8.6e-07" iyz="-1e-08" izz="3e-07"/>
    </inertial>
    <visual>
      <origin rpy="0 0 0" xyz="0 0 0"/>
      <geometry>
        <mesh filename="wuji_description/meshes/left/left_finger5_link4.STL"/>
      </geometry>
      <material name="">
        <color rgba="0.792156862745098 0.819607843137255 0.933333333333333 1"/>
      </material>
    </visual>
    <collision>
      <origin rpy="0 0 0" xyz="0 0 0"/>
      <geometry>
        <mesh filename="wuji_description/meshes/left/left_finger5_link4.STL"/>
      </geometry>
    </collision>
  </link>
  <joint name="left_finger5_joint4" type="revolute">
    <origin rpy="0 0 0" xyz="0 0 0.0294999999805625"/>
    <parent link="left_finger5_link3"/>
    <child link="left_finger5_link4"/>
    <axis xyz="0 1 0"/>
    <limit effort="0.1866" lower="-0.4683" upper="1.5735" velocity="13.578"/>
  </joint>
  <link name="left_finger5_tip_link">
    <inertial>
      <origin rpy="0 0 0" xyz="-0.000906048247514996 1.84281765614885e-05 -0.0137240933494371"/>
      <mass value="0.00318"/>
      <inertia ixx="2e-07" ixy="0.0" ixz="0.0" iyy="2.1e-07" iyz="0.0" izz="1.3e-07"/>
    </inertial>
    <visual>
      <origin rpy="0 0 0" xyz="0 0 0"/>
      <geometry>
        <mesh filename="wuji_description/meshes/left/left_finger5_tip_link.STL"/>
      </geometry>
      <material name="">
        <color rgba="0.792156862745098 0.819607843137255 0.933333333333333 1"/>
      </material>
    </visual>
    <collision>
      <origin rpy="0 0 0" xyz="0 0 0"/>
      <geometry>
        <mesh filename="wuji_description/meshes/left/left_finger5_tip_link.STL"/>
      </geometry>
    </collision>
  </link>
  <joint name="left_finger5_tip_fixed" type="fixed">
    <origin rpy="0 0 0" xyz="0 0 0.026"/>
    <parent link="left_finger5_link4"/>
    <child link="left_finger5_tip_link"/>
  </joint>
  <!-- This URDF was automatically created by SolidWorks to URDF Exporter! Originally created by Stephen Brawner (brawner@gmail.com) 
     Commit Version: 1.6.0-4-g7f85cfe  Build Version: 1.6.7995.38578
     For more information, please see http://wiki.ros.org/sw_urdf_exporter -->
  <link name="right_palm_link">
    <inertial>
      <origin rpy="0 0 0" xyz="0.0015244526948108 0.0026423462207805 0.0376699164153404"/>
      <mass value="0.16914"/>
      <inertia ixx="0.00014" ixy="2.54e-06" ixz="6.91e-06" iyy="9.47e-05" iyz="-6.63e-06" izz="6e-05"/>
    </inertial>
    <visual>
      <origin rpy="0 0 0" xyz="0 0 0"/>
      <geometry>
        <mesh filename="wuji_description/meshes/right/right_palm_link.STL"/>
      </geometry>
      <material name="">
        <color rgba="0.627450980392157 0.627450980392157 0.627450980392157 1"/>
      </material>
    </visual>
    <collision>
      <origin rpy="0 0 0" xyz="0 0 0"/>
      <geometry>
        <mesh filename="wuji_description/meshes/right/right_palm_link.STL"/>
      </geometry>
    </collision>
  </link>
  <link name="right_finger1_link1">
    <inertial>
      <origin rpy="0 0 0" xyz="-0.00991709829681589 -0.00598449671146729 0.00152323837071189"/>
      <mass value="0.0075"/>
      <inertia ixx="3.2e-07" ixy="-2e-08" ixz="0.0" iyy="3e-07" iyz="4e-08" izz="2.3e-07"/>
    </inertial>
    <visual>
      <origin rpy="0 0 0" xyz="0 0 0"/>
      <geometry>
        <mesh filename="wuji_description/meshes/right/right_finger1_link1.STL"/>
      </geometry>
      <material name="">
        <color rgba="0.792156862745098 0.819607843137255 0.933333333333333 1"/>
      </material>
    </visual>
    <collision>
      <origin rpy="0 0 0" xyz="0 0 0"/>
      <geometry>
        <mesh filename="wuji_description/meshes/right/right_finger1_link1.STL"/>
      </geometry>
    </collision>
  </link>
  <joint name="right_finger1_joint1" type="revolute">
    <origin rpy="-1.328 -0.37161 -0.7307" xyz="0.0085244 0.020575 0.028712"/>
    <parent link="right_palm_link"/>
    <child link="right_finger1_link1"/>
    <axis xyz="0 1 0"/>
    <limit effort="0.4452" lower="0.0475" upper="1.6033" velocity="8.587"/>
  </joint>
  <link name="right_finger1_link2">
    <inertial>
      <origin rpy="0 0 0" xyz="-0.00111960409510236 1.2374913890275e-05 0.0156635402212431"/>
      <mass value="0.0248"/>
      <inertia ixx="2.76e-06" ixy="2e-08" ixz="1e-08" iyy="2.81e-06" iyz="2e-08" izz="6.8e-07"/>
    </inertial>
    <visual>
      <origin rpy="0 0 0" xyz="0 0 0"/>
      <geometry>
        <mesh filename="wuji_description/meshes/right/right_finger1_link2.STL"/>
      </geometry>
      <material name="">
        <color rgba="0.792156862745098 0.819607843137255 0.933333333333333 1"/>
      </material>
    </visual>
    <collision>
      <origin rpy="0 0 0" xyz="0 0 0"/>
      <geometry>
        <mesh filename="wuji_description/meshes/right/right_finger1_link2.STL"/>
      </geometry>
    </collision>
  </link>
  <joint name="right_finger1_joint2" type="revolute">
    <origin rpy="0.57428 0.23677 -1.3382" xyz="-0.0047549 -0.0060191 0.014132"/>
    <parent link="right_finger1_link1"/>
    <child link="right_finger1_link2"/>
    <axis xyz="0 1 0"/>
    <limit effort="0.4259" lower="-0.1387" upper="0.9324" velocity="11.1"/>
  </joint>
  <link name="right_finger1_link3">
    <inertial>
      <origin rpy="0 0 0" xyz="0.000775214806825741 -0.000210057427154717 0.0127725629703719"/>
      <mass value="0.0165"/>
      <inertia ixx="1.46e-06" ixy="0.0" ixz="-2e-08" iyy="1.42e-06" iyz="0.0" izz="4.5e-07"/>
    </inertial>
    <visual>
      <origin rpy="0 0 0" xyz="0 0 0"/>
      <geometry>
        <mesh filename="wuji_description/meshes/right/right_finger1_link3.STL"/>
      </geometry>
      <material name="">
        <color rgba="0.792156862745098 0.819607843137255 0.933333333333333 1"/>
      </material>
    </visual>
    <collision>
      <origin rpy="0 0 0" xyz="0 0 0"/>
      <geometry>
        <mesh filename="wuji_description/meshes/right/right_finger1_link3.STL"/>
      </geometry>
    </collision>
  </link>
  <joint name="right_finger1_joint3" type="revolute">
    <origin rpy="0.049049 0.017311 1.2331" xyz="-0.00037714 0.001058 0.034673"/>
    <parent link="right_finger1_link2"/>
    <child link="right_finger1_link3"/>
    <axis xyz="0 1 0"/>
    <limit effort="0.1888" lower="-0.4642" upper="1.5623" velocity="12.863"/>
  </joint>
  <link name="right_finger1_link4">
    <inertial>
      <origin rpy="0 0 0" xyz="0.000494269230061378 -0.000154399984218116 0.0149071964271234"/>
      <mass value="0.0165"/>
      <inertia ixx="1.18e-06" ixy="0.0" ixz="1.2e-07" iyy="1.25e-06" iyz="0.0" izz="5.1e-07"/>
    </inertial>
    <visual>
      <origin rpy="0 0 0" xyz="0 0 0"/>
      <geometry>
        <mesh filename="wuji_description/meshes/right/right_finger1_link4.STL"/>
      </geometry>
      <material name="">
        <color rgba="0.792156862745098 0.819607843137255 0.933333333333333 1"/>
      </material>
    </visual>
    <collision>
      <origin rpy="0 0 0" xyz="0 0 0"/>
      <geometry>
        <mesh filename="wuji_description/meshes/right/right_finger1_link4.STL"/>
      </geometry>
    </collision>
  </link>
  <joint name="right_finger1_joint4" type="revolute">
    <origin rpy="0 0 0" xyz="0 0 0.0295"/>
    <parent link="right_finger1_link3"/>
    <child link="right_finger1_link4"/>
    <axis xyz="0 1 0"/>
    <limit effort="0.1468" lower="-0.4699" upper="1.5568" velocity="13.578"/>
  </joint>
  <link name="right_finger1_tip_link">
    <inertial>
      <origin rpy="0 0 0" xyz="0.000230275526129822 4.67895686886363e-05 -0.0179008347506294"/>
      <mass value="0.0041"/>
      <inertia ixx="5.5e-07" ixy="0.0" ixz="2e-08" iyy="5.2e-07" iyz="0.0" izz="2.7e-07"/>
    </inertial>
    <visual>
      <origin rpy="0 0 0" xyz="0 0 0"/>
      <geometry>
        <mesh filename="wuji_description/meshes/right/right_finger1_tip_link.STL"/>
      </geometry>
      <material name="">
        <color rgba="0.792156862745098 0.819607843137255 0.933333333333333 1"/>
      </material>
    </visual>
    <collision>
      <origin rpy="0 0 0" xyz="0 0 0"/>
      <geometry>
        <mesh filename="wuji_description/meshes/right/right_finger1_tip_link.STL"/>
      </geometry>
    </collision>
  </link>
  <joint name="right_finger1_tip_fixed" type="fixed">
    <origin rpy="0 0 0" xyz="0.00026399 -0.00020119 0.032808"/>
    <parent link="right_finger1_link4"/>
    <child link="right_finger1_tip_link"/>
  </joint>
  <link name="right_finger1_link2_softbody">
    <inertial>
      <origin rpy="0 0 0" xyz="-0.00205925374751718 -0.000366960939356481 0.0130977333944686"/>
      <mass value="0.00855316785801501"/>
      <inertia ixx="1.32027483558426E-06" ixy="5.18227633852468E-08" ixz="-1.58186187253834E-07" iyy="1.27943844242678E-06" iyz="-6.78214522771452E-08" izz="1.527999323729E-06"/>
    </inertial>
    <visual>
      <origin rpy="0 0 0" xyz="0 0 0"/>
      <geometry>
        <mesh filename="wuji_description/meshes/right/right_finger1_link2_softbody.STL"/>
      </geometry>
      <material name="">
        <color rgba="0.792156862745098 0.819607843137255 0.933333333333333 1"/>
      </material>
    </visual>
    <collision>
      <origin rpy="0 0 0" xyz="0 0 0"/>
      <geometry>
        <mesh filename="wuji_description/meshes/right/right_finger1_link2_softbody.STL"/>
      </geometry>
    </collision>
  </link>
  <joint name="right_finger1_joint2_softbody" type="fixed">
    <origin rpy="0 0 0" xyz="0 0 0"/>
    <parent link="right_finger1_link2"/>
    <child link="right_finger1_link2_softbody"/>
  </joint>
  <link name="right_finger2_link1">
    <inertial>
      <origin rpy="0 0 0" xyz="-0.00132913664538446 -2.06891034096324e-08 0.000319814735126503"/>
      <mass value="0.0032"/>
      <inertia ixx="8e-08" ixy="0.0" ixz="-3e-08" iyy="7e-08" iyz="0.0" izz="8e-08"/>
    </inertial>
    <visual>
      <origin rpy="0 0 0" xyz="0 0 0"/>
      <geometry>
        <mesh filename="wuji_description/meshes/right/right_finger2_link1.STL"/>
      </geometry>
      <material name="">
        <color rgba="0.792156862745098 0.819607843137255 0.933333333333333 1"/>
      </material>
    </visual>
    <collision>
      <origin rpy="0 0 0" xyz="0 0 0"/>
      <geometry>
        <mesh filename="wuji_description/meshes/right/right_finger2_link1.STL"/>
      </geometry>
    </collision>
  </link>
  <joint name="right_finger2_joint1" type="revolute">
    <origin rpy="-0.11071 -0.071139 -0.21822" xyz="-0.0058701 0.029434 0.091917"/>
    <parent link="right_palm_link"/>
    <child link="right_finger2_link1"/>
    <axis xyz="0 1 0"/>
    <limit effort="0.6188" lower="-0.1585" upper="1.5604" velocity="8.203"/>
  </joint>
  <link name="right_finger2_link2">
    <inertial>
      <origin rpy="0 0 0" xyz="1.8561410194233e-06 0.00370978720988412 0.0184837103970346"/>
      <mass value="0.033"/>
      <inertia ixx="6.31e-06" ixy="0.0" ixz="-1.6e-07" iyy="6.34e-06" iyz="0.0" izz="8.9e-07"/>
    </inertial>
    <visual>
      <origin rpy="0 0 0" xyz="0 0 0"/>
      <geometry>
        <mesh filename="wuji_description/meshes/right/right_finger2_link2.STL"/>
      </geometry>
      <material name="">
        <color rgba="0.792156862745098 0.819607843137255 0.933333333333333 1"/>
      </material>
    </visual>
    <collision>
      <origin rpy="0 0 0" xyz="0 0 0"/>
      <geometry>
        <mesh filename="wuji_description/meshes/right/right_finger2_link2.STL"/>
      </geometry>
    </collision>
  </link>
  <joint name="right_finger2_joint2" type="revolute">
    <origin rpy="0 0 1.57079633736728" xyz="0.0022000001158338 0 0.00400000569251532"/>
    <parent link="right_finger2_link1"/>
    <child link="right_finger2_link2"/>
    <axis xyz="0 1 0"/>
    <limit effort="0.1822" lower="-0.3700" upper="0.3700" velocity="8.115"/>
  </joint>
  <link name="right_finger2_link3">
    <inertial>
      <origin rpy="0 0 0" xyz="0.000342045432440366 1.41767248455285e-05 0.0134813717831617"/>
      <mass value="0.0165"/>
      <inertia ixx="1.47e-06" ixy="0.0" ixz="3e-08" iyy="1.44e-06" iyz="0.0" izz="4.5e-07"/>
    </inertial>
    <visual>
      <origin rpy="0 0 0" xyz="0 0 0"/>
      <geometry>
        <mesh filename="wuji_description/meshes/right/right_finger2_link3.STL"/>
      </geometry>
      <material name="">
        <color rgba="0.792156862745098 0.819607843137255 0.933333333333333 1"/>
      </material>
    </visual>
    <collision>
      <origin rpy="0 0 0" xyz="0 0 0"/>
      <geometry>
        <mesh filename="wuji_description/meshes/right/right_finger2_link3.STL"/>
      </geometry>
    </collision>
  </link>
  <joint name="right_finger2_joint3" type="revolute">
    <origin rpy="0 0 -1.57106493951267" xyz="0 0.00475028212346139 0.0436176566915279"/>
    <parent link="right_finger2_link2"/>
    <child link="right_finger2_link3"/>
    <axis xyz="0 1 0"/>
    <limit effort="0.2251" lower="-0.4777" upper="1.5485" velocity="12.863"/>
  </joint>
  <link name="right_finger2_link4">
    <inertial>
      <origin rpy="0 0 0" xyz="-0.000815041721252801 1.34300481698206e-05 0.0107855119657755"/>
      <mass value="0.014"/>
      <inertia ixx="9.5e-07" ixy="0.0" ixz="1.4e-07" iyy="8.6e-07" iyz="-1e-08" izz="3e-07"/>
    </inertial>
    <visual>
      <origin rpy="0 0 0" xyz="0 0 0"/>
      <geometry>
        <mesh filename="wuji_description/meshes/right/right_finger2_link4.STL"/>
      </geometry>
      <material name="">
        <color rgba="0.792156862745098 0.819607843137255 0.933333333333333 1"/>
      </material>
    </visual>
    <collision>
      <origin rpy="0 0 0" xyz="0 0 0"/>
      <geometry>
        <mesh filename="wuji_description/meshes/right/right_finger2_link4.STL"/>
      </geometry>
    </collision>
  </link>
  <joint name="right_finger2_joint4" type="revolute">
    <origin rpy="0 0 0" xyz="0 0 0.0294999999999997"/>
    <parent link="right_finger2_link3"/>
    <child link="right_finger2_link4"/>
    <axis xyz="0 1 0"/>
    <limit effort="0.2170" lower="-0.4683" upper="1.5753" velocity="13.578"/>
  </joint>
  <link name="right_finger2_tip_link">
    <inertial>
      <origin rpy="0 0 0" xyz="-6.56106086053404e-05 1.33496131320236e-05 -0.0132144933085167"/>
      <mass value="0.00318"/>
      <inertia ixx="2e-07" ixy="0.0" ixz="0.0" iyy="2.1e-07" iyz="0.0" izz="1.3e-07"/>
    </inertial>
    <visual>
      <origin rpy="0 0 0" xyz="0 0 0"/>
      <geometry>
        <mesh filename="wuji_description/meshes/right/right_finger2_tip_link.STL"/>
      </geometry>
      <material name="">
        <color rgba="0.792156862745098 0.819607843137255 0.933333333333333 1"/>
      </material>
    </visual>
    <collision>
      <origin rpy="0 0 0" xyz="0 0 0"/>
      <geometry>
        <mesh filename="wuji_description/meshes/right/right_finger2_tip_link.STL"/>
      </geometry>
    </collision>
  </link>
  <joint name="right_finger2_tip_fixed" type="fixed">
    <origin rpy="0 0 0" xyz="-0.000749345476102073 0 0.0240000048488493"/>
    <parent link="right_finger2_link4"/>
    <child link="right_finger2_tip_link"/>
  </joint>
  <link name="right_finger3_link1">
    <inertial>
      <origin rpy="0 0 0" xyz="-0.00132907800736239 3.41332629175128e-09 0.00031998285359347"/>
      <mass value="0.0032"/>
      <inertia ixx="8e-08" ixy="0.0" ixz="-3e-08" iyy="7e-08" iyz="0.0" izz="8e-08"/>
    </inertial>
    <visual>
      <origin rpy="0 0 0" xyz="0 0 0"/>
      <geometry>
        <mesh filename="wuji_description/meshes/right/right_finger3_link1.STL"/>
      </geometry>
      <material name="">
        <color rgba="0.792156862745098 0.819607843137255 0.933333333333333 1"/>
      </material>
    </visual>
    <collision>
      <origin rpy="0 0 0" xyz="0 0 0"/>
      <geometry>
        <mesh filename="wuji_description/meshes/right/right_finger3_link1.STL"/>
      </geometry>
    </collision>
  </link>
  <joint name="right_finger3_joint1" type="revolute">
    <origin rpy="-5.0886E-05 -0.087266 0.00058387" xyz="-0.01046 0.0074615 0.089544"/>
    <parent link="right_palm_link"/>
    <child link="right_finger3_link1"/>
    <axis xyz="0 1 0"/>
    <limit effort="0.6494" lower="-0.1644" upper="1.5516" velocity="8.203"/>
  </joint>
  <link name="right_finger3_link2">
    <inertial>
      <origin rpy="0 0 0" xyz="1.86458691599656e-06 0.0037097987397023 0.0184837075909854"/>
      <mass value="0.033"/>
      <inertia ixx="6.31e-06" ixy="0.0" ixz="-1.6e-07" iyy="6.34e-06" iyz="0.0" izz="8.9e-07"/>
    </inertial>
    <visual>
      <origin rpy="0 0 0" xyz="0 0 0"/>
      <geometry>
        <mesh filename="wuji_description/meshes/right/right_finger3_link2.STL"/>
      </geometry>
      <material name="">
        <color rgba="0.792156862745098 0.819607843137255 0.933333333333333 1"/>
      </material>
    </visual>
    <collision>
      <origin rpy="0 0 0" xyz="0 0 0"/>
      <geometry>
        <mesh filename="wuji_description/meshes/right/right_finger3_link2.STL"/>
      </geometry>
    </collision>
  </link>
  <joint name="right_finger3_joint2" type="revolute">
    <origin rpy="0 0 1.57079633736875" xyz="0.00220000044040472 0 0.00400000557349313"/>
    <parent link="right_finger3_link1"/>
    <child link="right_finger3_link2"/>
    <axis xyz="0 1 0"/>
    <limit effort="0.1827" lower="-0.3700" upper="0.3700" velocity="8.115"/>
  </joint>
  <link name="right_finger3_link3">
    <inertial>
      <origin rpy="0 0 0" xyz="0.00033387963896773 1.06802068574018e-05 0.013486531065416"/>
      <mass value="0.0165"/>
      <inertia ixx="1.47e-06" ixy="0.0" ixz="3e-08" iyy="1.44e-06" iyz="0.0" izz="4.5e-07"/>
    </inertial>
    <visual>
      <origin rpy="0 0 0" xyz="0 0 0"/>
      <geometry>
        <mesh filename="wuji_description/meshes/right/right_finger3_link3.STL"/>
      </geometry>
      <material name="">
        <color rgba="0.792156862745098 0.819607843137255 0.933333333333333 1"/>
      </material>
    </visual>
    <collision>
      <origin rpy="0 0 0" xyz="0 0 0"/>
      <geometry>
        <mesh filename="wuji_description/meshes/right/right_finger3_link3.STL"/>
      </geometry>
    </collision>
  </link>
  <joint name="right_finger3_joint3" type="revolute">
    <origin rpy="0 0 -1.57106493951267" xyz="0 0.00475000012644279 0.0436176873976532"/>
    <parent link="right_finger3_link2"/>
    <child link="right_finger3_link3"/>
    <axis xyz="0 1 0"/>
    <limit effort="0.2078" lower="-0.4739" upper="1.5512" velocity="12.863"/>
  </joint>
  <link name="right_finger3_link4">
    <inertial>
      <origin rpy="0 0 0" xyz="-0.000815351138295195 1.33727494529183e-05 0.0107852075877401"/>
      <mass value="0.014"/>
      <inertia ixx="9.5e-07" ixy="0.0" ixz="1.4e-07" iyy="8.6e-07" iyz="-1e-08" izz="3e-07"/>
    </inertial>
    <visual>
      <origin rpy="0 0 0" xyz="0 0 0"/>
      <geometry>
        <mesh filename="wuji_description/meshes/right/right_finger3_link4.STL"/>
      </geometry>
      <material name="">
        <color rgba="0.792156862745098 0.819607843137255 0.933333333333333 1"/>
      </material>
    </visual>
    <collision>
      <origin rpy="0 0 0" xyz="0 0 0"/>
      <geometry>
        <mesh filename="wuji_description/meshes/right/right_finger3_link4.STL"/>
      </geometry>
    </collision>
  </link>
  <joint name="right_finger3_joint4" type="revolute">
    <origin rpy="0 0 0" xyz="0 0 0.0294999999999993"/>
    <parent link="right_finger3_link3"/>
    <child link="right_finger3_link4"/>
    <axis xyz="0 1 0"/>
    <limit effort="0.2018" lower="-0.4684" upper="1.5745" velocity="13.578"/>
  </joint>
  <link name="right_finger3_tip_link">
    <inertial>
      <origin rpy="0 0 0" xyz="-6.53557694337819e-05 1.32722820960825e-05 -0.0132147924176925"/>
      <mass value="0.00318"/>
      <inertia ixx="2e-07" ixy="0.0" ixz="0.0" iyy="2.1e-07" iyz="0.0" izz="1.3e-07"/>
    </inertial>
    <visual>
      <origin rpy="0 0 0" xyz="0 0 0"/>
      <geometry>
        <mesh filename="wuji_description/meshes/right/right_finger3_tip_link.STL"/>
      </geometry>
      <material name="">
        <color rgba="0.792156862745098 0.819607843137255 0.933333333333333 1"/>
      </material>
    </visual>
    <collision>
      <origin rpy="0 0 0" xyz="0 0 0"/>
      <geometry>
        <mesh filename="wuji_description/meshes/right/right_finger3_tip_link.STL"/>
      </geometry>
    </collision>
  </link>
  <joint name="right_finger3_tip_fixed" type="fixed">
    <origin rpy="0 0 -0.000313047908830003" xyz="-0.000749999526923902 0 0.0240000000054326"/>
    <parent link="right_finger3_link4"/>
    <child link="right_finger3_tip_link"/>
  </joint>
  <link name="right_finger4_link1">
    <inertial>
      <origin rpy="0 0 0" xyz="-0.00132912451132636 1.24361438334775e-09 0.000319883557432801"/>
      <mass value="0.0032"/>
      <inertia ixx="8e-08" ixy="0.0" ixz="-3e-08" iyy="7e-08" iyz="0.0" izz="8e-08"/>
    </inertial>
    <visual>
      <origin rpy="0 0 0" xyz="0 0 0"/>
      <geometry>
        <mesh filename="wuji_description/meshes/right/right_finger4_link1.STL"/>
      </geometry>
      <material name="">
        <color rgba="0.792156862745098 0.819607843137255 0.933333333333333 1"/>
      </material>
    </visual>
    <collision>
      <origin rpy="0 0 0" xyz="0 0 0"/>
      <geometry>
        <mesh filename="wuji_description/meshes/right/right_finger4_link1.STL"/>
      </geometry>
    </collision>
  </link>
  <joint name="right_finger4_joint1" type="revolute">
    <origin rpy="0.090375 -0.083436 0.047127" xyz="-0.0076649 -0.013712 0.084429"/>
    <parent link="right_palm_link"/>
    <child link="right_finger4_link1"/>
    <axis xyz="0 1 0"/>
    <limit effort="0.6389" lower="-0.1554" upper="1.5585" velocity="8.203"/>
  </joint>
  <link name="right_finger4_link2">
    <inertial>
      <origin rpy="0 0 0" xyz="1.84945050425017e-06 0.00370375369981009 0.0185160521801185"/>
      <mass value="0.033"/>
      <inertia ixx="6.31e-06" ixy="0.0" ixz="-1.6e-07" iyy="6.34e-06" iyz="0.0" izz="8.9e-07"/>
    </inertial>
    <visual>
      <origin rpy="0 0 0" xyz="0 0 0"/>
      <geometry>
        <mesh filename="wuji_description/meshes/right/right_finger4_link2.STL"/>
      </geometry>
      <material name="">
        <color rgba="0.792156862745098 0.819607843137255 0.933333333333333 1"/>
      </material>
    </visual>
    <collision>
      <origin rpy="0 0 0" xyz="0 0 0"/>
      <geometry>
        <mesh filename="wuji_description/meshes/right/right_finger4_link2.STL"/>
      </geometry>
    </collision>
  </link>
  <joint name="right_finger4_joint2" type="revolute">
    <origin rpy="-0.000604862877277418 0 1.57079632679857" xyz="0.00220000047813762 0 0.0040000054485206"/>
    <parent link="right_finger4_link1"/>
    <child link="right_finger4_link2"/>
    <axis xyz="0 1 0"/>
    <limit effort="0.1832" lower="-0.3700" upper="0.3700" velocity="8.115"/>
  </joint>
  <link name="right_finger4_link3">
    <inertial>
      <origin rpy="0 0 0" xyz="0.000319082051113247 1.04410976575053e-05 0.0135408629697312"/>
      <mass value="0.0165"/>
      <inertia ixx="1.47e-06" ixy="0.0" ixz="3e-08" iyy="1.44e-06" iyz="0.0" izz="4.5e-07"/>
    </inertial>
    <visual>
      <origin rpy="0 0 0" xyz="0 0 0"/>
      <geometry>
        <mesh filename="wuji_description/meshes/right/right_finger4_link3.STL"/>
      </geometry>
      <material name="">
        <color rgba="0.792156862745098 0.819607843137255 0.933333333333333 1"/>
      </material>
    </visual>
    <collision>
      <origin rpy="0 0 0" xyz="0 0 0"/>
      <geometry>
        <mesh filename="wuji_description/meshes/right/right_finger4_link3.STL"/>
      </geometry>
    </collision>
  </link>
  <joint name="right_finger4_joint3" type="revolute">
    <origin rpy="0 0.000604862855432222 -1.5710649395618" xyz="0 0.00472361583469614 0.0436205526038598"/>
    <parent link="right_finger4_link2"/>
    <child link="right_finger4_link3"/>
    <axis xyz="0 1 0"/>
    <limit effort="0.2249" lower="-0.4765" upper="1.5487" velocity="12.863"/>
  </joint>
  <link name="right_finger4_link4">
    <inertial>
      <origin rpy="0 0 0" xyz="-0.00086509418615433 1.02480892825735e-05 0.0108405834237434"/>
      <mass value="0.014"/>
      <inertia ixx="9.5e-07" ixy="0.0" ixz="1.4e-07" iyy="8.6e-07" iyz="-1e-08" izz="3e-07"/>
    </inertial>
    <visual>
      <origin rpy="0 0 0" xyz="0 0 0"/>
      <geometry>
        <mesh filename="wuji_description/meshes/right/right_finger4_link4.STL"/>
      </geometry>
      <material name="">
        <color rgba="0.792156862745098 0.819607843137255 0.933333333333333 1"/>
      </material>
    </visual>
    <collision>
      <origin rpy="0 0 0" xyz="0 0 0"/>
      <geometry>
        <mesh filename="wuji_description/meshes/right/right_finger4_link4.STL"/>
      </geometry>
    </collision>
  </link>
  <joint name="right_finger4_joint4" type="revolute">
    <origin rpy="0 0 0" xyz="0 0 0.0294999999999996"/>
    <parent link="right_finger4_link3"/>
    <child link="right_finger4_link4"/>
    <axis xyz="0 1 0"/>
    <limit effort="0.2044" lower="-0.4777" upper="1.5634" velocity="13.578"/>
  </joint>
  <link name="right_finger4_tip_link">
    <inertial>
      <origin rpy="0 0 0" xyz="-5.39301790766361e-05 1.01851996692614e-05 -0.013158930321946"/>
      <mass value="0.00318"/>
      <inertia ixx="2e-07" ixy="0.0" ixz="0.0" iyy="2.1e-07" iyz="0.0" izz="1.3e-07"/>
    </inertial>
    <visual>
      <origin rpy="0 0 0" xyz="0 0 0"/>
      <geometry>
        <mesh filename="wuji_description/meshes/right/right_finger4_tip_link.STL"/>
      </geometry>
      <material name="">
        <color rgba="0.792156862745098 0.819607843137255 0.933333333333333 1"/>
      </material>
    </visual>
    <collision>
      <origin rpy="0 0 0" xyz="0 0 0"/>
      <geometry>
        <mesh filename="wuji_description/meshes/right/right_finger4_tip_link.STL"/>
      </geometry>
    </collision>
  </link>
  <joint name="right_finger4_tip_fixed" type="fixed">
    <origin rpy="0 0 0" xyz="-0.000811164007077695 0 0.0239995137456894"/>
    <parent link="right_finger4_link4"/>
    <child link="right_finger4_tip_link"/>
  </joint>
  <link name="right_finger5_link1">
    <inertial>
      <origin rpy="0 0 0" xyz="-0.00132912774308231 1.08611305747741e-08 0.000319899008963065"/>
      <mass value="0.0032"/>
      <inertia ixx="8e-08" ixy="0.0" ixz="-3e-08" iyy="7e-08" iyz="0.0" izz="8e-08"/>
    </inertial>
    <visual>
      <origin rpy="0 0 0" xyz="0 0 0"/>
      <geometry>
        <mesh filename="wuji_description/meshes/right/right_finger5_link1.STL"/>
      </geometry>
      <material name="">
        <color rgba="0.792156862745098 0.819607843137255 0.933333333333333 1"/>
      </material>
    </visual>
    <collision>
      <origin rpy="0 0 0" xyz="0 0 0"/>
      <geometry>
        <mesh filename="wuji_description/meshes/right/right_finger5_link1.STL"/>
      </geometry>
    </collision>
  </link>
  <joint name="right_finger5_joint1" type="revolute">
    <origin rpy="0.192483658660879 -0.0925172337475745 0.15767281866967" xyz="-0.00226865141495017 -0.0340011086840191 0.0742813385316328"/>
    <parent link="right_palm_link"/>
    <child link="right_finger5_link1"/>
    <axis xyz="0 1 0"/>
    <limit effort="0.6441" lower="-0.1626" upper="1.5585" velocity="8.203"/>
  </joint>
  <link name="right_finger5_link2">
    <inertial>
      <origin rpy="0 0 0" xyz="1.84965825334241e-06 0.0037023022598306 0.0193361743868221"/>
      <mass value="0.033"/>
      <inertia ixx="6.31e-06" ixy="0.0" ixz="-1.6e-07" iyy="6.34e-06" iyz="0.0" izz="8.9e-07"/>
    </inertial>
    <visual>
      <origin rpy="0 0 0" xyz="0 0 0"/>
      <geometry>
        <mesh filename="wuji_description/meshes/right/right_finger5_link2.STL"/>
      </geometry>
      <material name="">
        <color rgba="0.792156862745098 0.819607843137255 0.933333333333333 1"/>
      </material>
    </visual>
    <collision>
      <origin rpy="0 0 0" xyz="0 0 0"/>
      <geometry>
        <mesh filename="wuji_description/meshes/right/right_finger5_link2.STL"/>
      </geometry>
    </collision>
  </link>
  <joint name="right_finger5_joint2" type="revolute">
    <origin rpy="-0.000756548636659104 0 1.5707963373693" xyz="0.00220000064788035 0 0.00400000524843"/>
    <parent link="right_finger5_link1"/>
    <child link="right_finger5_link2"/>
    <axis xyz="0 1 0"/>
    <limit effort="0.1798" lower="-0.3700" upper="0.3700" velocity="8.115"/>
  </joint>
  <link name="right_finger5_link3">
    <inertial>
      <origin rpy="0 0 0" xyz="0.000328501378931936 5.05491576449982e-06 0.0142852793969278"/>
      <mass value="0.0165"/>
      <inertia ixx="1.47e-06" ixy="0.0" ixz="3e-08" iyy="1.44e-06" iyz="0.0" izz="4.5e-07"/>
    </inertial>
    <visual>
      <origin rpy="0 0 0" xyz="0 0 0"/>
      <geometry>
        <mesh filename="wuji_description/meshes/right/right_finger5_link3.STL"/>
      </geometry>
      <material name="">
        <color rgba="0.792156862745098 0.819607843137255 0.933333333333333 1"/>
      </material>
    </visual>
    <collision>
      <origin rpy="0 0 0" xyz="0 0 0"/>
      <geometry>
        <mesh filename="wuji_description/meshes/right/right_finger5_link3.STL"/>
      </geometry>
    </collision>
  </link>
  <joint name="right_finger5_joint3" type="revolute">
    <origin rpy="0 0.00075654860934489 -1.57106493958954" xyz="0 0.00471699911185841 0.0436212686072489"/>
    <parent link="right_finger5_link2"/>
    <child link="right_finger5_link3"/>
    <axis xyz="0 1 0"/>
    <limit effort="0.2384" lower="-0.4768" upper="1.5490" velocity="12.863"/>
  </joint>
  <link name="right_finger5_link4">
    <inertial>
      <origin rpy="0 0 0" xyz="-0.000908092655695626 -1.90466220408823e-05 0.0122783863262139"/>
      <mass value="0.014"/>
      <inertia ixx="9.5e-07" ixy="0.0" ixz="1.4e-07" iyy="8.6e-07" iyz="-1e-08" izz="3e-07"/>
    </inertial>
    <visual>
      <origin rpy="0 0 0" xyz="0 0 0"/>
      <geometry>
        <mesh filename="wuji_description/meshes/right/right_finger5_link4.STL"/>
      </geometry>
      <material name="">
        <color rgba="0.792156862745098 0.819607843137255 0.933333333333333 1"/>
      </material>
    </visual>
    <collision>
      <origin rpy="0 0 0" xyz="0 0 0"/>
      <geometry>
        <mesh filename="wuji_description/meshes/right/right_finger5_link4.STL"/>
      </geometry>
    </collision>
  </link>
  <joint name="right_finger5_joint4" type="revolute">
    <origin rpy="0 0 0" xyz="0 0 0.0295"/>
    <parent link="right_finger5_link3"/>
    <child link="right_finger5_link4"/>
    <axis xyz="0 1 0"/>
    <limit effort="0.1866" lower="-0.4683" upper="1.5735" velocity="13.578"/>
  </joint>
  <link name="right_finger5_tip_link">
    <inertial>
      <origin rpy="0 0 0" xyz="-8.00770571780483e-05 -1.91045654970926e-05 -0.0137209946788495"/>
      <mass value="0.00318"/>
      <inertia ixx="2e-07" ixy="0.0" ixz="0.0" iyy="2.1e-07" iyz="0.0" izz="1.3e-07"/>
    </inertial>
    <visual>
      <origin rpy="0 0 0" xyz="0 0 0"/>
      <geometry>
        <mesh filename="wuji_description/meshes/right/right_finger5_tip_link.STL"/>
      </geometry>
      <material name="">
        <color rgba="0.792156862745098 0.819607843137255 0.933333333333333 1"/>
      </material>
    </visual>
    <collision>
      <origin rpy="0 0 0" xyz="0 0 0"/>
      <geometry>
        <mesh filename="wuji_description/meshes/right/right_finger5_tip_link.STL"/>
      </geometry>
    </collision>
  </link>
  <joint name="right_finger5_tip_fixed" type="fixed">
    <origin rpy="0 0 0" xyz="-0.00082801559851758 0 0.0259993810050634"/>
    <parent link="right_finger5_link4"/>
    <child link="right_finger5_tip_link"/>
  </joint>
  <joint name="main_base_to_marvin_left" type="fixed">
    <origin rpy="-1.5708 -1.5708 0" xyz="0 0.2 0.5"/>
    <parent link="main_base_link"/>
    <child link="Base_L"/>
  </joint>
  <joint name="main_base_to_marvin_right" type="fixed">
    <origin rpy="1.5708 -1.5708 0" xyz="0 -0.2 0.5"/>
    <parent link="main_base_link"/>
    <child link="Base_R"/>
  </joint>
  <joint name="marvin_left_to_wuji_left" type="fixed">
    <origin rpy="1.5708 3.1416 0" xyz="0 -0.12 0"/>
    <parent link="Link7_L"/>
    <child link="left_palm_link"/>
  </joint>
  <joint name="marvin_right_to_wuji_right" type="fixed">
    <origin rpy="1.5708 0 0" xyz="0 -0.12 0"/>
    <parent link="Link7_R"/>
    <child link="right_palm_link"/>
  </joint>
</robot>
