<mujoco model="robot">
  <compiler angle="radian" meshdir="../../"/>

  <asset>
    <mesh name="base_link" file="robot_description/meshes/base_link.STL"/>
    <mesh name="lift_platform_link" file="robot_description/meshes/lift_platform_link.STL"/>
    <mesh name="Base_L" file="marvin_description/meshes/left/Base_L.STL"/>
    <mesh name="Link1_L" file="marvin_description/meshes/left/Link1_L.STL"/>
    <mesh name="Link2_L" file="marvin_description/meshes/left/Link2_L.STL"/>
    <mesh name="Link3_L" file="marvin_description/meshes/left/Link3_L.STL"/>
    <mesh name="Link4_L" file="marvin_description/meshes/left/Link4_L.STL"/>
    <mesh name="Link5_L" file="marvin_description/meshes/left/Link5_L.STL"/>
    <mesh name="Link6_L" file="marvin_description/meshes/left/Link6_L.STL"/>
    <mesh name="Link7_L" file="marvin_description/meshes/left/Link7_L.STL"/>
    <mesh name="Base_R" file="marvin_description/meshes/right/Base_R.STL"/>
    <mesh name="Link1_R" file="marvin_description/meshes/right/Link1_R.STL"/>
    <mesh name="Link2_R" file="marvin_description/meshes/right/Link2_R.STL"/>
    <mesh name="Link3_R" file="marvin_description/meshes/right/Link3_R.STL"/>
    <mesh name="Link4_R" file="marvin_description/meshes/right/Link4_R.STL"/>
    <mesh name="Link5_R" file="marvin_description/meshes/right/Link5_R.STL"/>
    <mesh name="Link6_R" file="marvin_description/meshes/right/Link6_R.STL"/>
    <mesh name="Link7_R" file="marvin_description/meshes/right/Link7_R.STL"/>
    <mesh name="left_palm_link" file="wuji_description/meshes/left/left_palm_link.STL"/>
    <mesh name="left_finger1_link1" file="wuji_description/meshes/left/left_finger1_link1.STL"/>
    <mesh name="left_finger1_link2" file="wuji_description/meshes/left/left_finger1_link2.STL"/>
    <mesh name="left_finger1_link3" file="wuji_description/meshes/left/left_finger1_link3.STL"/>
    <mesh name="left_finger1_link4" file="wuji_description/meshes/left/left_finger1_link4.STL"/>
    <mesh name="left_finger1_tip_link" file="wuji_description/meshes/left/left_finger1_tip_link.STL"/>
    <mesh name="left_finger1_link2_softbody" file="wuji_description/meshes/left/left_finger1_link2_softbody.STL"/>
    <mesh name="left_finger2_link1" file="wuji_description/meshes/left/left_finger2_link1.STL"/>
    <mesh name="left_finger2_link2" file="wuji_description/meshes/left/left_finger2_link2.STL"/>
    <mesh name="left_finger2_link3" file="wuji_description/meshes/left/left_finger2_link3.STL"/>
    <mesh name="left_finger2_link4" file="wuji_description/meshes/left/left_finger2_link4.STL"/>
    <mesh name="left_finger2_tip_link" file="wuji_description/meshes/left/left_finger2_tip_link.STL"/>
    <mesh name="left_finger3_link1" file="wuji_description/meshes/left/left_finger3_link1.STL"/>
    <mesh name="left_finger3_link2" file="wuji_description/meshes/left/left_finger3_link2.STL"/>
    <mesh name="left_finger3_link3" file="wuji_description/meshes/left/left_finger3_link3.STL"/>
    <mesh name="left_finger3_link4" file="wuji_description/meshes/left/left_finger3_link4.STL"/>
    <mesh name="left_finger3_tip_link" file="wuji_description/meshes/left/left_finger3_tip_link.STL"/>
    <mesh name="left_finger4_link1" file="wuji_description/meshes/left/left_finger4_link1.STL"/>
    <mesh name="left_finger4_link2" file="wuji_description/meshes/left/left_finger4_link2.STL"/>
    <mesh name="left_finger4_link3" file="wuji_description/meshes/left/left_finger4_link3.STL"/>
    <mesh name="left_finger4_link4" file="wuji_description/meshes/left/left_finger4_link4.STL"/>
    <mesh name="left_finger4_tip_link" file="wuji_description/meshes/left/left_finger4_tip_link.STL"/>
    <mesh name="left_finger5_link1" file="wuji_description/meshes/left/left_finger5_link1.STL"/>
    <mesh name="left_finger5_link2" file="wuji_description/meshes/left/left_finger5_link2.STL"/>
    <mesh name="left_finger5_link3" file="wuji_description/meshes/left/left_finger5_link3.STL"/>
    <mesh name="left_finger5_link4" file="wuji_description/meshes/left/left_finger5_link4.STL"/>
    <mesh name="left_finger5_tip_link" file="wuji_description/meshes/left/left_finger5_tip_link.STL"/>
    <mesh name="right_palm_link" file="wuji_description/meshes/right/right_palm_link.STL"/>
    <mesh name="right_finger1_link1" file="wuji_description/meshes/right/right_finger1_link1.STL"/>
    <mesh name="right_finger1_link2" file="wuji_description/meshes/right/right_finger1_link2.STL"/>
    <mesh name="right_finger1_link3" file="wuji_description/meshes/right/right_finger1_link3.STL"/>
    <mesh name="right_finger1_link4" file="wuji_description/meshes/right/right_finger1_link4.STL"/>
    <mesh name="right_finger1_tip_link" file="wuji_description/meshes/right/right_finger1_tip_link.STL"/>
    <mesh name="right_finger1_link2_softbody" file="wuji_description/meshes/right/right_finger1_link2_softbody.STL"/>
    <mesh name="right_finger2_link1" file="wuji_description/meshes/right/right_finger2_link1.STL"/>
    <mesh name="right_finger2_link2" file="wuji_description/meshes/right/right_finger2_link2.STL"/>
    <mesh name="right_finger2_link3" file="wuji_description/meshes/right/right_finger2_link3.STL"/>
    <mesh name="right_finger2_link4" file="wuji_description/meshes/right/right_finger2_link4.STL"/>
    <mesh name="right_finger2_tip_link" file="wuji_description/meshes/right/right_finger2_tip_link.STL"/>
    <mesh name="right_finger3_link1" file="wuji_description/meshes/right/right_finger3_link1.STL"/>
    <mesh name="right_finger3_link2" file="wuji_description/meshes/right/right_finger3_link2.STL"/>
    <mesh name="right_finger3_link3" file="wuji_description/meshes/right/right_finger3_link3.STL"/>
    <mesh name="right_finger3_link4" file="wuji_description/meshes/right/right_finger3_link4.STL"/>
    <mesh name="right_finger3_tip_link" file="wuji_description/meshes/right/right_finger3_tip_link.STL"/>
    <mesh name="right_finger4_link1" file="wuji_description/meshes/right/right_finger4_link1.STL"/>
    <mesh name="right_finger4_link2" file="wuji_description/meshes/right/right_finger4_link2.STL"/>
    <mesh name="right_finger4_link3" file="wuji_description/meshes/right/right_finger4_link3.STL"/>
    <mesh name="right_finger4_link4" file="wuji_description/meshes/right/right_finger4_link4.STL"/>
    <mesh name="right_finger4_tip_link" file="wuji_description/meshes/right/right_finger4_tip_link.STL"/>
    <mesh name="right_finger5_link1" file="wuji_description/meshes/right/right_finger5_link1.STL"/>
    <mesh name="right_finger5_link2" file="wuji_description/meshes/right/right_finger5_link2.STL"/>
    <mesh name="right_finger5_link3" file="wuji_description/meshes/right/right_finger5_link3.STL"/>
    <mesh name="right_finger5_link4" file="wuji_description/meshes/right/right_finger5_link4.STL"/>
    <mesh name="right_finger5_tip_link" file="wuji_description/meshes/right/right_finger5_tip_link.STL"/>
    <mesh name="hand_docking_link" file="robot_description/meshes/hand_docking_link.STL"/>
    <mesh name="camera_adapter_link" file="robot_description/meshes/camera_adapter_link.STL"/>
  </asset>

  <worldbody>
    <body name="base_link">
      <inertial pos="0.0195359 -0.00155643 0.215131" quat="0.511175 0.486842 0.531548 0.468125" mass="76.7122" diaginertia="2.26697 2.26517 1.89111"/>
      <geom type="mesh" contype="0" conaffinity="0" group="1" density="0" rgba="1 1 1 1" mesh="base_link"/>
      <geom type="mesh" rgba="1 1 1 1" mesh="base_link"/>
      <body name="lift_platform_link" pos="0.2958 0.0070867 1.0124">
        <inertial pos="-0.0039344 0 0.065" quat="0.5 0.5 0.5 0.5" mass="2.19055" diaginertia="0.0104605 0.0101785 0.00717541"/>
        <geom type="mesh" contype="0" conaffinity="0" group="1" density="0" rgba="0.776471 0.756863 0.737255 1" mesh="lift_platform_link"/>
        <geom type="mesh" rgba="0.776471 0.756863 0.737255 1" mesh="lift_platform_link"/>
        <body name="Base_L" pos="0.0252 0.04725 0.065" quat="0.499998 -0.5 -0.5 -0.500002">
          <inertial pos="0.00032267 4.798e-05 0.0406635" quat="0.582787 0.36644 -0.620273 0.375956" mass="1.1962" diaginertia="0.00127375 0.00107367 0.00106904"/>
          <geom type="mesh" contype="0" conaffinity="0" group="1" density="0" rgba="1 0 0 1" mesh="Base_L"/>
          <geom type="mesh" rgba="1 0 0 1" mesh="Base_L"/>
          <body name="Link1_L" pos="0 0 0.1745">
            <inertial pos="2.347e-05 0.0055715 -0.03076" quat="0.711599 0.0343691 -0.0341702 0.700912" mass="1.9705" diaginertia="0.00529754 0.00492285 0.00184874"/>
            <joint name="Joint1_L" pos="0 0 0" axis="0 0 1" range="-3.1067 3.1067" actuatorfrcrange="-108 108"/>
            <geom type="mesh" contype="0" conaffinity="0" group="1" density="0" rgba="0 1 0 1" mesh="Link1_L"/>
            <geom type="mesh" rgba="0 1 0 1" mesh="Link1_L"/>
            <body name="Link2_L" quat="0.707105 0.707108 0 0">
              <inertial pos="0.00013483 0.0617046 0.00950639" quat="0.643375 0.765551 -3.57328e-05 0.000294349" mass="2.24398" diaginertia="0.0119493 0.0112156 0.00338374"/>
              <joint name="Joint2_L" pos="0 0 0" axis="0 0 1" range="-2.0944 2.0944" actuatorfrcrange="-108 108"/>
              <geom type="mesh" contype="0" conaffinity="0" group="1" density="0" rgba="0 0 1 1" mesh="Link2_L"/>
              <geom type="mesh" rgba="0 0 1 1" mesh="Link2_L"/>
              <body name="Link3_L" pos="0 0.287 0" quat="0.707105 -0.707108 0 0">
                <inertial pos="0.00968562 0.00246599 -0.046273" quat="0.782446 -0.0355285 -0.0735516 0.617337" mass="1.9242" diaginertia="0.00765215 0.00730789 0.0016338"/>
                <joint name="Joint3_L" pos="0 0 0" axis="0 0 1" range="-3.1067 3.1067" actuatorfrcrange="-66 66"/>
                <geom type="mesh" contype="0" conaffinity="0" group="1" density="0" rgba="1 0 0 1" mesh="Link3_L"/>
                <geom type="mesh" rgba="1 0 0 1" mesh="Link3_L"/>
                <body name="Link4_L" pos="0.018 0 0" quat="-2.59734e-06 2.59735e-06 -0.707108 0.707105">
                  <inertial pos="0.00850411 -0.0471822 0.00941509" quat="0.741754 0.628694 0.0774999 -0.220317" mass="1.6085" diaginertia="0.00603244 0.00535875 0.00198228"/>
                  <joint name="Joint4_L" pos="0 0 0" axis="0 0 1" range="-2.5307 1.0472" actuatorfrcrange="-66 66"/>
                  <geom type="mesh" contype="0" conaffinity="0" group="1" density="0" rgba="0 1 0 1" mesh="Link4_L"/>
                  <geom type="mesh" rgba="0 1 0 1" mesh="Link4_L"/>
                  <body name="Link5_L" pos="0.018 -0.314 0" quat="-2.59734e-06 2.59735e-06 -0.707108 0.707105">
                    <inertial pos="0.00051127 0.00101064 -0.112717" quat="0.999438 -0.00995046 -0.00675781 0.0312997" mass="2.0883" diaginertia="0.00626924 0.00564262 0.00243436"/>
                    <joint name="Joint5_L" pos="0 0 0" axis="0 0 1" range="-3.1067 3.1067" actuatorfrcrange="-18 18"/>
                    <geom type="mesh" contype="0" conaffinity="0" group="1" density="0" rgba="0 0 1 1" mesh="Link5_L"/>
                    <geom type="mesh" rgba="0 0 1 1" mesh="Link5_L"/>
                    <body name="Link6_L" quat="0.499998 0.5 -0.5 0.500002">
                      <inertial pos="0.00032659 0.00531336 -0.00030182" quat="0.718188 -0.0225408 0.00407878 0.695472" mass="0.72496" diaginertia="0.000517351 0.000460362 0.000425057"/>
                      <joint name="Joint6_L" pos="0 0 0" axis="0 0 1" range="-1.0472 1.0472" actuatorfrcrange="-18 18"/>
                      <geom type="mesh" contype="0" conaffinity="0" group="1" density="0" rgba="1 0 0 1" mesh="Link6_L"/>
                      <geom type="mesh" rgba="1 0 0 1" mesh="Link6_L"/>
                      <body name="Link7_L" quat="0.499998 0.5 -0.5 0.500002">
                        <inertial pos="-9.108e-05 -0.0315325 0.00889371" quat="0.84481 0.535026 0.00229584 -0.00609725" mass="0.68606" diaginertia="0.00173691 0.00153911 0.000745263"/>
                        <joint name="Joint7_L" pos="0 0 0" axis="0 0 1" range="-1.5708 1.5708" actuatorfrcrange="-18 18"/>
                        <geom type="mesh" contype="0" conaffinity="0" group="1" density="0" rgba="0 1 0 1" mesh="Link7_L"/>
                        <geom type="mesh" rgba="0 1 0 1" mesh="Link7_L"/>
                        <body name="left_hand_docking_link" pos="0 -0.1 0" quat="0.499998 0.5 0.5 -0.500002">
                          <inertial pos="0 0.000613 0.008094" quat="0.435285 0.5573 -0.557322 0.435127" mass="0.051956" diaginertia="1.93305e-05 1.81473e-05 1.72441e-05"/>
                          <geom type="mesh" contype="0" conaffinity="0" group="1" density="0" rgba="0.792157 0.819608 0.933333 1" mesh="hand_docking_link"/>
                          <geom type="mesh" rgba="0.792157 0.819608 0.933333 1" mesh="hand_docking_link"/>
                          <body name="left_palm_link" pos="0 0 0.05" quat="0.92388 0 0 -0.382683">
                            <inertial pos="0.00152445 -0.00264235 0.0376699" quat="0.994582 0.0930829 -0.0427472 -0.0177281" mass="0.16914" diaginertia="0.000140677 9.58896e-05 5.81329e-05"/>
                            <geom type="mesh" contype="0" conaffinity="0" group="1" density="0" rgba="0.627451 0.627451 0.627451 1" mesh="left_palm_link"/>
                            <geom type="mesh" rgba="0.627451 0.627451 0.627451 1" mesh="left_palm_link"/>
                            <body name="left_finger1_link1" pos="0.00852444 -0.0205754 0.0287119" quat="0.682211 0.617678 0.0805082 0.382859">
                              <inertial pos="-0.00246155 0.00144069 0.00778554" quat="0.904243 0.21652 0.0443878 -0.365368" mass="0.0075" diaginertia="3.37599e-07 3.01198e-07 2.11203e-07"/>
                              <joint name="left_finger1_joint1" pos="0 0 0" axis="0 1 0" range="0.0475 1.6033" actuatorfrcrange="-0.4452 0.4452"/>
                              <geom type="mesh" contype="0" conaffinity="0" group="1" density="0" rgba="0.792157 0.819608 0.933333 1" mesh="left_finger1_link1"/>
                              <geom type="mesh" rgba="0.792157 0.819608 0.933333 1" mesh="left_finger1_link1"/>
                              <body name="left_finger1_link2" pos="-0.0047549 0.00601914 0.0141321" quat="0.616957 0.0855876 -0.29085 -0.726254">
                                <inertial pos="0.00111964 1.24225e-05 0.0156636" quat="0.815906 0.0024483 -0.00462559 0.57816" mass="0.0248" diaginertia="2.81725e-06 2.75299e-06 6.79766e-07"/>
                                <joint name="left_finger1_joint2" pos="0 0 0" axis="0 -1 0" range="-0.1387 0.9324" actuatorfrcrange="-0.4259 0.4259"/>
                                <geom type="mesh" contype="0" conaffinity="0" group="1" density="0" rgba="0.792157 0.819608 0.933333 1" mesh="left_finger1_link2"/>
                                <geom type="mesh" rgba="0.792157 0.819608 0.933333 1" mesh="left_finger1_link2"/>
                                <body name="left_finger1_link3" pos="0.000188722 0.000991601 0.0346636" quat="0.577836 -0.0212382 -0.0150036 0.815739">
                                  <inertial pos="0.000774544 1.11939e-05 0.01277" quat="0.999951 0 0.00989566 0" mass="0.0165" diaginertia="1.4604e-06 1.42e-06 4.49604e-07"/>
                                  <joint name="left_finger1_joint3" pos="0 0 0" axis="0 1 0" range="-0.4642 1.5623" actuatorfrcrange="-0.1888 0.1888"/>
                                  <geom type="mesh" contype="0" conaffinity="0" group="1" density="0" rgba="0.792157 0.819608 0.933333 1" mesh="left_finger1_link3"/>
                                  <geom type="mesh" rgba="0.792157 0.819608 0.933333 1" mesh="left_finger1_link3"/>
                                  <body name="left_finger1_link4" pos="0 -0.0002 0.0295">
                                    <inertial pos="0.000492755 0.000153669 0.0149026" quat="0.704494 -0.0607308 -0.0607308 0.704494" mass="0.0165" diaginertia="1.25e-06 1.20084e-06 4.89156e-07"/>
                                    <joint name="left_finger1_joint4" pos="0 0 0" axis="0 1 0" range="-0.4699 1.5568" actuatorfrcrange="-0.1468 0.1468"/>
                                    <geom type="mesh" contype="0" conaffinity="0" group="1" density="0" rgba="0.792157 0.819608 0.933333 1" mesh="left_finger1_link4"/>
                                    <geom type="mesh" rgba="0.792157 0.819608 0.933333 1" mesh="left_finger1_link4"/>
                                    <body name="left_finger1_tip_link" pos="0 0 0.0328135">
                                      <inertial pos="0.000492755 0.000153669 -0.0179109" quat="0.999371 0 -0.0354668 0" mass="0.0041" diaginertia="5.51421e-07 5.2e-07 2.68579e-07"/>
                                      <geom type="mesh" contype="0" conaffinity="0" group="1" density="0" rgba="0.792157 0.819608 0.933333 1" mesh="left_finger1_tip_link"/>
                                      <geom type="mesh" rgba="0.792157 0.819608 0.933333 1" mesh="left_finger1_tip_link"/>
                                    </body>
                                  </body>
                                </body>
                                <body name="left_finger1_link2_softbody">
                                  <inertial pos="0.00206036 -0.000368008 0.0130971" quat="-0.234766 0.824261 0.00606141 0.51521" mass="0.00855126" diaginertia="1.63312e-06 1.26464e-06 1.22907e-06"/>
                                  <geom type="mesh" contype="0" conaffinity="0" group="1" density="0" rgba="0.792157 0.819608 0.933333 1" mesh="left_finger1_link2_softbody"/>
                                  <geom type="mesh" rgba="0.792157 0.819608 0.933333 1" mesh="left_finger1_link2_softbody"/>
                                </body>
                              </body>
                            </body>
                            <body name="left_finger2_link1" pos="-0.00587009 -0.0294339 0.0919165" quat="0.991689 0.0588292 -0.0292755 0.110616">
                              <inertial pos="-0.00132905 4.18014e-08 0.000320068" quat="0.92388 0 0.382683 0" mass="0.0032" diaginertia="1.1e-07 7e-08 5e-08"/>
                              <joint name="left_finger2_joint1" pos="0 0 0" axis="0 1 0" range="-0.1585 1.5604" actuatorfrcrange="-0.6188 0.6188"/>
                              <geom type="mesh" contype="0" conaffinity="0" group="1" density="0" rgba="0.792157 0.819608 0.933333 1" mesh="left_finger2_link1"/>
                              <geom type="mesh" rgba="0.792157 0.819608 0.933333 1" mesh="left_finger2_link1"/>
                              <body name="left_finger2_link2" pos="0.0022 0 0.00400001" quat="0.707107 0 0 0.707107">
                                <inertial pos="-1.78565e-06 0.00370948 0.0184837" quat="0.70703 0.0104245 0.0104245 0.70703" mass="0.033" diaginertia="6.34e-06 6.31472e-06 8.85281e-07"/>
                                <joint name="left_finger2_joint2" pos="0 0 0" axis="0 1 0" range="-0.37 0.37" actuatorfrcrange="-0.1822 0.1822"/>
                                <geom type="mesh" contype="0" conaffinity="0" group="1" density="0" rgba="0.792157 0.819608 0.933333 1" mesh="left_finger2_link2"/>
                                <geom type="mesh" rgba="0.792157 0.819608 0.933333 1" mesh="left_finger2_link2"/>
                                <body name="left_finger2_link3" pos="0 0.00475 0.0436177" quat="0.707202 0 0 -0.707012">
                                  <inertial pos="0.000341914 -1.40911e-05 0.0134812" quat="0.999892 0 -0.0146884 0" mass="0.0165" diaginertia="1.47088e-06 1.44e-06 4.49118e-07"/>
                                  <joint name="left_finger2_joint3" pos="0 0 0" axis="0 1 0" range="-0.4777 1.5485" actuatorfrcrange="-0.2251 0.2251"/>
                                  <geom type="mesh" contype="0" conaffinity="0" group="1" density="0" rgba="0.792157 0.819608 0.933333 1" mesh="left_finger2_link3"/>
                                  <geom type="mesh" rgba="0.792157 0.819608 0.933333 1" mesh="left_finger2_link3"/>
                                  <body name="left_finger2_link4" pos="0 0 0.0295">
                                    <inertial pos="-0.000815133 -1.35285e-05 0.0107847" quat="0.994759 -0.00740613 -0.101551 -0.00930236" mass="0.014" diaginertia="9.78906e-07 8.60128e-07 2.70966e-07"/>
                                    <joint name="left_finger2_joint4" pos="0 0 0" axis="0 1 0" range="-0.4683 1.5753" actuatorfrcrange="-0.217 0.217"/>
                                    <geom type="mesh" contype="0" conaffinity="0" group="1" density="0" rgba="0.792157 0.819608 0.933333 1" mesh="left_finger2_link4"/>
                                    <geom type="mesh" rgba="0.792157 0.819608 0.933333 1" mesh="left_finger2_link4"/>
                                    <body name="left_finger2_tip_link" pos="0 0 0.024">
                                      <inertial pos="-0.000815133 -1.35285e-05 -0.0132153" quat="0.707107 0 0 0.707107" mass="0.00318" diaginertia="2.1e-07 2e-07 1.3e-07"/>
                                      <geom type="mesh" contype="0" conaffinity="0" group="1" density="0" rgba="0.792157 0.819608 0.933333 1" mesh="left_finger2_tip_link"/>
                                      <geom type="mesh" rgba="0.792157 0.819608 0.933333 1" mesh="left_finger2_tip_link"/>
                                    </body>
                                  </body>
                                </body>
                              </body>
                            </body>
                            <body name="left_finger3_link1" pos="-0.0104597 -0.00746146 0.0895435" quat="0.999048 1.26889e-05 -0.0436194 -0.000290548">
                              <inertial pos="-0.0013291 3.85118e-08 0.000319976" quat="0.92388 0 0.382683 0" mass="0.0032" diaginertia="1.1e-07 7e-08 5e-08"/>
                              <joint name="left_finger3_joint1" pos="0 0 0" axis="0 1 0" range="-0.1644 1.5516" actuatorfrcrange="-0.6494 0.6494"/>
                              <geom type="mesh" contype="0" conaffinity="0" group="1" density="0" rgba="0.792157 0.819608 0.933333 1" mesh="left_finger3_link1"/>
                              <geom type="mesh" rgba="0.792157 0.819608 0.933333 1" mesh="left_finger3_link1"/>
                              <body name="left_finger3_link2" pos="0.0022 0 0.00400001" quat="0.707107 0 0 0.707107">
                                <inertial pos="-1.82891e-06 0.00370965 0.0184837" quat="0.70703 0.0104245 0.0104245 0.70703" mass="0.033" diaginertia="6.34e-06 6.31472e-06 8.85281e-07"/>
                                <joint name="left_finger3_joint2" pos="0 0 0" axis="0 1 0" range="-0.37 0.37" actuatorfrcrange="-0.1827 0.1827"/>
                                <geom type="mesh" contype="0" conaffinity="0" group="1" density="0" rgba="0.792157 0.819608 0.933333 1" mesh="left_finger3_link2"/>
                                <geom type="mesh" rgba="0.792157 0.819608 0.933333 1" mesh="left_finger3_link2"/>
                                <body name="left_finger3_link3" pos="0 0.00475 0.0436177" quat="0.707202 0 0 -0.707012">
                                  <inertial pos="0.000333742 -1.05568e-05 0.0134866" quat="0.999892 0 -0.0146884 0" mass="0.0165" diaginertia="1.47088e-06 1.44e-06 4.49118e-07"/>
                                  <joint name="left_finger3_joint3" pos="0 0 0" axis="0 1 0" range="-0.4739 1.5512" actuatorfrcrange="-0.2078 0.2078"/>
                                  <geom type="mesh" contype="0" conaffinity="0" group="1" density="0" rgba="0.792157 0.819608 0.933333 1" mesh="left_finger3_link3"/>
                                  <geom type="mesh" rgba="0.792157 0.819608 0.933333 1" mesh="left_finger3_link3"/>
                                  <body name="left_finger3_link4" pos="0 0 0.0295">
                                    <inertial pos="-0.000815615 -1.34653e-05 0.0107846" quat="0.994759 -0.00740613 -0.101551 -0.00930236" mass="0.014" diaginertia="9.78906e-07 8.60128e-07 2.70966e-07"/>
                                    <joint name="left_finger3_joint4" pos="0 0 0" axis="0 1 0" range="-0.4684 1.5745" actuatorfrcrange="-0.2018 0.2018"/>
                                    <geom type="mesh" contype="0" conaffinity="0" group="1" density="0" rgba="0.792157 0.819608 0.933333 1" mesh="left_finger3_link4"/>
                                    <geom type="mesh" rgba="0.792157 0.819608 0.933333 1" mesh="left_finger3_link4"/>
                                    <body name="left_finger3_tip_link" pos="0 0 0.024">
                                      <inertial pos="-0.000815615 -1.34653e-05 -0.0132154" quat="0.707107 0 0 0.707107" mass="0.00318" diaginertia="2.1e-07 2e-07 1.3e-07"/>
                                      <geom type="mesh" contype="0" conaffinity="0" group="1" density="0" rgba="0.792157 0.819608 0.933333 1" mesh="left_finger3_tip_link"/>
                                      <geom type="mesh" rgba="0.792157 0.819608 0.933333 1" mesh="left_finger3_tip_link"/>
                                    </body>
                                  </body>
                                </body>
                              </body>
                            </body>
                            <body name="left_finger4_link1" pos="-0.00766486 0.0137122 0.0844287" quat="0.997789 -0.0461017 -0.0405881 -0.0254">
                              <inertial pos="-0.00132911 4.56181e-08 0.000319941" quat="0.92388 0 0.382683 0" mass="0.0032" diaginertia="1.1e-07 7e-08 5e-08"/>
                              <joint name="left_finger4_joint1" pos="0 0 0" axis="0 1 0" range="-0.1554 1.5585" actuatorfrcrange="-0.6389 0.6389"/>
                              <geom type="mesh" contype="0" conaffinity="0" group="1" density="0" rgba="0.792157 0.819608 0.933333 1" mesh="left_finger4_link1"/>
                              <geom type="mesh" rgba="0.792157 0.819608 0.933333 1" mesh="left_finger4_link1"/>
                              <body name="left_finger4_link2" pos="0.0022 0 0.00400001" quat="0.707107 0 0 0.707107">
                                <inertial pos="-1.82336e-06 0.00371493 0.0185138" quat="0.70703 0.0104245 0.0104245 0.70703" mass="0.033" diaginertia="6.34e-06 6.31472e-06 8.85281e-07"/>
                                <joint name="left_finger4_joint2" pos="0 0 0" axis="0 1 0" range="-0.37 0.37" actuatorfrcrange="-0.1832 0.1832"/>
                                <geom type="mesh" contype="0" conaffinity="0" group="1" density="0" rgba="0.792157 0.819608 0.933333 1" mesh="left_finger4_link2"/>
                                <geom type="mesh" rgba="0.792157 0.819608 0.933333 1" mesh="left_finger4_link2"/>
                                <body name="left_finger4_link3" pos="0 0.00475 0.0436177" quat="0.707202 0 0 -0.707012">
                                  <inertial pos="0.00031892 -1.03297e-05 0.0135407" quat="0.999892 0 -0.0146884 0" mass="0.0165" diaginertia="1.47088e-06 1.44e-06 4.49118e-07"/>
                                  <joint name="left_finger4_joint3" pos="0 0 0" axis="0 1 0" range="-0.4765 1.5487" actuatorfrcrange="-0.2249 0.2249"/>
                                  <geom type="mesh" contype="0" conaffinity="0" group="1" density="0" rgba="0.792157 0.819608 0.933333 1" mesh="left_finger4_link3"/>
                                  <geom type="mesh" rgba="0.792157 0.819608 0.933333 1" mesh="left_finger4_link3"/>
                                  <body name="left_finger4_link4" pos="0 0 0.0295">
                                    <inertial pos="-0.000864592 -1.02217e-05 0.0108394" quat="0.994759 -0.00740613 -0.101551 -0.00930236" mass="0.014" diaginertia="9.78906e-07 8.60128e-07 2.70966e-07"/>
                                    <joint name="left_finger4_joint4" pos="0 0 0" axis="0 1 0" range="-0.4777 1.5634" actuatorfrcrange="-0.2044 0.2044"/>
                                    <geom type="mesh" contype="0" conaffinity="0" group="1" density="0" rgba="0.792157 0.819608 0.933333 1" mesh="left_finger4_link4"/>
                                    <geom type="mesh" rgba="0.792157 0.819608 0.933333 1" mesh="left_finger4_link4"/>
                                    <body name="left_finger4_tip_link" pos="0 0 0.024">
                                      <inertial pos="-0.000864592 -1.02217e-05 -0.0131606" quat="0.707107 0 0 0.707107" mass="0.00318" diaginertia="2.1e-07 2e-07 1.3e-07"/>
                                      <geom type="mesh" contype="0" conaffinity="0" group="1" density="0" rgba="0.792157 0.819608 0.933333 1" mesh="left_finger4_tip_link"/>
                                      <geom type="mesh" rgba="0.792157 0.819608 0.933333 1" mesh="left_finger4_tip_link"/>
                                    </body>
                                  </body>
                                </body>
                              </body>
                            </body>
                            <body name="left_finger5_link1" pos="-0.00226865 0.0340011 0.0742813" quat="0.990869 -0.0993173 -0.0383255 -0.0827362">
                              <inertial pos="-0.00132912 3.31411e-08 0.000319867" quat="0.92388 0 0.382683 0" mass="0.0032" diaginertia="1.1e-07 7e-08 5e-08"/>
                              <joint name="left_finger5_joint1" pos="0 0 0" axis="0 1 0" range="-0.1626 1.5585" actuatorfrcrange="-0.6441 0.6441"/>
                              <geom type="mesh" contype="0" conaffinity="0" group="1" density="0" rgba="0.792157 0.819608 0.933333 1" mesh="left_finger5_link1"/>
                              <geom type="mesh" rgba="0.792157 0.819608 0.933333 1" mesh="left_finger5_link1"/>
                              <body name="left_finger5_link2" pos="0.0022 0 0.00400001" quat="0.707107 0 0 0.707107">
                                <inertial pos="-1.8211e-06 0.00371684 0.0193334" quat="0.70703 0.0104245 0.0104245 0.70703" mass="0.033" diaginertia="6.34e-06 6.31472e-06 8.85281e-07"/>
                                <joint name="left_finger5_joint2" pos="0 0 0" axis="0 1 0" range="-0.37 0.37" actuatorfrcrange="-0.1798 0.1798"/>
                                <geom type="mesh" contype="0" conaffinity="0" group="1" density="0" rgba="0.792157 0.819608 0.933333 1" mesh="left_finger5_link2"/>
                                <geom type="mesh" rgba="0.792157 0.819608 0.933333 1" mesh="left_finger5_link2"/>
                                <body name="left_finger5_link3" pos="0 0.00475 0.0436177" quat="0.707202 0 0 -0.707012">
                                  <inertial pos="0.000353514 -5.08998e-06 0.0139268" quat="0.999892 0 -0.0146884 0" mass="0.0165" diaginertia="1.47088e-06 1.44e-06 4.49118e-07"/>
                                  <joint name="left_finger5_joint3" pos="0 0 0" axis="0 1 0" range="-0.4768 1.549" actuatorfrcrange="-0.2384 0.2384"/>
                                  <geom type="mesh" contype="0" conaffinity="0" group="1" density="0" rgba="0.792157 0.819608 0.933333 1" mesh="left_finger5_link3"/>
                                  <geom type="mesh" rgba="0.792157 0.819608 0.933333 1" mesh="left_finger5_link3"/>
                                  <body name="left_finger5_link4" pos="0 0 0.0295">
                                    <inertial pos="-0.000906048 1.84282e-05 0.0122759" quat="0.994759 -0.00740613 -0.101551 -0.00930236" mass="0.014" diaginertia="9.78906e-07 8.60128e-07 2.70966e-07"/>
                                    <joint name="left_finger5_joint4" pos="0 0 0" axis="0 1 0" range="-0.4683 1.5735" actuatorfrcrange="-0.1866 0.1866"/>
                                    <geom type="mesh" contype="0" conaffinity="0" group="1" density="0" rgba="0.792157 0.819608 0.933333 1" mesh="left_finger5_link4"/>
                                    <geom type="mesh" rgba="0.792157 0.819608 0.933333 1" mesh="left_finger5_link4"/>
                                    <body name="left_finger5_tip_link" pos="0 0 0.026">
                                      <inertial pos="-0.000906048 1.84282e-05 -0.0137241" quat="0.707107 0 0 0.707107" mass="0.00318" diaginertia="2.1e-07 2e-07 1.3e-07"/>
                                      <geom type="mesh" contype="0" conaffinity="0" group="1" density="0" rgba="0.792157 0.819608 0.933333 1" mesh="left_finger5_tip_link"/>
                                      <geom type="mesh" rgba="0.792157 0.819608 0.933333 1" mesh="left_finger5_tip_link"/>
                                    </body>
                                  </body>
                                </body>
                              </body>
                            </body>
                          </body>
                        </body>
                        <body name="left_camera_adapter_link" pos="0 -0.1 0" quat="0.65328 0.270597 -0.270598 -0.653283">
                          <inertial pos="0.008437 0 0.042705" mass="0.05" diaginertia="0.0001104 9.298e-05 2.343e-05"/>
                          <geom type="mesh" contype="0" conaffinity="0" group="1" density="0" rgba="0.55 0.55 0.55 1" mesh="camera_adapter_link"/>
                          <geom type="mesh" rgba="0.55 0.55 0.55 1" mesh="camera_adapter_link"/>
                          <body name="left_wrist_camera_bottom_screw_frame" pos="0.01137 0 0.0885" quat="0.92388 0 0.382683 0">
                            <body name="left_wrist_camera_link" pos="0.0106 0.0175 0.0125">
                              <inertial pos="0 0 0" quat="0.707107 0.707107 0 0" mass="0.072" diaginertia="0.00388124 0.00387926 0.00049894"/>
                              <geom size="0.012525 0.045 0.0125" pos="0 -0.0175 0" type="box"/>
                              <body name="left_wrist_camera_depth_frame">
                                <body name="left_wrist_camera_depth_optical_frame" quat="0.5 -0.5 0.5 -0.5"/>
                              </body>
                              <body name="left_wrist_camera_infra1_frame">
                                <body name="left_wrist_camera_infra1_optical_frame" quat="0.5 -0.5 0.5 -0.5"/>
                              </body>
                              <body name="left_wrist_camera_infra2_frame" pos="0 -0.05 0">
                                <body name="left_wrist_camera_infra2_optical_frame" quat="0.5 -0.5 0.5 -0.5"/>
                              </body>
                              <body name="left_wrist_camera_color_frame" pos="0 0.015 0">
                                <body name="left_wrist_camera_color_optical_frame" quat="0.5 -0.5 0.5 -0.5"/>
                              </body>
                              <body name="left_wrist_camera_accel_frame" pos="-0.01174 -0.00552 0.0051">
                                <body name="left_wrist_camera_accel_optical_frame" quat="0.5 -0.5 0.5 -0.5"/>
                              </body>
                              <body name="left_wrist_camera_gyro_frame" pos="-0.01174 -0.00552 0.0051">
                                <body name="left_wrist_camera_gyro_optical_frame" quat="0.5 -0.5 0.5 -0.5"/>
                              </body>
                            </body>
                          </body>
                        </body>
                      </body>
                    </body>
                  </body>
                </body>
              </body>
            </body>
          </body>
        </body>
        <body name="Base_R" pos="0.0252 -0.04725 0.065" quat="0.499998 0.5 -0.5 0.500002">
          <inertial pos="0.00032267 4.798e-05 0.0406635" quat="0.582787 0.36644 -0.620273 0.375956" mass="1.1962" diaginertia="0.00127375 0.00107367 0.00106904"/>
          <geom type="mesh" contype="0" conaffinity="0" group="1" density="0" rgba="1 0 0 1" mesh="Base_R"/>
          <geom type="mesh" rgba="1 0 0 1" mesh="Base_R"/>
          <body name="Link1_R" pos="0 0 0.1745">
            <inertial pos="2.347e-05 0.0055715 -0.03076" quat="0.711599 0.0343691 -0.0341702 0.700912" mass="1.9705" diaginertia="0.00529754 0.00492285 0.00184874"/>
            <joint name="Joint1_R" pos="0 0 0" axis="0 0 1" range="-3.1067 3.1067" actuatorfrcrange="-108 108"/>
            <geom type="mesh" contype="0" conaffinity="0" group="1" density="0" rgba="0 1 0 1" mesh="Link1_R"/>
            <geom type="mesh" rgba="0 1 0 1" mesh="Link1_R"/>
            <body name="Link2_R" quat="0.707105 0.707108 0 0">
              <inertial pos="0.00013483 0.0617046 0.00950639" quat="0.643375 0.765551 -3.57328e-05 0.000294349" mass="2.24398" diaginertia="0.0119493 0.0112156 0.00338374"/>
              <joint name="Joint2_R" pos="0 0 0" axis="0 0 1" range="-2.0944 2.0944" actuatorfrcrange="-108 108"/>
              <geom type="mesh" contype="0" conaffinity="0" group="1" density="0" rgba="0 0 1 1" mesh="Link2_R"/>
              <geom type="mesh" rgba="0 0 1 1" mesh="Link2_R"/>
              <body name="Link3_R" pos="0 0.287 0" quat="0.707105 -0.707108 0 0">
                <inertial pos="0.00968562 0.00246599 -0.046273" quat="0.782446 -0.0355285 -0.0735516 0.617337" mass="1.9242" diaginertia="0.00765215 0.00730789 0.0016338"/>
                <joint name="Joint3_R" pos="0 0 0" axis="0 0 1" range="-3.1067 3.1067" actuatorfrcrange="-66 66"/>
                <geom type="mesh" contype="0" conaffinity="0" group="1" density="0" rgba="1 0 0 1" mesh="Link3_R"/>
                <geom type="mesh" rgba="1 0 0 1" mesh="Link3_R"/>
                <body name="Link4_R" pos="0.018 0 0" quat="-2.59734e-06 2.59735e-06 -0.707108 0.707105">
                  <inertial pos="0.00850411 -0.0471822 0.00941509" quat="0.741754 0.628694 0.0774999 -0.220317" mass="1.6085" diaginertia="0.00603244 0.00535875 0.00198228"/>
                  <joint name="Joint4_R" pos="0 0 0" axis="0 0 1" range="-2.5307 1.0472" actuatorfrcrange="-66 66"/>
                  <geom type="mesh" contype="0" conaffinity="0" group="1" density="0" rgba="0 1 0 1" mesh="Link4_R"/>
                  <geom type="mesh" rgba="0 1 0 1" mesh="Link4_R"/>
                  <body name="Link5_R" pos="0.018 -0.314 0" quat="-2.59734e-06 2.59735e-06 -0.707108 0.707105">
                    <inertial pos="-0.00051127 -0.00101064 -0.112717" quat="0.999438 0.00995046 0.00675781 0.0312997" mass="2.0883" diaginertia="0.00626924 0.00564262 0.00243436"/>
                    <joint name="Joint5_R" pos="0 0 0" axis="0 0 1" range="-3.1067 3.1067" actuatorfrcrange="-18 18"/>
                    <geom type="mesh" contype="0" conaffinity="0" group="1" density="0" rgba="0 0 1 1" mesh="Link5_R"/>
                    <geom type="mesh" rgba="0 0 1 1" mesh="Link5_R"/>
                    <body name="Link6_R" quat="0.499998 0.5 -0.5 0.500002">
                      <inertial pos="0.00032659 -0.00531336 0.00030182" quat="0.695472 -0.00407878 0.0225408 0.718188" mass="0.72496" diaginertia="0.000517351 0.000460362 0.000425057"/>
                      <joint name="Joint6_R" pos="0 0 0" axis="0 0 1" range="-1.0472 1.0472" actuatorfrcrange="-18 18"/>
                      <geom type="mesh" contype="0" conaffinity="0" group="1" density="0" rgba="1 0 0 1" mesh="Link6_R"/>
                      <geom type="mesh" rgba="1 0 0 1" mesh="Link6_R"/>
                      <body name="Link7_R" quat="0.499998 0.5 -0.5 0.500002">
                        <inertial pos="-9.108e-05 -0.0315325 0.00889371" quat="0.84481 0.535026 0.00229584 -0.00609725" mass="0.68606" diaginertia="0.00173691 0.00153911 0.000745263"/>
                        <joint name="Joint7_R" pos="0 0 0" axis="0 0 1" range="-1.5708 1.5708" actuatorfrcrange="-18 18"/>
                        <geom type="mesh" contype="0" conaffinity="0" group="1" density="0" rgba="0 1 0 1" mesh="Link7_R"/>
                        <geom type="mesh" rgba="0 1 0 1" mesh="Link7_R"/>
                        <body name="right_hand_docking_link" pos="0 -0.1 0" quat="0.707105 0.707108 0 0">
                          <inertial pos="0 0.000613 0.008094" quat="0.435285 0.5573 -0.557322 0.435127" mass="0.051956" diaginertia="1.93305e-05 1.81473e-05 1.72441e-05"/>
                          <geom type="mesh" contype="0" conaffinity="0" group="1" density="0" rgba="0.792157 0.819608 0.933333 1" mesh="hand_docking_link"/>
                          <geom type="mesh" rgba="0.792157 0.819608 0.933333 1" mesh="hand_docking_link"/>
                          <body name="right_palm_link" pos="0 0 0.05" quat="0.92388 0 0 -0.382683">
                            <inertial pos="0.00152445 0.00264235 0.0376699" quat="0.994582 -0.0930829 -0.0427472 0.0177281" mass="0.16914" diaginertia="0.000140677 9.58896e-05 5.81329e-05"/>
                            <geom type="mesh" contype="0" conaffinity="0" group="1" density="0" rgba="0.627451 0.627451 0.627451 1" mesh="right_palm_link"/>
                            <geom type="mesh" rgba="0.627451 0.627451 0.627451 1" mesh="right_palm_link"/>
                            <body name="right_finger1_link1" pos="0.0085244 0.020575 0.028712" quat="0.682219 -0.617669 0.0805047 -0.382859">
                              <inertial pos="-0.0099171 -0.0059845 0.00152324" quat="0.904243 0.21652 0.0443878 -0.365368" mass="0.0075" diaginertia="3.37599e-07 3.01198e-07 2.11203e-07"/>
                              <joint name="right_finger1_joint1" pos="0 0 0" axis="0 1 0" range="0.0475 1.6033" actuatorfrcrange="-0.4452 0.4452"/>
                              <geom type="mesh" contype="0" conaffinity="0" group="1" density="0" rgba="0.792157 0.819608 0.933333 1" mesh="right_finger1_link1"/>
                              <geom type="mesh" rgba="0.792157 0.819608 0.933333 1" mesh="right_finger1_link1"/>
                              <body name="right_finger1_link2" pos="-0.0047549 -0.0060191 0.014132" quat="0.726252 0.290851 -0.0855912 -0.616958">
                                <inertial pos="-0.0011196 1.23749e-05 0.0156635" quat="0.815906 0.0024483 -0.00462559 0.57816" mass="0.0248" diaginertia="2.81725e-06 2.75299e-06 6.79766e-07"/>
                                <joint name="right_finger1_joint2" pos="0 0 0" axis="0 1 0" range="-0.1387 0.9324" actuatorfrcrange="-0.4259 0.4259"/>
                                <geom type="mesh" contype="0" conaffinity="0" group="1" density="0" rgba="0.792157 0.819608 0.933333 1" mesh="right_finger1_link2"/>
                                <geom type="mesh" rgba="0.792157 0.819608 0.933333 1" mesh="right_finger1_link2"/>
                                <body name="right_finger1_link3" pos="-0.00037714 0.001058 0.034673" quat="0.815725 0.015003 0.0212383 0.577855">
                                  <inertial pos="0.000775215 -0.000210057 0.0127726" quat="0.999951 0 0.00989566 0" mass="0.0165" diaginertia="1.4604e-06 1.42e-06 4.49604e-07"/>
                                  <joint name="right_finger1_joint3" pos="0 0 0" axis="0 1 0" range="-0.4642 1.5623" actuatorfrcrange="-0.1888 0.1888"/>
                                  <geom type="mesh" contype="0" conaffinity="0" group="1" density="0" rgba="0.792157 0.819608 0.933333 1" mesh="right_finger1_link3"/>
                                  <geom type="mesh" rgba="0.792157 0.819608 0.933333 1" mesh="right_finger1_link3"/>
                                  <body name="right_finger1_link4" pos="0 0 0.0295">
                                    <inertial pos="0.000494269 -0.0001544 0.0149072" quat="0.704494 -0.0607308 -0.0607308 0.704494" mass="0.0165" diaginertia="1.25e-06 1.20084e-06 4.89156e-07"/>
                                    <joint name="right_finger1_joint4" pos="0 0 0" axis="0 1 0" range="-0.4699 1.5568" actuatorfrcrange="-0.1468 0.1468"/>
                                    <geom type="mesh" contype="0" conaffinity="0" group="1" density="0" rgba="0.792157 0.819608 0.933333 1" mesh="right_finger1_link4"/>
                                    <geom type="mesh" rgba="0.792157 0.819608 0.933333 1" mesh="right_finger1_link4"/>
                                    <body name="right_finger1_tip_link" pos="0.00026399 -0.00020119 0.032808">
                                      <inertial pos="0.000230276 4.67896e-05 -0.0179008" quat="0.999371 0 -0.0354668 0" mass="0.0041" diaginertia="5.51421e-07 5.2e-07 2.68579e-07"/>
                                      <geom type="mesh" contype="0" conaffinity="0" group="1" density="0" rgba="0.792157 0.819608 0.933333 1" mesh="right_finger1_tip_link"/>
                                      <geom type="mesh" rgba="0.792157 0.819608 0.933333 1" mesh="right_finger1_tip_link"/>
                                    </body>
                                  </body>
                                </body>
                                <body name="right_finger1_link2_softbody">
                                  <inertial pos="-0.00205925 -0.000366961 0.0130977" quat="0.00451527 0.515324 -0.232234 0.824917" mass="0.00855317" diaginertia="1.63347e-06 1.265e-06 1.22924e-06"/>
                                  <geom type="mesh" contype="0" conaffinity="0" group="1" density="0" rgba="0.792157 0.819608 0.933333 1" mesh="right_finger1_link2_softbody"/>
                                  <geom type="mesh" rgba="0.792157 0.819608 0.933333 1" mesh="right_finger1_link2_softbody"/>
                                </body>
                              </body>
                            </body>
                            <body name="right_finger2_link1" pos="-0.0058701 0.029434 0.091917" quat="0.991689 -0.0588295 -0.0292755 -0.110614">
                              <inertial pos="-0.00132914 -2.06891e-08 0.000319815" quat="0.92388 0 0.382683 0" mass="0.0032" diaginertia="1.1e-07 7e-08 5e-08"/>
                              <joint name="right_finger2_joint1" pos="0 0 0" axis="0 1 0" range="-0.1585 1.5604" actuatorfrcrange="-0.6188 0.6188"/>
                              <geom type="mesh" contype="0" conaffinity="0" group="1" density="0" rgba="0.792157 0.819608 0.933333 1" mesh="right_finger2_link1"/>
                              <geom type="mesh" rgba="0.792157 0.819608 0.933333 1" mesh="right_finger2_link1"/>
                              <body name="right_finger2_link2" pos="0.0022 0 0.00400001" quat="0.707107 0 0 0.707107">
                                <inertial pos="1.85614e-06 0.00370979 0.0184837" quat="0.70703 0.0104245 0.0104245 0.70703" mass="0.033" diaginertia="6.34e-06 6.31472e-06 8.85281e-07"/>
                                <joint name="right_finger2_joint2" pos="0 0 0" axis="0 1 0" range="-0.37 0.37" actuatorfrcrange="-0.1822 0.1822"/>
                                <geom type="mesh" contype="0" conaffinity="0" group="1" density="0" rgba="0.792157 0.819608 0.933333 1" mesh="right_finger2_link2"/>
                                <geom type="mesh" rgba="0.792157 0.819608 0.933333 1" mesh="right_finger2_link2"/>
                                <body name="right_finger2_link3" pos="0 0.00475028 0.0436177" quat="0.707012 0 0 -0.707202">
                                  <inertial pos="0.000342045 1.41767e-05 0.0134814" quat="0.999892 0 -0.0146884 0" mass="0.0165" diaginertia="1.47088e-06 1.44e-06 4.49118e-07"/>
                                  <joint name="right_finger2_joint3" pos="0 0 0" axis="0 1 0" range="-0.4777 1.5485" actuatorfrcrange="-0.2251 0.2251"/>
                                  <geom type="mesh" contype="0" conaffinity="0" group="1" density="0" rgba="0.792157 0.819608 0.933333 1" mesh="right_finger2_link3"/>
                                  <geom type="mesh" rgba="0.792157 0.819608 0.933333 1" mesh="right_finger2_link3"/>
                                  <body name="right_finger2_link4" pos="0 0 0.0295">
                                    <inertial pos="-0.000815042 1.343e-05 0.0107855" quat="0.994759 -0.00740613 -0.101551 -0.00930236" mass="0.014" diaginertia="9.78906e-07 8.60128e-07 2.70966e-07"/>
                                    <joint name="right_finger2_joint4" pos="0 0 0" axis="0 1 0" range="-0.4683 1.5753" actuatorfrcrange="-0.217 0.217"/>
                                    <geom type="mesh" contype="0" conaffinity="0" group="1" density="0" rgba="0.792157 0.819608 0.933333 1" mesh="right_finger2_link4"/>
                                    <geom type="mesh" rgba="0.792157 0.819608 0.933333 1" mesh="right_finger2_link4"/>
                                    <body name="right_finger2_tip_link" pos="-0.000749345 0 0.024">
                                      <inertial pos="-6.56106e-05 1.33496e-05 -0.0132145" quat="0.707107 0 0 0.707107" mass="0.00318" diaginertia="2.1e-07 2e-07 1.3e-07"/>
                                      <geom type="mesh" contype="0" conaffinity="0" group="1" density="0" rgba="0.792157 0.819608 0.933333 1" mesh="right_finger2_tip_link"/>
                                      <geom type="mesh" rgba="0.792157 0.819608 0.933333 1" mesh="right_finger2_tip_link"/>
                                    </body>
                                  </body>
                                </body>
                              </body>
                            </body>
                            <body name="right_finger3_link1" pos="-0.01046 0.0074615 0.089544" quat="0.999048 -1.26848e-05 -0.0436192 0.000290547">
                              <inertial pos="-0.00132908 3.41333e-09 0.000319983" quat="0.92388 0 0.382683 0" mass="0.0032" diaginertia="1.1e-07 7e-08 5e-08"/>
                              <joint name="right_finger3_joint1" pos="0 0 0" axis="0 1 0" range="-0.1644 1.5516" actuatorfrcrange="-0.6494 0.6494"/>
                              <geom type="mesh" contype="0" conaffinity="0" group="1" density="0" rgba="0.792157 0.819608 0.933333 1" mesh="right_finger3_link1"/>
                              <geom type="mesh" rgba="0.792157 0.819608 0.933333 1" mesh="right_finger3_link1"/>
                              <body name="right_finger3_link2" pos="0.0022 0 0.00400001" quat="0.707107 0 0 0.707107">
                                <inertial pos="1.86459e-06 0.0037098 0.0184837" quat="0.70703 0.0104245 0.0104245 0.70703" mass="0.033" diaginertia="6.34e-06 6.31472e-06 8.85281e-07"/>
                                <joint name="right_finger3_joint2" pos="0 0 0" axis="0 1 0" range="-0.37 0.37" actuatorfrcrange="-0.1827 0.1827"/>
                                <geom type="mesh" contype="0" conaffinity="0" group="1" density="0" rgba="0.792157 0.819608 0.933333 1" mesh="right_finger3_link2"/>
                                <geom type="mesh" rgba="0.792157 0.819608 0.933333 1" mesh="right_finger3_link2"/>
                                <body name="right_finger3_link3" pos="0 0.00475 0.0436177" quat="0.707012 0 0 -0.707202">
                                  <inertial pos="0.00033388 1.06802e-05 0.0134865" quat="0.999892 0 -0.0146884 0" mass="0.0165" diaginertia="1.47088e-06 1.44e-06 4.49118e-07"/>
                                  <joint name="right_finger3_joint3" pos="0 0 0" axis="0 1 0" range="-0.4739 1.5512" actuatorfrcrange="-0.2078 0.2078"/>
                                  <geom type="mesh" contype="0" conaffinity="0" group="1" density="0" rgba="0.792157 0.819608 0.933333 1" mesh="right_finger3_link3"/>
                                  <geom type="mesh" rgba="0.792157 0.819608 0.933333 1" mesh="right_finger3_link3"/>
                                  <body name="right_finger3_link4" pos="0 0 0.0295">
                                    <inertial pos="-0.000815351 1.33727e-05 0.0107852" quat="0.994759 -0.00740613 -0.101551 -0.00930236" mass="0.014" diaginertia="9.78906e-07 8.60128e-07 2.70966e-07"/>
                                    <joint name="right_finger3_joint4" pos="0 0 0" axis="0 1 0" range="-0.4684 1.5745" actuatorfrcrange="-0.2018 0.2018"/>
                                    <geom type="mesh" contype="0" conaffinity="0" group="1" density="0" rgba="0.792157 0.819608 0.933333 1" mesh="right_finger3_link4"/>
                                    <geom type="mesh" rgba="0.792157 0.819608 0.933333 1" mesh="right_finger3_link4"/>
                                    <body name="right_finger3_tip_link" pos="-0.00075 0 0.024" quat="1 0 0 -0.000156524">
                                      <inertial pos="-6.53558e-05 1.32723e-05 -0.0132148" quat="0.707107 0 0 0.707107" mass="0.00318" diaginertia="2.1e-07 2e-07 1.3e-07"/>
                                      <geom type="mesh" contype="0" conaffinity="0" group="1" density="0" rgba="0.792157 0.819608 0.933333 1" mesh="right_finger3_tip_link"/>
                                      <geom type="mesh" rgba="0.792157 0.819608 0.933333 1" mesh="right_finger3_tip_link"/>
                                    </body>
                                  </body>
                                </body>
                              </body>
                            </body>
                            <body name="right_finger4_link1" pos="-0.0076649 -0.013712 0.084429" quat="0.997789 0.0461019 -0.0405884 0.0254002">
                              <inertial pos="-0.00132912 1.24361e-09 0.000319884" quat="0.92388 0 0.382683 0" mass="0.0032" diaginertia="1.1e-07 7e-08 5e-08"/>
                              <joint name="right_finger4_joint1" pos="0 0 0" axis="0 1 0" range="-0.1554 1.5585" actuatorfrcrange="-0.6389 0.6389"/>
                              <geom type="mesh" contype="0" conaffinity="0" group="1" density="0" rgba="0.792157 0.819608 0.933333 1" mesh="right_finger4_link1"/>
                              <geom type="mesh" rgba="0.792157 0.819608 0.933333 1" mesh="right_finger4_link1"/>
                              <body name="right_finger4_link2" pos="0.0022 0 0.00400001" quat="0.707107 -0.000213851 -0.000213851 0.707107">
                                <inertial pos="1.84945e-06 0.00370375 0.0185161" quat="0.70703 0.0104245 0.0104245 0.70703" mass="0.033" diaginertia="6.34e-06 6.31472e-06 8.85281e-07"/>
                                <joint name="right_finger4_joint2" pos="0 0 0" axis="0 1 0" range="-0.37 0.37" actuatorfrcrange="-0.1832 0.1832"/>
                                <geom type="mesh" contype="0" conaffinity="0" group="1" density="0" rgba="0.792157 0.819608 0.933333 1" mesh="right_finger4_link2"/>
                                <geom type="mesh" rgba="0.792157 0.819608 0.933333 1" mesh="right_finger4_link2"/>
                                <body name="right_finger4_link3" pos="0 0.00472362 0.0436206" quat="0.707012 0.00021388 0.000213823 -0.707202">
                                  <inertial pos="0.000319082 1.04411e-05 0.0135409" quat="0.999892 0 -0.0146884 0" mass="0.0165" diaginertia="1.47088e-06 1.44e-06 4.49118e-07"/>
                                  <joint name="right_finger4_joint3" pos="0 0 0" axis="0 1 0" range="-0.4765 1.5487" actuatorfrcrange="-0.2249 0.2249"/>
                                  <geom type="mesh" contype="0" conaffinity="0" group="1" density="0" rgba="0.792157 0.819608 0.933333 1" mesh="right_finger4_link3"/>
                                  <geom type="mesh" rgba="0.792157 0.819608 0.933333 1" mesh="right_finger4_link3"/>
                                  <body name="right_finger4_link4" pos="0 0 0.0295">
                                    <inertial pos="-0.000865094 1.02481e-05 0.0108406" quat="0.994759 -0.00740613 -0.101551 -0.00930236" mass="0.014" diaginertia="9.78906e-07 8.60128e-07 2.70966e-07"/>
                                    <joint name="right_finger4_joint4" pos="0 0 0" axis="0 1 0" range="-0.4777 1.5634" actuatorfrcrange="-0.2044 0.2044"/>
                                    <geom type="mesh" contype="0" conaffinity="0" group="1" density="0" rgba="0.792157 0.819608 0.933333 1" mesh="right_finger4_link4"/>
                                    <geom type="mesh" rgba="0.792157 0.819608 0.933333 1" mesh="right_finger4_link4"/>
                                    <body name="right_finger4_tip_link" pos="-0.000811164 0 0.0239995">
                                      <inertial pos="-5.39302e-05 1.01852e-05 -0.0131589" quat="0.707107 0 0 0.707107" mass="0.00318" diaginertia="2.1e-07 2e-07 1.3e-07"/>
                                      <geom type="mesh" contype="0" conaffinity="0" group="1" density="0" rgba="0.792157 0.819608 0.933333 1" mesh="right_finger4_tip_link"/>
                                      <geom type="mesh" rgba="0.792157 0.819608 0.933333 1" mesh="right_finger4_tip_link"/>
                                    </body>
                                  </body>
                                </body>
                              </body>
                            </body>
                            <body name="right_finger5_link1" pos="-0.00226865 -0.0340011 0.0742813" quat="0.990869 0.0993173 -0.0383255 0.0827362">
                              <inertial pos="-0.00132913 1.08611e-08 0.000319899" quat="0.92388 0 0.382683 0" mass="0.0032" diaginertia="1.1e-07 7e-08 5e-08"/>
                              <joint name="right_finger5_joint1" pos="0 0 0" axis="0 1 0" range="-0.1626 1.5585" actuatorfrcrange="-0.6441 0.6441"/>
                              <geom type="mesh" contype="0" conaffinity="0" group="1" density="0" rgba="0.792157 0.819608 0.933333 1" mesh="right_finger5_link1"/>
                              <geom type="mesh" rgba="0.792157 0.819608 0.933333 1" mesh="right_finger5_link1"/>
                              <body name="right_finger5_link2" pos="0.0022 0 0.00400001" quat="0.707107 -0.00026748 -0.00026748 0.707107">
                                <inertial pos="1.84966e-06 0.0037023 0.0193362" quat="0.70703 0.0104245 0.0104245 0.70703" mass="0.033" diaginertia="6.34e-06 6.31472e-06 8.85281e-07"/>
                                <joint name="right_finger5_joint2" pos="0 0 0" axis="0 1 0" range="-0.37 0.37" actuatorfrcrange="-0.1798 0.1798"/>
                                <geom type="mesh" contype="0" conaffinity="0" group="1" density="0" rgba="0.792157 0.819608 0.933333 1" mesh="right_finger5_link2"/>
                                <geom type="mesh" rgba="0.792157 0.819608 0.933333 1" mesh="right_finger5_link2"/>
                                <body name="right_finger5_link3" pos="0 0.004717 0.0436213" quat="0.707012 0.000267516 0.000267444 -0.707202">
                                  <inertial pos="0.000328501 5.05492e-06 0.0142853" quat="0.999892 0 -0.0146884 0" mass="0.0165" diaginertia="1.47088e-06 1.44e-06 4.49118e-07"/>
                                  <joint name="right_finger5_joint3" pos="0 0 0" axis="0 1 0" range="-0.4768 1.549" actuatorfrcrange="-0.2384 0.2384"/>
                                  <geom type="mesh" contype="0" conaffinity="0" group="1" density="0" rgba="0.792157 0.819608 0.933333 1" mesh="right_finger5_link3"/>
                                  <geom type="mesh" rgba="0.792157 0.819608 0.933333 1" mesh="right_finger5_link3"/>
                                  <body name="right_finger5_link4" pos="0 0 0.0295">
                                    <inertial pos="-0.000908093 -1.90466e-05 0.0122784" quat="0.994759 -0.00740613 -0.101551 -0.00930236" mass="0.014" diaginertia="9.78906e-07 8.60128e-07 2.70966e-07"/>
                                    <joint name="right_finger5_joint4" pos="0 0 0" axis="0 1 0" range="-0.4683 1.5735" actuatorfrcrange="-0.1866 0.1866"/>
                                    <geom type="mesh" contype="0" conaffinity="0" group="1" density="0" rgba="0.792157 0.819608 0.933333 1" mesh="right_finger5_link4"/>
                                    <geom type="mesh" rgba="0.792157 0.819608 0.933333 1" mesh="right_finger5_link4"/>
                                    <body name="right_finger5_tip_link" pos="-0.000828016 0 0.0259994">
                                      <inertial pos="-8.00771e-05 -1.91046e-05 -0.013721" quat="0.707107 0 0 0.707107" mass="0.00318" diaginertia="2.1e-07 2e-07 1.3e-07"/>
                                      <geom type="mesh" contype="0" conaffinity="0" group="1" density="0" rgba="0.792157 0.819608 0.933333 1" mesh="right_finger5_tip_link"/>
                                      <geom type="mesh" rgba="0.792157 0.819608 0.933333 1" mesh="right_finger5_tip_link"/>
                                    </body>
                                  </body>
                                </body>
                              </body>
                            </body>
                          </body>
                        </body>
                        <body name="right_camera_adapter_link" pos="0 -0.1 0" quat="0.65328 -0.270597 0.270598 -0.653283">
                          <inertial pos="0.008437 0 0.042705" mass="0.05" diaginertia="0.0001104 9.298e-05 2.343e-05"/>
                          <geom type="mesh" contype="0" conaffinity="0" group="1" density="0" rgba="0.55 0.55 0.55 1" mesh="camera_adapter_link"/>
                          <geom type="mesh" rgba="0.55 0.55 0.55 1" mesh="camera_adapter_link"/>
                          <body name="right_wrist_camera_bottom_screw_frame" pos="0.01137 0 0.0885" quat="0.92388 0 0.382683 0">
                            <body name="right_wrist_camera_link" pos="0.0106 0.0175 0.0125">
                              <inertial pos="0 0 0" quat="0.707107 0.707107 0 0" mass="0.072" diaginertia="0.00388124 0.00387926 0.00049894"/>
                              <geom size="0.012525 0.045 0.0125" pos="0 -0.0175 0" type="box"/>
                              <body name="right_wrist_camera_depth_frame">
                                <body name="right_wrist_camera_depth_optical_frame" quat="0.5 -0.5 0.5 -0.5"/>
                              </body>
                              <body name="right_wrist_camera_infra1_frame">
                                <body name="right_wrist_camera_infra1_optical_frame" quat="0.5 -0.5 0.5 -0.5"/>
                              </body>
                              <body name="right_wrist_camera_infra2_frame" pos="0 -0.05 0">
                                <body name="right_wrist_camera_infra2_optical_frame" quat="0.5 -0.5 0.5 -0.5"/>
                              </body>
                              <body name="right_wrist_camera_color_frame" pos="0 0.015 0">
                                <body name="right_wrist_camera_color_optical_frame" quat="0.5 -0.5 0.5 -0.5"/>
                              </body>
                              <body name="right_wrist_camera_accel_frame" pos="-0.01174 -0.00552 0.0051">
                                <body name="right_wrist_camera_accel_optical_frame" quat="0.5 -0.5 0.5 -0.5"/>
                              </body>
                              <body name="right_wrist_camera_gyro_frame" pos="-0.01174 -0.00552 0.0051">
                                <body name="right_wrist_camera_gyro_optical_frame" quat="0.5 -0.5 0.5 -0.5"/>
                              </body>
                            </body>
                          </body>
                        </body>
                      </body>
                    </body>
                  </body>
                </body>
              </body>
            </body>
          </body>
        </body>
      </body>
      <body name="head_camera_bottom_screw_frame" pos="0.35 0.0070867 1.3124" quat="0.887011 0 0.461749 0">
        <body name="head_camera_link" pos="0.0106 0.0175 0.0125">
          <inertial pos="0 0 0" quat="0.707107 0.707107 0 0" mass="0.072" diaginertia="0.00388124 0.00387926 0.00049894"/>
          <geom size="0.012525 0.045 0.0125" pos="0 -0.0175 0" type="box"/>
          <body name="head_camera_depth_frame">
            <body name="head_camera_depth_optical_frame" quat="0.5 -0.5 0.5 -0.5"/>
          </body>
          <body name="head_camera_infra1_frame">
            <body name="head_camera_infra1_optical_frame" quat="0.5 -0.5 0.5 -0.5"/>
          </body>
          <body name="head_camera_infra2_frame" pos="0 -0.05 0">
            <body name="head_camera_infra2_optical_frame" quat="0.5 -0.5 0.5 -0.5"/>
          </body>
          <body name="head_camera_color_frame" pos="0 0.015 0">
            <body name="head_camera_color_optical_frame" quat="0.5 -0.5 0.5 -0.5"/>
          </body>
          <body name="head_camera_accel_frame" pos="-0.01174 -0.00552 0.0051">
            <body name="head_camera_accel_optical_frame" quat="0.5 -0.5 0.5 -0.5"/>
          </body>
          <body name="head_camera_gyro_frame" pos="-0.01174 -0.00552 0.0051">
            <body name="head_camera_gyro_optical_frame" quat="0.5 -0.5 0.5 -0.5"/>
          </body>
        </body>
      </body>
    </body>
  </worldbody>
</mujoco>
