<mujoco model="robot">
  <compiler angle="radian" meshdir="../../" discardvisual="false" autolimits="true" />
  <option timestep="0.001" gravity="0 0 -9.81" integrator="implicitfast" />
  <default>
    <default class="visual">
      <geom contype="0" conaffinity="0" group="2" density="0" />
    </default>
    <default class="collision">
      <geom contype="1" conaffinity="1" group="3" density="0" />
    </default>
  </default>
  <asset>
    <mesh name="Base_L" file="marvin_description/meshes/left/Base_L.STL" />
    <mesh name="Link1_L" file="marvin_description/meshes/left/Link1_L.STL" />
    <mesh name="Link2_L" file="marvin_description/meshes/left/Link2_L.STL" />
    <mesh name="Link3_L" file="marvin_description/meshes/left/Link3_L.STL" />
    <mesh name="Link4_L" file="marvin_description/meshes/left/Link4_L.STL" />
    <mesh name="Link5_L" file="marvin_description/meshes/left/Link5_L.STL" />
    <mesh name="Link6_L" file="marvin_description/meshes/left/Link6_L.STL" />
    <mesh name="Link7_L" file="marvin_description/meshes/left/Link7_L.STL" />
    <mesh name="Base_R" file="marvin_description/meshes/right/Base_R.STL" />
    <mesh name="Link1_R" file="marvin_description/meshes/right/Link1_R.STL" />
    <mesh name="Link2_R" file="marvin_description/meshes/right/Link2_R.STL" />
    <mesh name="Link3_R" file="marvin_description/meshes/right/Link3_R.STL" />
    <mesh name="Link4_R" file="marvin_description/meshes/right/Link4_R.STL" />
    <mesh name="Link5_R" file="marvin_description/meshes/right/Link5_R.STL" />
    <mesh name="Link6_R" file="marvin_description/meshes/right/Link6_R.STL" />
    <mesh name="Link7_R" file="marvin_description/meshes/right/Link7_R.STL" />
    <mesh name="left_palm_link" file="wuji_description/meshes/left/left_palm_link.STL" />
    <mesh name="left_finger1_link1" file="wuji_description/meshes/left/left_finger1_link1.STL" />
    <mesh name="left_finger1_link2" file="wuji_description/meshes/left/left_finger1_link2.STL" />
    <mesh name="left_finger1_link3" file="wuji_description/meshes/left/left_finger1_link3.STL" />
    <mesh name="left_finger1_link4" file="wuji_description/meshes/left/left_finger1_link4.STL" />
    <mesh name="left_finger1_tip_link" file="wuji_description/meshes/left/left_finger1_tip_link.STL" />
    <mesh name="left_finger1_link2_softbody" file="wuji_description/meshes/left/left_finger1_link2_softbody.STL" />
    <mesh name="left_finger2_link1" file="wuji_description/meshes/left/left_finger2_link1.STL" />
    <mesh name="left_finger2_link2" file="wuji_description/meshes/left/left_finger2_link2.STL" />
    <mesh name="left_finger2_link3" file="wuji_description/meshes/left/left_finger2_link3.STL" />
    <mesh name="left_finger2_link4" file="wuji_description/meshes/left/left_finger2_link4.STL" />
    <mesh name="left_finger2_tip_link" file="wuji_description/meshes/left/left_finger2_tip_link.STL" />
    <mesh name="left_finger3_link1" file="wuji_description/meshes/left/left_finger3_link1.STL" />
    <mesh name="left_finger3_link2" file="wuji_description/meshes/left/left_finger3_link2.STL" />
    <mesh name="left_finger3_link3" file="wuji_description/meshes/left/left_finger3_link3.STL" />
    <mesh name="left_finger3_link4" file="wuji_description/meshes/left/left_finger3_link4.STL" />
    <mesh name="left_finger3_tip_link" file="wuji_description/meshes/left/left_finger3_tip_link.STL" />
    <mesh name="left_finger4_link1" file="wuji_description/meshes/left/left_finger4_link1.STL" />
    <mesh name="left_finger4_link2" file="wuji_description/meshes/left/left_finger4_link2.STL" />
    <mesh name="left_finger4_link3" file="wuji_description/meshes/left/left_finger4_link3.STL" />
    <mesh name="left_finger4_link4" file="wuji_description/meshes/left/left_finger4_link4.STL" />
    <mesh name="left_finger4_tip_link" file="wuji_description/meshes/left/left_finger4_tip_link.STL" />
    <mesh name="left_finger5_link1" file="wuji_description/meshes/left/left_finger5_link1.STL" />
    <mesh name="left_finger5_link2" file="wuji_description/meshes/left/left_finger5_link2.STL" />
    <mesh name="left_finger5_link3" file="wuji_description/meshes/left/left_finger5_link3.STL" />
    <mesh name="left_finger5_link4" file="wuji_description/meshes/left/left_finger5_link4.STL" />
    <mesh name="left_finger5_tip_link" file="wuji_description/meshes/left/left_finger5_tip_link.STL" />
    <mesh name="right_palm_link" file="wuji_description/meshes/right/right_palm_link.STL" />
    <mesh name="right_finger1_link1" file="wuji_description/meshes/right/right_finger1_link1.STL" />
    <mesh name="right_finger1_link2" file="wuji_description/meshes/right/right_finger1_link2.STL" />
    <mesh name="right_finger1_link3" file="wuji_description/meshes/right/right_finger1_link3.STL" />
    <mesh name="right_finger1_link4" file="wuji_description/meshes/right/right_finger1_link4.STL" />
    <mesh name="right_finger1_tip_link" file="wuji_description/meshes/right/right_finger1_tip_link.STL" />
    <mesh name="right_finger1_link2_softbody" file="wuji_description/meshes/right/right_finger1_link2_softbody.STL" />
    <mesh name="right_finger2_link1" file="wuji_description/meshes/right/right_finger2_link1.STL" />
    <mesh name="right_finger2_link2" file="wuji_description/meshes/right/right_finger2_link2.STL" />
    <mesh name="right_finger2_link3" file="wuji_description/meshes/right/right_finger2_link3.STL" />
    <mesh name="right_finger2_link4" file="wuji_description/meshes/right/right_finger2_link4.STL" />
    <mesh name="right_finger2_tip_link" file="wuji_description/meshes/right/right_finger2_tip_link.STL" />
    <mesh name="right_finger3_link1" file="wuji_description/meshes/right/right_finger3_link1.STL" />
    <mesh name="right_finger3_link2" file="wuji_description/meshes/right/right_finger3_link2.STL" />
    <mesh name="right_finger3_link3" file="wuji_description/meshes/right/right_finger3_link3.STL" />
    <mesh name="right_finger3_link4" file="wuji_description/meshes/right/right_finger3_link4.STL" />
    <mesh name="right_finger3_tip_link" file="wuji_description/meshes/right/right_finger3_tip_link.STL" />
    <mesh name="right_finger4_link1" file="wuji_description/meshes/right/right_finger4_link1.STL" />
    <mesh name="right_finger4_link2" file="wuji_description/meshes/right/right_finger4_link2.STL" />
    <mesh name="right_finger4_link3" file="wuji_description/meshes/right/right_finger4_link3.STL" />
    <mesh name="right_finger4_link4" file="wuji_description/meshes/right/right_finger4_link4.STL" />
    <mesh name="right_finger4_tip_link" file="wuji_description/meshes/right/right_finger4_tip_link.STL" />
    <mesh name="right_finger5_link1" file="wuji_description/meshes/right/right_finger5_link1.STL" />
    <mesh name="right_finger5_link2" file="wuji_description/meshes/right/right_finger5_link2.STL" />
    <mesh name="right_finger5_link3" file="wuji_description/meshes/right/right_finger5_link3.STL" />
    <mesh name="right_finger5_link4" file="wuji_description/meshes/right/right_finger5_link4.STL" />
    <mesh name="right_finger5_tip_link" file="wuji_description/meshes/right/right_finger5_tip_link.STL" />
  </asset>
  <worldbody>
    <body name="main_base_link" pos="0 0 0.7">
      <inertial pos="0 0 0" mass="0.001" diaginertia="1e-6 1e-6 1e-6" />
      <body name="head_camera" pos="0 0 0.8" quat="-0.674380 -0.212629 0.212633 0.674379">
        <camera name="head_camera" mode="fixed" resolution="1920 1080" fovy="42.5" />
        <body name="head_camera_optical_frame" quat="0 1 0 0">
          <site name="head_camera_optical_frame" size="0.01" />
        </body>
      </body>
      <geom pos="0 0.2 0.5" quat="0.499998 -0.5 -0.5 -0.500002" type="mesh" rgba="1 0 0 1" mesh="Base_L" class="visual" />
      <geom pos="0 0.2 0.5" quat="0.499998 -0.5 -0.5 -0.500002" type="mesh" rgba="1 0 0 1" mesh="Base_L" class="collision" />
      <geom pos="0 -0.2 0.5" quat="0.499998 0.5 -0.5 0.500002" type="mesh" rgba="1 0 0 1" mesh="Base_R" class="visual" />
      <geom pos="0 -0.2 0.5" quat="0.499998 0.5 -0.5 0.500002" type="mesh" rgba="1 0 0 1" mesh="Base_R" class="collision" />
      <body name="Link1_L" pos="6.40974e-07 0.3745 0.5" quat="0.499998 -0.5 -0.5 -0.500002">
        <inertial pos="2.347e-05 0.0055715 -0.03076" quat="0.711599 0.0343691 -0.0341702 0.700912" mass="1.9705" diaginertia="0.00529754 0.00492285 0.00184874" />
        <joint name="Joint1_L" pos="0 0 0" axis="0 0 1" range="-3.1067 3.1067" actuatorfrcrange="-108 108" />
        <geom type="mesh" rgba="0 1 0 1" mesh="Link1_L" class="visual" />
        <geom type="mesh" rgba="0 1 0 1" mesh="Link1_L" class="collision" />
        <body name="Link2_L" quat="0.707105 0.707108 0 0">
          <inertial pos="0.00013483 0.0617046 0.00950639" quat="0.643375 0.765551 -3.57328e-05 0.000294349" mass="2.24398" diaginertia="0.0119493 0.0112156 0.00338374" />
          <joint name="Joint2_L" pos="0 0 0" axis="0 0 1" range="-2.0944 2.0944" actuatorfrcrange="-108 108" />
          <geom type="mesh" rgba="0 0 1 1" mesh="Link2_L" class="visual" />
          <geom type="mesh" rgba="0 0 1 1" mesh="Link2_L" class="collision" />
          <body name="Link3_L" pos="0 0.287 0" quat="0.707105 -0.707108 0 0">
            <inertial pos="0.00968562 0.00246599 -0.046273" quat="0.782446 -0.0355285 -0.0735516 0.617337" mass="1.9242" diaginertia="0.00765215 0.00730789 0.0016338" />
            <joint name="Joint3_L" pos="0 0 0" axis="0 0 1" range="-3.1067 3.1067" actuatorfrcrange="-66 66" />
            <geom type="mesh" rgba="1 0 0 1" mesh="Link3_L" class="visual" />
            <geom type="mesh" rgba="1 0 0 1" mesh="Link3_L" class="collision" />
            <body name="Link4_L" pos="0.018 0 0" quat="-2.59734e-06 2.59735e-06 -0.707108 0.707105">
              <inertial pos="0.00850411 -0.0471822 0.00941509" quat="0.741754 0.628694 0.0774999 -0.220317" mass="1.6085" diaginertia="0.00603244 0.00535875 0.00198228" />
              <joint name="Joint4_L" pos="0 0 0" axis="0 0 1" range="-2.5307 1.0472" actuatorfrcrange="-66 66" />
              <geom type="mesh" rgba="0 1 0 1" mesh="Link4_L" class="visual" />
              <geom type="mesh" rgba="0 1 0 1" mesh="Link4_L" class="collision" />
              <body name="Link5_L" pos="0.018 -0.314 0" quat="-2.59734e-06 2.59735e-06 -0.707108 0.707105">
                <inertial pos="0.00051127 0.00101064 -0.112717" quat="0.999438 -0.00995046 -0.00675781 0.0312997" mass="2.0883" diaginertia="0.00626924 0.00564262 0.00243436" />
                <joint name="Joint5_L" pos="0 0 0" axis="0 0 1" range="-3.1067 3.1067" actuatorfrcrange="-18 18" />
                <geom type="mesh" rgba="0 0 1 1" mesh="Link5_L" class="visual" />
                <geom type="mesh" rgba="0 0 1 1" mesh="Link5_L" class="collision" />
                <body name="Link6_L" quat="0.499998 0.5 -0.5 0.500002">
                  <inertial pos="0.00032659 0.00531336 -0.00030182" quat="0.718188 -0.0225408 0.00407878 0.695472" mass="0.72496" diaginertia="0.000517351 0.000460362 0.000425057" />
                  <joint name="Joint6_L" pos="0 0 0" axis="0 0 1" range="-1.0472 1.0472" actuatorfrcrange="-18 18" />
                  <geom type="mesh" rgba="1 0 0 1" mesh="Link6_L" class="visual" />
                  <geom type="mesh" rgba="1 0 0 1" mesh="Link6_L" class="collision" />
                  <body name="Link7_L" quat="0.499998 0.5 -0.5 0.500002">
                    <inertial pos="-0.000374566 -0.0564798 0.00765736" quat="0.733436 0.679696 0.0034114 -0.00857689" mass="0.8552" diaginertia="0.0040413 0.00366354 0.000940055" />
                    <joint name="Joint7_L" pos="0 0 0" axis="0 0 1" range="-1.5708 1.5708" actuatorfrcrange="-18 18" />
                    <geom type="mesh" rgba="0 1 0 1" mesh="Link7_L" class="visual" />
                    <geom type="mesh" rgba="0 1 0 1" mesh="Link7_L" class="collision" />
                    <geom pos="0 -0.12 0" quat="-2.59734e-06 -2.59735e-06 0.707105 -0.707108" type="mesh" rgba="0.627451 0.627451 0.627451 1" mesh="left_palm_link" class="visual" />
                    <geom pos="0 -0.12 0" quat="-2.59734e-06 -2.59735e-06 0.707105 -0.707108" type="mesh" rgba="0.627451 0.627451 0.627451 1" mesh="left_palm_link" class="collision" />
                    <body name="left_finger1_link1" pos="-0.00852429 -0.148712 0.0205756" quat="0.213794 0.327646 0.0456311 -0.919161">
                      <inertial pos="-0.00246155 0.00144069 0.00778554" quat="0.904243 0.21652 0.0443878 -0.365368" mass="0.0075" diaginertia="3.37599e-07 3.01198e-07 2.11203e-07" />
                      <joint name="left_finger1_joint1" pos="0 0 0" axis="0 1 0" range="0.0475 1.6033" actuatorfrcrange="-0.4452 0.4452" />
                      <geom type="mesh" rgba="0.792157 0.819608 0.933333 1" mesh="left_finger1_link1" class="visual" />
                      <geom type="mesh" rgba="0.792157 0.819608 0.933333 1" mesh="left_finger1_link1" class="collision" />
                      <body name="left_finger1_link2" pos="-0.0047549 0.00601914 0.0141321" quat="0.616957 0.0855876 -0.29085 -0.726254">
                        <inertial pos="0.00136084 -8.51198e-05 0.0150055" quat="0.926192 0.00548447 -0.048696 -0.373854" mass="0.0333513" diaginertia="4.1738e-06 4.1045e-06 2.19539e-06" />
                        <joint name="left_finger1_joint2" pos="0 0 0" axis="0 -1 0" range="-0.1387 0.9324" actuatorfrcrange="-0.4259 0.4259" />
                        <geom type="mesh" rgba="0.792157 0.819608 0.933333 1" mesh="left_finger1_link2" class="visual" />
                        <geom type="mesh" rgba="0.792157 0.819608 0.933333 1" mesh="left_finger1_link2" class="collision" />
                        <geom type="mesh" rgba="0.792157 0.819608 0.933333 1" mesh="left_finger1_link2_softbody" class="visual" />
                        <geom type="mesh" rgba="0.792157 0.819608 0.933333 1" mesh="left_finger1_link2_softbody" class="collision" />
                        <body name="left_finger1_link3" pos="0.000188722 0.000991601 0.0346636" quat="0.577836 -0.0212382 -0.0150036 0.815739">
                          <inertial pos="0.000774544 1.11939e-05 0.01277" quat="0.999951 0 0.00989566 0" mass="0.0165" diaginertia="1.4604e-06 1.42e-06 4.49604e-07" />
                          <joint name="left_finger1_joint3" pos="0 0 0" axis="0 1 0" range="-0.4642 1.5623" actuatorfrcrange="-0.1888 0.1888" />
                          <geom type="mesh" rgba="0.792157 0.819608 0.933333 1" mesh="left_finger1_link3" class="visual" />
                          <geom type="mesh" rgba="0.792157 0.819608 0.933333 1" mesh="left_finger1_link3" class="collision" />
                          <body name="left_finger1_link4" pos="0 -0.0002 0.0295">
                            <inertial pos="0.000492755 0.000153669 0.0149026" quat="0.705292 -0.0506246 -0.0506246 0.705292" mass="0.0206" diaginertia="1.77e-06 1.7502e-06 7.59798e-07" />
                            <joint name="left_finger1_joint4" pos="0 0 0" axis="0 1 0" range="-0.4699 1.5568" actuatorfrcrange="-0.1468 0.1468" />
                            <geom type="mesh" rgba="0.792157 0.819608 0.933333 1" mesh="left_finger1_link4" class="visual" />
                            <geom type="mesh" rgba="0.792157 0.819608 0.933333 1" mesh="left_finger1_link4" class="collision" />
                            <geom pos="0 0 0.0328135" quat="1 0 0 0" type="mesh" rgba="0.792157 0.819608 0.933333 1" mesh="left_finger1_tip_link" class="visual" />
                            <geom pos="0 0 0.0328135" quat="1 0 0 0" type="mesh" rgba="0.792157 0.819608 0.933333 1" mesh="left_finger1_tip_link" class="collision" />
                          </body>
                        </body>
                      </body>
                    </body>
                    <body name="left_finger2_link1" pos="0.00587031 -0.211916 0.0294342" quat="0.0989161 0.0575137 0.65963 -0.74283">
                      <inertial pos="-0.00132905 4.18014e-08 0.000320068" quat="0.92388 0 0.382683 0" mass="0.0032" diaginertia="1.1e-07 7e-08 5e-08" />
                      <joint name="left_finger2_joint1" pos="0 0 0" axis="0 1 0" range="-0.1585 1.5604" actuatorfrcrange="-0.6188 0.6188" />
                      <geom type="mesh" rgba="0.792157 0.819608 0.933333 1" mesh="left_finger2_link1" class="visual" />
                      <geom type="mesh" rgba="0.792157 0.819608 0.933333 1" mesh="left_finger2_link1" class="collision" />
                      <body name="left_finger2_link2" pos="0.0022 0 0.00400001" quat="0.707107 0 0 0.707107">
                        <inertial pos="-1.78565e-06 0.00370948 0.0184837" quat="0.70703 0.0104245 0.0104245 0.70703" mass="0.033" diaginertia="6.34e-06 6.31472e-06 8.85281e-07" />
                        <joint name="left_finger2_joint2" pos="0 0 0" axis="0 1 0" range="-0.37 0.37" actuatorfrcrange="-0.1822 0.1822" />
                        <geom type="mesh" rgba="0.792157 0.819608 0.933333 1" mesh="left_finger2_link2" class="visual" />
                        <geom type="mesh" rgba="0.792157 0.819608 0.933333 1" mesh="left_finger2_link2" class="collision" />
                        <body name="left_finger2_link3" pos="0 0.00475 0.0436177" quat="0.707202 0 0 -0.707012">
                          <inertial pos="0.000341914 -1.40911e-05 0.0134812" quat="0.999892 0 -0.0146884 0" mass="0.0165" diaginertia="1.47088e-06 1.44e-06 4.49118e-07" />
                          <joint name="left_finger2_joint3" pos="0 0 0" axis="0 1 0" range="-0.4777 1.5485" actuatorfrcrange="-0.2251 0.2251" />
                          <geom type="mesh" rgba="0.792157 0.819608 0.933333 1" mesh="left_finger2_link3" class="visual" />
                          <geom type="mesh" rgba="0.792157 0.819608 0.933333 1" mesh="left_finger2_link3" class="collision" />
                          <body name="left_finger2_link4" pos="0 0 0.0295">
                            <inertial pos="-0.000815133 -1.35285e-05 0.0107847" quat="0.995635 -0.00653716 -0.0926302 -0.00932836" mass="0.01718" diaginertia="1.1763e-06 1.07011e-06 4.03591e-07" />
                            <joint name="left_finger2_joint4" pos="0 0 0" axis="0 1 0" range="-0.4683 1.5753" actuatorfrcrange="-0.217 0.217" />
                            <geom type="mesh" rgba="0.792157 0.819608 0.933333 1" mesh="left_finger2_link4" class="visual" />
                            <geom type="mesh" rgba="0.792157 0.819608 0.933333 1" mesh="left_finger2_link4" class="collision" />
                            <geom pos="0 0 0.024" quat="1 0 0 0" type="mesh" rgba="0.792157 0.819608 0.933333 1" mesh="left_finger2_tip_link" class="visual" />
                            <geom pos="0 0 0.024" quat="1 0 0 0" type="mesh" rgba="0.792157 0.819608 0.933333 1" mesh="left_finger2_tip_link" class="collision" />
                          </body>
                        </body>
                      </body>
                    </body>
                    <body name="left_finger3_link1" pos="0.0104598 -0.209543 0.00746171" quat="0.0306355 -0.0310517 0.706424 -0.706444">
                      <inertial pos="-0.0013291 3.85118e-08 0.000319976" quat="0.92388 0 0.382683 0" mass="0.0032" diaginertia="1.1e-07 7e-08 5e-08" />
                      <joint name="left_finger3_joint1" pos="0 0 0" axis="0 1 0" range="-0.1644 1.5516" actuatorfrcrange="-0.6494 0.6494" />
                      <geom type="mesh" rgba="0.792157 0.819608 0.933333 1" mesh="left_finger3_link1" class="visual" />
                      <geom type="mesh" rgba="0.792157 0.819608 0.933333 1" mesh="left_finger3_link1" class="collision" />
                      <body name="left_finger3_link2" pos="0.0022 0 0.00400001" quat="0.707107 0 0 0.707107">
                        <inertial pos="-1.82891e-06 0.00370965 0.0184837" quat="0.70703 0.0104245 0.0104245 0.70703" mass="0.033" diaginertia="6.34e-06 6.31472e-06 8.85281e-07" />
                        <joint name="left_finger3_joint2" pos="0 0 0" axis="0 1 0" range="-0.37 0.37" actuatorfrcrange="-0.1827 0.1827" />
                        <geom type="mesh" rgba="0.792157 0.819608 0.933333 1" mesh="left_finger3_link2" class="visual" />
                        <geom type="mesh" rgba="0.792157 0.819608 0.933333 1" mesh="left_finger3_link2" class="collision" />
                        <body name="left_finger3_link3" pos="0 0.00475 0.0436177" quat="0.707202 0 0 -0.707012">
                          <inertial pos="0.000333742 -1.05568e-05 0.0134866" quat="0.999892 0 -0.0146884 0" mass="0.0165" diaginertia="1.47088e-06 1.44e-06 4.49118e-07" />
                          <joint name="left_finger3_joint3" pos="0 0 0" axis="0 1 0" range="-0.4739 1.5512" actuatorfrcrange="-0.2078 0.2078" />
                          <geom type="mesh" rgba="0.792157 0.819608 0.933333 1" mesh="left_finger3_link3" class="visual" />
                          <geom type="mesh" rgba="0.792157 0.819608 0.933333 1" mesh="left_finger3_link3" class="collision" />
                          <body name="left_finger3_link4" pos="0 0 0.0295">
                            <inertial pos="-0.000815615 -1.34653e-05 0.0107846" quat="0.995635 -0.00653716 -0.0926302 -0.00932836" mass="0.01718" diaginertia="1.1763e-06 1.07011e-06 4.03591e-07" />
                            <joint name="left_finger3_joint4" pos="0 0 0" axis="0 1 0" range="-0.4684 1.5745" actuatorfrcrange="-0.2018 0.2018" />
                            <geom type="mesh" rgba="0.792157 0.819608 0.933333 1" mesh="left_finger3_link4" class="visual" />
                            <geom type="mesh" rgba="0.792157 0.819608 0.933333 1" mesh="left_finger3_link4" class="collision" />
                            <geom pos="0 0 0.024" quat="1 0 0 0" type="mesh" rgba="0.792157 0.819608 0.933333 1" mesh="left_finger3_tip_link" class="visual" />
                            <geom pos="0 0 0.024" quat="1 0 0 0" type="mesh" rgba="0.792157 0.819608 0.933333 1" mesh="left_finger3_tip_link" class="collision" />
                          </body>
                        </body>
                      </body>
                    </body>
                    <body name="left_finger4_link1" pos="0.00766476 -0.204429 -0.013712" quat="0.0107368 -0.0466632 0.738141 -0.672945">
                      <inertial pos="-0.00132911 4.56181e-08 0.000319941" quat="0.92388 0 0.382683 0" mass="0.0032" diaginertia="1.1e-07 7e-08 5e-08" />
                      <joint name="left_finger4_joint1" pos="0 0 0" axis="0 1 0" range="-0.1554 1.5585" actuatorfrcrange="-0.6389 0.6389" />
                      <geom type="mesh" rgba="0.792157 0.819608 0.933333 1" mesh="left_finger4_link1" class="visual" />
                      <geom type="mesh" rgba="0.792157 0.819608 0.933333 1" mesh="left_finger4_link1" class="collision" />
                      <body name="left_finger4_link2" pos="0.0022 0 0.00400001" quat="0.707107 0 0 0.707107">
                        <inertial pos="-1.82336e-06 0.00371493 0.0185138" quat="0.70703 0.0104245 0.0104245 0.70703" mass="0.033" diaginertia="6.34e-06 6.31472e-06 8.85281e-07" />
                        <joint name="left_finger4_joint2" pos="0 0 0" axis="0 1 0" range="-0.37 0.37" actuatorfrcrange="-0.1832 0.1832" />
                        <geom type="mesh" rgba="0.792157 0.819608 0.933333 1" mesh="left_finger4_link2" class="visual" />
                        <geom type="mesh" rgba="0.792157 0.819608 0.933333 1" mesh="left_finger4_link2" class="collision" />
                        <body name="left_finger4_link3" pos="0 0.00475 0.0436177" quat="0.707202 0 0 -0.707012">
                          <inertial pos="0.00031892 -1.03297e-05 0.0135407" quat="0.999892 0 -0.0146884 0" mass="0.0165" diaginertia="1.47088e-06 1.44e-06 4.49118e-07" />
                          <joint name="left_finger4_joint3" pos="0 0 0" axis="0 1 0" range="-0.4765 1.5487" actuatorfrcrange="-0.2249 0.2249" />
                          <geom type="mesh" rgba="0.792157 0.819608 0.933333 1" mesh="left_finger4_link3" class="visual" />
                          <geom type="mesh" rgba="0.792157 0.819608 0.933333 1" mesh="left_finger4_link3" class="collision" />
                          <body name="left_finger4_link4" pos="0 0 0.0295">
                            <inertial pos="-0.000864592 -1.02217e-05 0.0108394" quat="0.995635 -0.00653716 -0.0926302 -0.00932836" mass="0.01718" diaginertia="1.1763e-06 1.07011e-06 4.03591e-07" />
                            <joint name="left_finger4_joint4" pos="0 0 0" axis="0 1 0" range="-0.4777 1.5634" actuatorfrcrange="-0.2044 0.2044" />
                            <geom type="mesh" rgba="0.792157 0.819608 0.933333 1" mesh="left_finger4_link4" class="visual" />
                            <geom type="mesh" rgba="0.792157 0.819608 0.933333 1" mesh="left_finger4_link4" class="collision" />
                            <geom pos="0 0 0.024" quat="1 0 0 0" type="mesh" rgba="0.792157 0.819608 0.933333 1" mesh="left_finger4_tip_link" class="visual" />
                            <geom pos="0 0 0.024" quat="1 0 0 0" type="mesh" rgba="0.792157 0.819608 0.933333 1" mesh="left_finger4_tip_link" class="collision" />
                          </body>
                        </body>
                      </body>
                    </body>
                    <body name="left_finger5_link1" pos="0.0022684 -0.194281 -0.0340009" quat="-0.0314061 -0.0856058 0.770877 -0.630424">
                      <inertial pos="-0.00132912 3.31411e-08 0.000319867" quat="0.92388 0 0.382683 0" mass="0.0032" diaginertia="1.1e-07 7e-08 5e-08" />
                      <joint name="left_finger5_joint1" pos="0 0 0" axis="0 1 0" range="-0.1626 1.5585" actuatorfrcrange="-0.6441 0.6441" />
                      <geom type="mesh" rgba="0.792157 0.819608 0.933333 1" mesh="left_finger5_link1" class="visual" />
                      <geom type="mesh" rgba="0.792157 0.819608 0.933333 1" mesh="left_finger5_link1" class="collision" />
                      <body name="left_finger5_link2" pos="0.0022 0 0.00400001" quat="0.707107 0 0 0.707107">
                        <inertial pos="-1.8211e-06 0.00371684 0.0193334" quat="0.70703 0.0104245 0.0104245 0.70703" mass="0.033" diaginertia="6.34e-06 6.31472e-06 8.85281e-07" />
                        <joint name="left_finger5_joint2" pos="0 0 0" axis="0 1 0" range="-0.37 0.37" actuatorfrcrange="-0.1798 0.1798" />
                        <geom type="mesh" rgba="0.792157 0.819608 0.933333 1" mesh="left_finger5_link2" class="visual" />
                        <geom type="mesh" rgba="0.792157 0.819608 0.933333 1" mesh="left_finger5_link2" class="collision" />
                        <body name="left_finger5_link3" pos="0 0.00475 0.0436177" quat="0.707202 0 0 -0.707012">
                          <inertial pos="0.000353514 -5.08998e-06 0.0139268" quat="0.999892 0 -0.0146884 0" mass="0.0165" diaginertia="1.47088e-06 1.44e-06 4.49118e-07" />
                          <joint name="left_finger5_joint3" pos="0 0 0" axis="0 1 0" range="-0.4768 1.549" actuatorfrcrange="-0.2384 0.2384" />
                          <geom type="mesh" rgba="0.792157 0.819608 0.933333 1" mesh="left_finger5_link3" class="visual" />
                          <geom type="mesh" rgba="0.792157 0.819608 0.933333 1" mesh="left_finger5_link3" class="collision" />
                          <body name="left_finger5_link4" pos="0 0 0.0295">
                            <inertial pos="-0.000906048 1.84282e-05 0.0122759" quat="0.995635 -0.00653716 -0.0926302 -0.00932836" mass="0.01718" diaginertia="1.1763e-06 1.07011e-06 4.03591e-07" />
                            <joint name="left_finger5_joint4" pos="0 0 0" axis="0 1 0" range="-0.4683 1.5735" actuatorfrcrange="-0.1866 0.1866" />
                            <geom type="mesh" rgba="0.792157 0.819608 0.933333 1" mesh="left_finger5_link4" class="visual" />
                            <geom type="mesh" rgba="0.792157 0.819608 0.933333 1" mesh="left_finger5_link4" class="collision" />
                            <geom pos="0 0 0.026" quat="1 0 0 0" type="mesh" rgba="0.792157 0.819608 0.933333 1" mesh="left_finger5_tip_link" class="visual" />
                            <geom pos="0 0 0.026" quat="1 0 0 0" type="mesh" rgba="0.792157 0.819608 0.933333 1" mesh="left_finger5_tip_link" class="collision" />
                          </body>
                        </body>
                      </body>
                    </body>
                  </body>
                </body>
              </body>
            </body>
          </body>
        </body>
      </body>
      <body name="Link1_R" pos="6.40974e-07 -0.3745 0.5" quat="0.499998 0.5 -0.5 0.500002">
        <inertial pos="2.347e-05 0.0055715 -0.03076" quat="0.711599 0.0343691 -0.0341702 0.700912" mass="1.9705" diaginertia="0.00529754 0.00492285 0.00184874" />
        <joint name="Joint1_R" pos="0 0 0" axis="0 0 1" range="-3.1067 3.1067" actuatorfrcrange="-108 108" />
        <geom type="mesh" rgba="0 1 0 1" mesh="Link1_R" class="visual" />
        <geom type="mesh" rgba="0 1 0 1" mesh="Link1_R" class="collision" />
        <body name="Link2_R" quat="0.707105 0.707108 0 0">
          <inertial pos="0.00013483 0.0617046 0.00950639" quat="0.643375 0.765551 -3.57328e-05 0.000294349" mass="2.24398" diaginertia="0.0119493 0.0112156 0.00338374" />
          <joint name="Joint2_R" pos="0 0 0" axis="0 0 1" range="-2.0944 2.0944" actuatorfrcrange="-108 108" />
          <geom type="mesh" rgba="0 0 1 1" mesh="Link2_R" class="visual" />
          <geom type="mesh" rgba="0 0 1 1" mesh="Link2_R" class="collision" />
          <body name="Link3_R" pos="0 0.287 0" quat="0.707105 -0.707108 0 0">
            <inertial pos="0.00968562 0.00246599 -0.046273" quat="0.782446 -0.0355285 -0.0735516 0.617337" mass="1.9242" diaginertia="0.00765215 0.00730789 0.0016338" />
            <joint name="Joint3_R" pos="0 0 0" axis="0 0 1" range="-3.1067 3.1067" actuatorfrcrange="-66 66" />
            <geom type="mesh" rgba="1 0 0 1" mesh="Link3_R" class="visual" />
            <geom type="mesh" rgba="1 0 0 1" mesh="Link3_R" class="collision" />
            <body name="Link4_R" pos="0.018 0 0" quat="-2.59734e-06 2.59735e-06 -0.707108 0.707105">
              <inertial pos="0.00850411 -0.0471822 0.00941509" quat="0.741754 0.628694 0.0774999 -0.220317" mass="1.6085" diaginertia="0.00603244 0.00535875 0.00198228" />
              <joint name="Joint4_R" pos="0 0 0" axis="0 0 1" range="-2.5307 1.0472" actuatorfrcrange="-66 66" />
              <geom type="mesh" rgba="0 1 0 1" mesh="Link4_R" class="visual" />
              <geom type="mesh" rgba="0 1 0 1" mesh="Link4_R" class="collision" />
              <body name="Link5_R" pos="0.018 -0.314 0" quat="-2.59734e-06 2.59735e-06 -0.707108 0.707105">
                <inertial pos="-0.00051127 -0.00101064 -0.112717" quat="0.999438 0.00995046 0.00675781 0.0312997" mass="2.0883" diaginertia="0.00626924 0.00564262 0.00243436" />
                <joint name="Joint5_R" pos="0 0 0" axis="0 0 1" range="-3.1067 3.1067" actuatorfrcrange="-18 18" />
                <geom type="mesh" rgba="0 0 1 1" mesh="Link5_R" class="visual" />
                <geom type="mesh" rgba="0 0 1 1" mesh="Link5_R" class="collision" />
                <body name="Link6_R" quat="0.499998 0.5 -0.5 0.500002">
                  <inertial pos="0.00032659 -0.00531336 0.00030182" quat="0.695472 -0.00407878 0.0225408 0.718188" mass="0.72496" diaginertia="0.000517351 0.000460362 0.000425057" />
                  <joint name="Joint6_R" pos="0 0 0" axis="0 0 1" range="-1.0472 1.0472" actuatorfrcrange="-18 18" />
                  <geom type="mesh" rgba="1 0 0 1" mesh="Link6_R" class="visual" />
                  <geom type="mesh" rgba="1 0 0 1" mesh="Link6_R" class="collision" />
                  <body name="Link7_R" quat="0.499998 0.5 -0.5 0.500002">
                    <inertial pos="0.000228437 -0.0564798 0.0076573" quat="0.733465 0.679701 -0.00163811 0.00580796" mass="0.8552" diaginertia="0.00404119 0.00366369 0.000940175" />
                    <joint name="Joint7_R" pos="0 0 0" axis="0 0 1" range="-1.5708 1.5708" actuatorfrcrange="-18 18" />
                    <geom type="mesh" rgba="0 1 0 1" mesh="Link7_R" class="visual" />
                    <geom type="mesh" rgba="0 1 0 1" mesh="Link7_R" class="collision" />
                    <geom pos="0 -0.12 0" quat="0.707105 0.707108 0 0" type="mesh" rgba="0.627451 0.627451 0.627451 1" mesh="right_palm_link" class="visual" />
                    <geom pos="0 -0.12 0" quat="0.707105 0.707108 0 0" type="mesh" rgba="0.627451 0.627451 0.627451 1" mesh="right_palm_link" class="collision" />
                    <body name="right_finger1_link1" pos="0.0085244 -0.148712 0.0205749" quat="0.91916 0.0456457 0.327648 -0.213796">
                      <inertial pos="-0.0099171 -0.0059845 0.00152324" quat="0.904243 0.21652 0.0443878 -0.365368" mass="0.0075" diaginertia="3.37599e-07 3.01198e-07 2.11203e-07" />
                      <joint name="right_finger1_joint1" pos="0 0 0" axis="0 1 0" range="0.0475 1.6033" actuatorfrcrange="-0.4452 0.4452" />
                      <geom type="mesh" rgba="0.792157 0.819608 0.933333 1" mesh="right_finger1_link1" class="visual" />
                      <geom type="mesh" rgba="0.792157 0.819608 0.933333 1" mesh="right_finger1_link1" class="collision" />
                      <body name="right_finger1_link2" pos="-0.0047549 -0.0060191 0.014132" quat="0.726252 0.290851 -0.0855912 -0.616958">
                        <inertial pos="-0.00136057 -8.49029e-05 0.0150056" quat="0.922053 0.00470413 0.0434721 0.384585" mass="0.0333532" diaginertia="4.2114e-06 4.06368e-06 2.19943e-06" />
                        <joint name="right_finger1_joint2" pos="0 0 0" axis="0 1 0" range="-0.1387 0.9324" actuatorfrcrange="-0.4259 0.4259" />
                        <geom type="mesh" rgba="0.792157 0.819608 0.933333 1" mesh="right_finger1_link2" class="visual" />
                        <geom type="mesh" rgba="0.792157 0.819608 0.933333 1" mesh="right_finger1_link2" class="collision" />
                        <geom type="mesh" rgba="0.792157 0.819608 0.933333 1" mesh="right_finger1_link2_softbody" class="visual" />
                        <geom type="mesh" rgba="0.792157 0.819608 0.933333 1" mesh="right_finger1_link2_softbody" class="collision" />
                        <body name="right_finger1_link3" pos="-0.00037714 0.001058 0.034673" quat="0.815725 0.015003 0.0212383 0.577855">
                          <inertial pos="0.000775215 -0.000210057 0.0127726" quat="0.999951 0 0.00989566 0" mass="0.0165" diaginertia="1.4604e-06 1.42e-06 4.49604e-07" />
                          <joint name="right_finger1_joint3" pos="0 0 0" axis="0 1 0" range="-0.4642 1.5623" actuatorfrcrange="-0.1888 0.1888" />
                          <geom type="mesh" rgba="0.792157 0.819608 0.933333 1" mesh="right_finger1_link3" class="visual" />
                          <geom type="mesh" rgba="0.792157 0.819608 0.933333 1" mesh="right_finger1_link3" class="collision" />
                          <body name="right_finger1_link4" pos="0 0 0.0295">
                            <inertial pos="0.000494268 -0.0001544 0.0149072" quat="0.705292 -0.0506246 -0.0506246 0.705292" mass="0.0206" diaginertia="1.77e-06 1.7502e-06 7.59798e-07" />
                            <joint name="right_finger1_joint4" pos="0 0 0" axis="0 1 0" range="-0.4699 1.5568" actuatorfrcrange="-0.1468 0.1468" />
                            <geom type="mesh" rgba="0.792157 0.819608 0.933333 1" mesh="right_finger1_link4" class="visual" />
                            <geom type="mesh" rgba="0.792157 0.819608 0.933333 1" mesh="right_finger1_link4" class="collision" />
                            <geom pos="0.00026399 -0.00020119 0.032808" type="mesh" rgba="0.792157 0.819608 0.933333 1" mesh="right_finger1_tip_link" class="visual" />
                            <geom pos="0.00026399 -0.00020119 0.032808" type="mesh" rgba="0.792157 0.819608 0.933333 1" mesh="right_finger1_tip_link" class="collision" />
                          </body>
                        </body>
                      </body>
                    </body>
                    <body name="right_finger2_link1" pos="-0.0058701 -0.211917 0.0294337" quat="0.742827 0.659632 0.0575151 -0.0989166">
                      <inertial pos="-0.00132914 -2.06891e-08 0.000319815" quat="0.92388 0 0.382683 0" mass="0.0032" diaginertia="1.1e-07 7e-08 5e-08" />
                      <joint name="right_finger2_joint1" pos="0 0 0" axis="0 1 0" range="-0.1585 1.5604" actuatorfrcrange="-0.6188 0.6188" />
                      <geom type="mesh" rgba="0.792157 0.819608 0.933333 1" mesh="right_finger2_link1" class="visual" />
                      <geom type="mesh" rgba="0.792157 0.819608 0.933333 1" mesh="right_finger2_link1" class="collision" />
                      <body name="right_finger2_link2" pos="0.0022 0 0.00400001" quat="0.707107 0 0 0.707107">
                        <inertial pos="1.85614e-06 0.00370979 0.0184837" quat="0.70703 0.0104245 0.0104245 0.70703" mass="0.033" diaginertia="6.34e-06 6.31472e-06 8.85281e-07" />
                        <joint name="right_finger2_joint2" pos="0 0 0" axis="0 1 0" range="-0.37 0.37" actuatorfrcrange="-0.1822 0.1822" />
                        <geom type="mesh" rgba="0.792157 0.819608 0.933333 1" mesh="right_finger2_link2" class="visual" />
                        <geom type="mesh" rgba="0.792157 0.819608 0.933333 1" mesh="right_finger2_link2" class="collision" />
                        <body name="right_finger2_link3" pos="0 0.00475028 0.0436177" quat="0.707012 0 0 -0.707202">
                          <inertial pos="0.000342045 1.41767e-05 0.0134814" quat="0.999892 0 -0.0146884 0" mass="0.0165" diaginertia="1.47088e-06 1.44e-06 4.49118e-07" />
                          <joint name="right_finger2_joint3" pos="0 0 0" axis="0 1 0" range="-0.4777 1.5485" actuatorfrcrange="-0.2251 0.2251" />
                          <geom type="mesh" rgba="0.792157 0.819608 0.933333 1" mesh="right_finger2_link3" class="visual" />
                          <geom type="mesh" rgba="0.792157 0.819608 0.933333 1" mesh="right_finger2_link3" class="collision" />
                          <body name="right_finger2_link4" pos="0 0 0.0295">
                            <inertial pos="-0.000815026 1.34152e-05 0.0107855" quat="0.995635 -0.00653716 -0.0926302 -0.00932836" mass="0.01718" diaginertia="1.1763e-06 1.07011e-06 4.03591e-07" />
                            <joint name="right_finger2_joint4" pos="0 0 0" axis="0 1 0" range="-0.4683 1.5753" actuatorfrcrange="-0.217 0.217" />
                            <geom type="mesh" rgba="0.792157 0.819608 0.933333 1" mesh="right_finger2_link4" class="visual" />
                            <geom type="mesh" rgba="0.792157 0.819608 0.933333 1" mesh="right_finger2_link4" class="collision" />
                            <geom pos="-0.000749345 0 0.024" quat="1 0 0 0" type="mesh" rgba="0.792157 0.819608 0.933333 1" mesh="right_finger2_tip_link" class="visual" />
                            <geom pos="-0.000749345 0 0.024" quat="1 0 0 0" type="mesh" rgba="0.792157 0.819608 0.933333 1" mesh="right_finger2_tip_link" class="collision" />
                          </body>
                        </body>
                      </body>
                    </body>
                    <body name="right_finger3_link1" pos="-0.01046 -0.209544 0.00746117" quat="0.706441 0.706426 -0.0310488 -0.030638">
                      <inertial pos="-0.00132908 3.41333e-09 0.000319983" quat="0.92388 0 0.382683 0" mass="0.0032" diaginertia="1.1e-07 7e-08 5e-08" />
                      <joint name="right_finger3_joint1" pos="0 0 0" axis="0 1 0" range="-0.1644 1.5516" actuatorfrcrange="-0.6494 0.6494" />
                      <geom type="mesh" rgba="0.792157 0.819608 0.933333 1" mesh="right_finger3_link1" class="visual" />
                      <geom type="mesh" rgba="0.792157 0.819608 0.933333 1" mesh="right_finger3_link1" class="collision" />
                      <body name="right_finger3_link2" pos="0.0022 0 0.00400001" quat="0.707107 0 0 0.707107">
                        <inertial pos="1.86459e-06 0.0037098 0.0184837" quat="0.70703 0.0104245 0.0104245 0.70703" mass="0.033" diaginertia="6.34e-06 6.31472e-06 8.85281e-07" />
                        <joint name="right_finger3_joint2" pos="0 0 0" axis="0 1 0" range="-0.37 0.37" actuatorfrcrange="-0.1827 0.1827" />
                        <geom type="mesh" rgba="0.792157 0.819608 0.933333 1" mesh="right_finger3_link2" class="visual" />
                        <geom type="mesh" rgba="0.792157 0.819608 0.933333 1" mesh="right_finger3_link2" class="collision" />
                        <body name="right_finger3_link3" pos="0 0.00475 0.0436177" quat="0.707012 0 0 -0.707202">
                          <inertial pos="0.00033388 1.06802e-05 0.0134865" quat="0.999892 0 -0.0146884 0" mass="0.0165" diaginertia="1.47088e-06 1.44e-06 4.49118e-07" />
                          <joint name="right_finger3_joint3" pos="0 0 0" axis="0 1 0" range="-0.4739 1.5512" actuatorfrcrange="-0.2078 0.2078" />
                          <geom type="mesh" rgba="0.792157 0.819608 0.933333 1" mesh="right_finger3_link3" class="visual" />
                          <geom type="mesh" rgba="0.792157 0.819608 0.933333 1" mesh="right_finger3_link3" class="collision" />
                          <body name="right_finger3_link4" pos="0 0 0.0295">
                            <inertial pos="-0.000815351 1.33579e-05 0.0107852" quat="0.995636 -0.00653894 -0.0926302 -0.00931398" mass="0.01718" diaginertia="1.1763e-06 1.07011e-06 4.03591e-07" />
                            <joint name="right_finger3_joint4" pos="0 0 0" axis="0 1 0" range="-0.4684 1.5745" actuatorfrcrange="-0.2018 0.2018" />
                            <geom type="mesh" rgba="0.792157 0.819608 0.933333 1" mesh="right_finger3_link4" class="visual" />
                            <geom type="mesh" rgba="0.792157 0.819608 0.933333 1" mesh="right_finger3_link4" class="collision" />
                            <geom pos="-0.00075 0 0.024" quat="1 0 0 -0.000156524" type="mesh" rgba="0.792157 0.819608 0.933333 1" mesh="right_finger3_tip_link" class="visual" />
                            <geom pos="-0.00075 0 0.024" quat="1 0 0 -0.000156524" type="mesh" rgba="0.792157 0.819608 0.933333 1" mesh="right_finger3_tip_link" class="collision" />
                          </body>
                        </body>
                      </body>
                    </body>
                    <body name="right_finger4_link1" pos="-0.0076649 -0.204429 -0.0137123" quat="0.672943 0.738143 -0.046661 -0.0107397">
                      <inertial pos="-0.00132912 1.24361e-09 0.000319884" quat="0.92388 0 0.382683 0" mass="0.0032" diaginertia="1.1e-07 7e-08 5e-08" />
                      <joint name="right_finger4_joint1" pos="0 0 0" axis="0 1 0" range="-0.1554 1.5585" actuatorfrcrange="-0.6389 0.6389" />
                      <geom type="mesh" rgba="0.792157 0.819608 0.933333 1" mesh="right_finger4_link1" class="visual" />
                      <geom type="mesh" rgba="0.792157 0.819608 0.933333 1" mesh="right_finger4_link1" class="collision" />
                      <body name="right_finger4_link2" pos="0.0022 0 0.00400001" quat="0.707107 -0.000213851 -0.000213851 0.707107">
                        <inertial pos="1.84945e-06 0.00370375 0.0185161" quat="0.70703 0.0104245 0.0104245 0.70703" mass="0.033" diaginertia="6.34e-06 6.31472e-06 8.85281e-07" />
                        <joint name="right_finger4_joint2" pos="0 0 0" axis="0 1 0" range="-0.37 0.37" actuatorfrcrange="-0.1832 0.1832" />
                        <geom type="mesh" rgba="0.792157 0.819608 0.933333 1" mesh="right_finger4_link2" class="visual" />
                        <geom type="mesh" rgba="0.792157 0.819608 0.933333 1" mesh="right_finger4_link2" class="collision" />
                        <body name="right_finger4_link3" pos="0 0.00472362 0.0436206" quat="0.707012 0.00021388 0.000213823 -0.707202">
                          <inertial pos="0.000319082 1.04411e-05 0.0135409" quat="0.999892 0 -0.0146884 0" mass="0.0165" diaginertia="1.47088e-06 1.44e-06 4.49118e-07" />
                          <joint name="right_finger4_joint3" pos="0 0 0" axis="0 1 0" range="-0.4765 1.5487" actuatorfrcrange="-0.2249 0.2249" />
                          <geom type="mesh" rgba="0.792157 0.819608 0.933333 1" mesh="right_finger4_link3" class="visual" />
                          <geom type="mesh" rgba="0.792157 0.819608 0.933333 1" mesh="right_finger4_link3" class="collision" />
                          <body name="right_finger4_link4" pos="0 0 0.0295">
                            <inertial pos="-0.000865094 1.02364e-05 0.0108406" quat="0.995635 -0.00653716 -0.0926302 -0.00932836" mass="0.01718" diaginertia="1.1763e-06 1.07011e-06 4.03591e-07" />
                            <joint name="right_finger4_joint4" pos="0 0 0" axis="0 1 0" range="-0.4777 1.5634" actuatorfrcrange="-0.2044 0.2044" />
                            <geom type="mesh" rgba="0.792157 0.819608 0.933333 1" mesh="right_finger4_link4" class="visual" />
                            <geom type="mesh" rgba="0.792157 0.819608 0.933333 1" mesh="right_finger4_link4" class="collision" />
                            <geom pos="-0.000811164 0 0.0239995" quat="1 0 0 0" type="mesh" rgba="0.792157 0.819608 0.933333 1" mesh="right_finger4_tip_link" class="visual" />
                            <geom pos="-0.000811164 0 0.0239995" quat="1 0 0 0" type="mesh" rgba="0.792157 0.819608 0.933333 1" mesh="right_finger4_tip_link" class="collision" />
                          </body>
                        </body>
                      </body>
                    </body>
                    <body name="right_finger5_link1" pos="-0.00226865 -0.194281 -0.0340014" quat="0.630421 0.77088 -0.0856036 0.031403">
                      <inertial pos="-0.00132913 1.08611e-08 0.000319899" quat="0.92388 0 0.382683 0" mass="0.0032" diaginertia="1.1e-07 7e-08 5e-08" />
                      <joint name="right_finger5_joint1" pos="0 0 0" axis="0 1 0" range="-0.1626 1.5585" actuatorfrcrange="-0.6441 0.6441" />
                      <geom type="mesh" rgba="0.792157 0.819608 0.933333 1" mesh="right_finger5_link1" class="visual" />
                      <geom type="mesh" rgba="0.792157 0.819608 0.933333 1" mesh="right_finger5_link1" class="collision" />
                      <body name="right_finger5_link2" pos="0.0022 0 0.00400001" quat="0.707107 -0.00026748 -0.00026748 0.707107">
                        <inertial pos="1.84966e-06 0.0037023 0.0193362" quat="0.70703 0.0104245 0.0104245 0.70703" mass="0.033" diaginertia="6.34e-06 6.31472e-06 8.85281e-07" />
                        <joint name="right_finger5_joint2" pos="0 0 0" axis="0 1 0" range="-0.37 0.37" actuatorfrcrange="-0.1798 0.1798" />
                        <geom type="mesh" rgba="0.792157 0.819608 0.933333 1" mesh="right_finger5_link2" class="visual" />
                        <geom type="mesh" rgba="0.792157 0.819608 0.933333 1" mesh="right_finger5_link2" class="collision" />
                        <body name="right_finger5_link3" pos="0 0.004717 0.0436213" quat="0.707012 0.000267516 0.000267444 -0.707202">
                          <inertial pos="0.000328501 5.05492e-06 0.0142853" quat="0.999892 0 -0.0146884 0" mass="0.0165" diaginertia="1.47088e-06 1.44e-06 4.49118e-07" />
                          <joint name="right_finger5_joint3" pos="0 0 0" axis="0 1 0" range="-0.4768 1.549" actuatorfrcrange="-0.2384 0.2384" />
                          <geom type="mesh" rgba="0.792157 0.819608 0.933333 1" mesh="right_finger5_link3" class="visual" />
                          <geom type="mesh" rgba="0.792157 0.819608 0.933333 1" mesh="right_finger5_link3" class="collision" />
                          <body name="right_finger5_link4" pos="0 0 0.0295">
                            <inertial pos="-0.000908093 -1.90573e-05 0.0122784" quat="0.995635 -0.00653716 -0.0926302 -0.00932836" mass="0.01718" diaginertia="1.1763e-06 1.07011e-06 4.03591e-07" />
                            <joint name="right_finger5_joint4" pos="0 0 0" axis="0 1 0" range="-0.4683 1.5735" actuatorfrcrange="-0.1866 0.1866" />
                            <geom type="mesh" rgba="0.792157 0.819608 0.933333 1" mesh="right_finger5_link4" class="visual" />
                            <geom type="mesh" rgba="0.792157 0.819608 0.933333 1" mesh="right_finger5_link4" class="collision" />
                            <geom pos="-0.000828016 0 0.0259994" quat="1 0 0 0" type="mesh" rgba="0.792157 0.819608 0.933333 1" mesh="right_finger5_tip_link" class="visual" />
                            <geom pos="-0.000828016 0 0.0259994" quat="1 0 0 0" type="mesh" rgba="0.792157 0.819608 0.933333 1" mesh="right_finger5_tip_link" class="collision" />
                          </body>
                        </body>
                      </body>
                    </body>
                  </body>
                </body>
              </body>
            </body>
          </body>
        </body>
      </body>
    </body>
  </worldbody>
</mujoco>
