<mujoco model="wujihand-left">
  <compiler angle="radian" />

  <option jacobian="sparse" integrator="RK4" timestep="0.002" solver="Newton" iterations="50" tolerance="1e-10" /><default><joint armature="0.0002" damping="0.0" /></default><asset>
    <mesh name="left_palm_link" content_type="model/stl" file="../meshes/left/left_palm_link.STL" />
    <mesh name="left_palm_link_collision" content_type="model/stl" file="../meshes/left/left_palm_link_simplified.STL" />
    <mesh name="left_finger1_link1" content_type="model/stl" file="../meshes/left/left_finger1_link1.STL" />
    <mesh name="left_finger1_link2" content_type="model/stl" file="../meshes/left/left_finger1_link2.STL" />
    <mesh name="left_finger1_link3" content_type="model/stl" file="../meshes/left/left_finger1_link3.STL" />
    <mesh name="left_finger1_link4" content_type="model/stl" file="../meshes/left/left_finger1_link4.STL" />
    <mesh name="left_finger1_link4_simplified" content_type="model/stl" file="../meshes/left/left_finger1_link4_simplified.STL" />
    <mesh name="left_finger1_tip_link" content_type="model/stl" file="../meshes/left/left_finger1_tip_link.STL" />
    <mesh name="left_finger1_link2_softbody" content_type="model/stl" file="../meshes/left/left_finger1_link2_softbody.STL" />
    <mesh name="left_finger1_link2_softbody_simplified" content_type="model/stl" file="../meshes/left/left_finger1_link2_softbody_simplified.STL" />
    <mesh name="left_finger2_link1" content_type="model/stl" file="../meshes/left/left_finger2_link1.STL" />
    <mesh name="left_finger2_link2" content_type="model/stl" file="../meshes/left/left_finger2_link2.STL" />
    <mesh name="left_finger2_link3" content_type="model/stl" file="../meshes/left/left_finger2_link3.STL" />
    <mesh name="left_finger2_link4" content_type="model/stl" file="../meshes/left/left_finger2_link4.STL" />
    <mesh name="left_finger2_link4_simplified" content_type="model/stl" file="../meshes/left/left_finger2_link4_simplified.STL" />
    <mesh name="left_finger2_tip_link" content_type="model/stl" file="../meshes/left/left_finger2_tip_link.STL" />
    <mesh name="left_finger3_link1" content_type="model/stl" file="../meshes/left/left_finger3_link1.STL" />
    <mesh name="left_finger3_link2" content_type="model/stl" file="../meshes/left/left_finger3_link2.STL" />
    <mesh name="left_finger3_link3" content_type="model/stl" file="../meshes/left/left_finger3_link3.STL" />
    <mesh name="left_finger3_link4" content_type="model/stl" file="../meshes/left/left_finger3_link4.STL" />
    <mesh name="left_finger3_link4_simplified" content_type="model/stl" file="../meshes/left/left_finger3_link4_simplified.STL" />
    <mesh name="left_finger3_tip_link" content_type="model/stl" file="../meshes/left/left_finger3_tip_link.STL" />
    <mesh name="left_finger4_link1" content_type="model/stl" file="../meshes/left/left_finger4_link1.STL" />
    <mesh name="left_finger4_link2" content_type="model/stl" file="../meshes/left/left_finger4_link2.STL" />
    <mesh name="left_finger4_link3" content_type="model/stl" file="../meshes/left/left_finger4_link3.STL" />
    <mesh name="left_finger4_link4" content_type="model/stl" file="../meshes/left/left_finger4_link4.STL" />
    <mesh name="left_finger4_link4_simplified" content_type="model/stl" file="../meshes/left/left_finger4_link4_simplified.STL" />
    <mesh name="left_finger4_tip_link" content_type="model/stl" file="../meshes/left/left_finger4_tip_link.STL" />
    <mesh name="left_finger5_link1" content_type="model/stl" file="../meshes/left/left_finger5_link1.STL" />
    <mesh name="left_finger5_link2" content_type="model/stl" file="../meshes/left/left_finger5_link2.STL" />
    <mesh name="left_finger5_link3" content_type="model/stl" file="../meshes/left/left_finger5_link3.STL" />
    <mesh name="left_finger5_link4" content_type="model/stl" file="../meshes/left/left_finger5_link4.STL" />
    <mesh name="left_finger5_link4_simplified" content_type="model/stl" file="../meshes/left/left_finger5_link4_simplified.STL" />
    <mesh name="left_finger5_tip_link" content_type="model/stl" file="../meshes/left/left_finger5_tip_link.STL" />
  </asset>

  <worldbody>
    <body name="left_palm_link"><inertial pos="0.001524452695 -0.002642346221 0.03766991642" mass="0.16914" quat="-0.01772809 0.04274722 0.09308295 -0.99458230" diaginertia="0.000140677446 9.5889647500e-05 5.8132906100e-05" /><geom type="mesh" contype="0" conaffinity="0" group="1" density="0" rgba="0.6 0.8 0.9 1" mesh="left_palm_link" />
    <geom type="mesh" rgba="0.6 0.8 0.9 1" mesh="left_palm_link_collision" contype="1" conaffinity="1" />
    <body name="left_finger1_link1" pos="0.00852444 -0.0205754 0.0287119" quat="0.682211 0.617678 0.0805082 0.382859">
      <inertial pos="-0.00246155 0.00144069 0.00778554" quat="0.904243 0.21652 0.0443878 -0.365368" mass="0.0075" diaginertia="3.37599e-07 3.01198e-07 2.11203e-07" />
      <joint name="left_finger1_joint1" pos="0 0 0" axis="0 1 0" range="0.0475 1.6033" actuatorfrcrange="-0.4452 0.4452" armature="0.0005" />
      <geom type="mesh" contype="0" conaffinity="0" group="1" density="0" rgba="0.7 0.7 0.7 1" mesh="left_finger1_link1" />
      <geom type="capsule" size="0.00615198 0.00362986" pos="0 0 0.00827912" rgba="0.7 0.7 0.7 1" contype="0" conaffinity="0" />
      <body name="left_finger1_link2" pos="-0.0047549 0.00601914 0.0141321" quat="0.616957 0.0855876 -0.29085 -0.726254">
        <inertial pos="0.00136084 -8.51198e-05 0.0150055" quat="0.926192 0.00548447 -0.048696 -0.373854" mass="0.0333513" diaginertia="4.1738e-06 4.1045e-06 2.19539e-06" />
        <joint name="left_finger1_joint2" pos="0 0 0" axis="0 -1 0" range="-0.1387 0.9324" actuatorfrcrange="-0.4259 0.4259" armature="0.0005" />
        <geom type="mesh" contype="0" conaffinity="0" group="1" density="0" rgba="0.9 0.8 0.6 1" mesh="left_finger1_link2" />
        <geom type="capsule" size="0.00661572 0.0135192" pos="0 0 0.0170004" rgba="0.9 0.8 0.6 1" contype="2" conaffinity="2" />
        <geom type="mesh" contype="0" conaffinity="0" group="1" density="0" rgba="0.9 0.8 0.6 1" mesh="left_finger1_link2_softbody" />
        <geom type="mesh" rgba="0.9 0.8 0.6 1" mesh="left_finger1_link2_softbody_simplified" contype="2" conaffinity="2" />
        <body name="left_finger1_link3" pos="0.000188722 0.000991601 0.0346636" quat="0.577836 -0.0212382 -0.0150036 0.815739">
          <inertial pos="0.000774544 1.11939e-05 0.01277" quat="0.999951 0 0.00989566 0" mass="0.0165" diaginertia="1.4604e-06 1.42e-06 4.49604e-07" />
          <joint name="left_finger1_joint3" pos="0 0 0" axis="0 1 0" range="-0.4642 1.5623" actuatorfrcrange="-0.1888 0.1888" />
          <geom type="mesh" contype="0" conaffinity="0" group="1" density="0" rgba="0.6 0.8 0.9 1" mesh="left_finger1_link3" />
          <geom type="capsule" size="0.0110676 0.0081727" pos="0 0 0.0140091" rgba="0.6 0.8 0.9 1" contype="1" conaffinity="1" />
          <body name="left_finger1_link4" pos="0 -0.0002 0.0295">
            <inertial pos="2.97895e-05 0.000153669 0.0148862" quat="0.705242 -0.0513145 -0.0513145 0.705242" mass="0.0206" diaginertia="1.78779e-06 1.75041e-06 7.7738e-07" />
            <joint name="left_finger1_joint4" pos="0 0 0" axis="0 1 0" range="-0.4699 1.5568" actuatorfrcrange="-0.1468 0.1468" />
            <geom type="mesh" contype="0" conaffinity="0" group="1" density="0" rgba="0.6 0.8 0.9 1" mesh="left_finger1_link4" />
            <geom type="mesh" rgba="0.6 0.8 0.9 1" mesh="left_finger1_link4_simplified" contype="1" conaffinity="1" />
            <geom pos="0 0 0.0328135" type="mesh" contype="0" conaffinity="0" group="1" density="0" rgba="0.6 0.8 0.9 1" mesh="left_finger1_tip_link" />
            
          </body>
        </body>
      </body>
    </body>
    <body name="left_finger2_link1" pos="-0.00587009 -0.0294339 0.0919165" quat="0.991689 0.0588292 -0.0292755 0.110616">
      <inertial pos="-0.00132905 4.18014e-08 0.000320068" quat="0.92388 0 0.382683 0" mass="0.0032" diaginertia="1.1e-07 7e-08 5e-08" />
      <joint name="left_finger2_joint1" pos="0 0 0" axis="0 1 0" range="-0.1585 1.5604" actuatorfrcrange="-0.6188 0.6188" armature="0.0005" />
      <geom type="mesh" contype="0" conaffinity="0" group="1" density="0" rgba="0.7 0.7 0.7 1" mesh="left_finger2_link1" />
      <geom type="sphere" size="0.00936231" pos="0 0 -0.000714564" rgba="0.7 0.7 0.7 1" contype="0" conaffinity="0" />
      <body name="left_finger2_link2" pos="0.0022 0 0.00400001" quat="0.707107 0 0 0.707107">
        <inertial pos="-1.78565e-06 0.00370948 0.0184837" quat="0.70703 0.0104245 0.0104245 0.70703" mass="0.033" diaginertia="6.34e-06 6.31472e-06 8.85281e-07" />
        <joint name="left_finger2_joint2" pos="0 0 0" axis="0 1 0" range="-0.37 0.37" actuatorfrcrange="-0.1822 0.1822" />
        <geom type="mesh" contype="0" conaffinity="0" group="1" density="0" rgba="0.9 0.8 0.6 1" mesh="left_finger2_link2" />
        <geom type="capsule" size="0.010221 0.0169968" pos="0 0.003 0.021631" rgba="0.9 0.8 0.6 1" contype="2" conaffinity="2" />
        <body name="left_finger2_link3" pos="0 0.00475 0.0436177" quat="0.707202 0 0 -0.707012">
          <inertial pos="0.000341914 -1.40911e-05 0.0134812" quat="0.999892 0 -0.0146884 0" mass="0.0165" diaginertia="1.47088e-06 1.44e-06 4.49118e-07" />
          <joint name="left_finger2_joint3" pos="0 0 0" axis="0 1 0" range="-0.4777 1.5485" actuatorfrcrange="-0.2251 0.2251" />
          <geom type="mesh" contype="0" conaffinity="0" group="1" density="0" rgba="0.6 0.8 0.9 1" mesh="left_finger2_link3" />
          <geom type="capsule" size="0.010221 0.0108889" pos="0 0 0.0136213" rgba="0.6 0.8 0.9 1" contype="1" conaffinity="1" />
          <body name="left_finger2_link4" pos="0 0 0.0295">
            <inertial pos="-0.000815133 -1.35285e-05 0.0107847" quat="0.995635 -0.00653716 -0.0926302 -0.00932836" mass="0.01718" diaginertia="1.1763e-06 1.07011e-06 4.03591e-07" />
            <joint name="left_finger2_joint4" pos="0 0 0" axis="0 1 0" range="-0.4683 1.5753" actuatorfrcrange="-0.217 0.217" />
            <geom type="mesh" contype="0" conaffinity="0" group="1" density="0" rgba="0.6 0.8 0.9 1" mesh="left_finger2_link4" />
            <geom type="mesh" rgba="0.6 0.8 0.9 1" mesh="left_finger2_link4_simplified" contype="1" conaffinity="1" />
            <geom pos="0 0 0.024" quat="1 0 0 0" type="mesh" contype="0" conaffinity="0" group="1" density="0" rgba="0.6 0.8 0.9 1" mesh="left_finger2_tip_link" />
            
          </body>
        </body>
      </body>
    </body>
    <body name="left_finger3_link1" pos="-0.0104597 -0.00746146 0.0895435" quat="0.999048 1.26889e-05 -0.0436194 -0.000290548">
      <inertial pos="-0.0013291 3.85118e-08 0.000319976" quat="0.92388 0 0.382683 0" mass="0.0032" diaginertia="1.1e-07 7e-08 5e-08" />
      <joint name="left_finger3_joint1" pos="0 0 0" axis="0 1 0" range="-0.1644 1.5516" actuatorfrcrange="-0.6494 0.6494" armature="0.0005" />
      <geom type="mesh" contype="0" conaffinity="0" group="1" density="0" rgba="0.7 0.7 0.7 1" mesh="left_finger3_link1" />
      <geom type="sphere" size="0.00939653" pos="0 0 -0.000715513" rgba="0.7 0.7 0.7 1" contype="0" conaffinity="0" />
      <body name="left_finger3_link2" pos="0.0022 0 0.00400001" quat="0.707107 0 0 0.707107">
        <inertial pos="-1.82891e-06 0.00370965 0.0184837" quat="0.70703 0.0104245 0.0104245 0.70703" mass="0.033" diaginertia="6.34e-06 6.31472e-06 8.85281e-07" />
        <joint name="left_finger3_joint2" pos="0 0 0" axis="0 1 0" range="-0.37 0.37" actuatorfrcrange="-0.1827 0.1827" />
        <geom type="mesh" contype="0" conaffinity="0" group="1" density="0" rgba="0.9 0.8 0.6 1" mesh="left_finger3_link2" />
        <geom type="capsule" size="0.010184 0.0170338" pos="0 0.003 0.021631" rgba="0.9 0.8 0.6 1" contype="2" conaffinity="2" />
        <body name="left_finger3_link3" pos="0 0.00475 0.0436177" quat="0.707202 0 0 -0.707012">
          <inertial pos="0.000333742 -1.05568e-05 0.0134866" quat="0.999892 0 -0.0146884 0" mass="0.0165" diaginertia="1.47088e-06 1.44e-06 4.49118e-07" />
          <joint name="left_finger3_joint3" pos="0 0 0" axis="0 1 0" range="-0.4739 1.5512" actuatorfrcrange="-0.2078 0.2078" />
          <geom type="mesh" contype="0" conaffinity="0" group="1" density="0" rgba="0.6 0.8 0.9 1" mesh="left_finger3_link3" />
          <geom type="capsule" size="0.010184 0.0109259" pos="0 0 0.0136212" rgba="0.6 0.8 0.9 1" contype="1" conaffinity="1" />
          <body name="left_finger3_link4" pos="0 0 0.0295">
            <inertial pos="-0.000815615 -1.34653e-05 0.0107846" quat="0.995635 -0.00653716 -0.0926302 -0.00932836" mass="0.01718" diaginertia="1.1763e-06 1.07011e-06 4.03591e-07" />
            <joint name="left_finger3_joint4" pos="0 0 0" axis="0 1 0" range="-0.4684 1.5745" actuatorfrcrange="-0.2018 0.2018" />
            <geom type="mesh" contype="0" conaffinity="0" group="1" density="0" rgba="0.6 0.8 0.9 1" mesh="left_finger3_link4" />
            <geom type="mesh" rgba="0.6 0.8 0.9 1" mesh="left_finger3_link4_simplified" contype="1" conaffinity="1" />
            <geom pos="0 0 0.024" quat="1 0 0 0" type="mesh" contype="0" conaffinity="0" group="1" density="0" rgba="0.6 0.8 0.9 1" mesh="left_finger3_tip_link" />
            
          </body>
        </body>
      </body>
    </body>
    <body name="left_finger4_link1" pos="-0.00766486 0.0137122 0.0844287" quat="0.997789 -0.0461017 -0.0405881 -0.0254">
      <inertial pos="-0.00132911 4.56181e-08 0.000319941" quat="0.92388 0 0.382683 0" mass="0.0032" diaginertia="1.1e-07 7e-08 5e-08" />
      <joint name="left_finger4_joint1" pos="0 0 0" axis="0 1 0" range="-0.1554 1.5585" actuatorfrcrange="-0.6389 0.6389" armature="0.0005" />
      <geom type="mesh" contype="0" conaffinity="0" group="1" density="0" rgba="0.7 0.7 0.7 1" mesh="left_finger4_link1" />
      <geom type="sphere" size="0.00938587" pos="0 0 -0.000693929" rgba="0.7 0.7 0.7 1" contype="0" conaffinity="0" />
      <body name="left_finger4_link2" pos="0.0022 0 0.00400001" quat="0.707107 0 0 0.707107">
        <inertial pos="-1.82336e-06 0.00371493 0.0185138" quat="0.70703 0.0104245 0.0104245 0.70703" mass="0.033" diaginertia="6.34e-06 6.31472e-06 8.85281e-07" />
        <joint name="left_finger4_joint2" pos="0 0 0" axis="0 1 0" range="-0.37 0.37" actuatorfrcrange="-0.1832 0.1832" />
        <geom type="mesh" contype="0" conaffinity="0" group="1" density="0" rgba="0.9 0.8 0.6 1" mesh="left_finger4_link2" />
        <geom type="capsule" size="0.0101786 0.0170048" pos="0 0.003 0.021669" rgba="0.9 0.8 0.6 1" contype="2" conaffinity="2" />
        <body name="left_finger4_link3" pos="0 0.00475 0.0436177" quat="0.707202 0 0 -0.707012">
          <inertial pos="0.00031892 -1.03297e-05 0.0135407" quat="0.999892 0 -0.0146884 0" mass="0.0165" diaginertia="1.47088e-06 1.44e-06 4.49118e-07" />
          <joint name="left_finger4_joint3" pos="0 0 0" axis="0 1 0" range="-0.4765 1.5487" actuatorfrcrange="-0.2249 0.2249" />
          <geom type="mesh" contype="0" conaffinity="0" group="1" density="0" rgba="0.6 0.8 0.9 1" mesh="left_finger4_link3" />
          <geom type="capsule" size="0.0101786 0.0108995" pos="0 0 0.0136532" rgba="0.6 0.8 0.9 1" contype="1" conaffinity="1" />
          <body name="left_finger4_link4" pos="0 0 0.0295">
            <inertial pos="-0.000864592 -1.02217e-05 0.0108394" quat="0.995635 -0.00653716 -0.0926302 -0.00932836" mass="0.01718" diaginertia="1.1763e-06 1.07011e-06 4.03591e-07" />
            <joint name="left_finger4_joint4" pos="0 0 0" axis="0 1 0" range="-0.4777 1.5634" actuatorfrcrange="-0.2044 0.2044" />
            <geom type="mesh" contype="0" conaffinity="0" group="1" density="0" rgba="0.6 0.8 0.9 1" mesh="left_finger4_link4" />
            <geom type="mesh" rgba="0.6 0.8 0.9 1" mesh="left_finger4_link4_simplified" contype="1" conaffinity="1" />
            <geom pos="0 0 0.024" quat="1 0 0 0" type="mesh" contype="0" conaffinity="0" group="1" density="0" rgba="0.6 0.8 0.9 1" mesh="left_finger4_tip_link" />
            
          </body>
        </body>
      </body>
    </body>
    <body name="left_finger5_link1" pos="-0.00226865 0.0340011 0.0742813" quat="0.990869 -0.0993173 -0.0383255 -0.0827362">
      <inertial pos="-0.00132912 3.31411e-08 0.000319867" quat="0.92388 0 0.382683 0" mass="0.0032" diaginertia="1.1e-07 7e-08 5e-08" />
      <joint name="left_finger5_joint1" pos="0 0 0" axis="0 1 0" range="-0.1626 1.5585" actuatorfrcrange="-0.6441 0.6441" armature="0.0005" />
      <geom type="mesh" contype="0" conaffinity="0" group="1" density="0" rgba="0.7 0.7 0.7 1" mesh="left_finger5_link1" />
      <geom type="sphere" size="0.00939158" pos="0 0 -0.000718182" rgba="0.7 0.7 0.7 1" contype="0" conaffinity="0" />
      <body name="left_finger5_link2" pos="0.0022 0 0.00400001" quat="0.707107 0 0 0.707107">
        <inertial pos="-1.8211e-06 0.00371684 0.0193334" quat="0.70703 0.0104245 0.0104245 0.70703" mass="0.033" diaginertia="6.34e-06 6.31472e-06 8.85281e-07" />
        <joint name="left_finger5_joint2" pos="0 0 0" axis="0 1 0" range="-0.37 0.37" actuatorfrcrange="-0.1798 0.1798" />
        <geom type="mesh" contype="0" conaffinity="0" group="1" density="0" rgba="0.9 0.8 0.6 1" mesh="left_finger5_link2" />
        <geom type="capsule" size="0.0101586 0.016917" pos="0 0.003 0.0217777" rgba="0.9 0.8 0.6 1" contype="2" conaffinity="2" />
        <body name="left_finger5_link3" pos="0 0.00475 0.0436177" quat="0.707202 0 0 -0.707012">
          <inertial pos="0.000353514 -5.08998e-06 0.0139268" quat="0.999892 0 -0.0146884 0" mass="0.0165" diaginertia="1.47088e-06 1.44e-06 4.49118e-07" />
          <joint name="left_finger5_joint3" pos="0 0 0" axis="0 1 0" range="-0.4768 1.549" actuatorfrcrange="-0.2384 0.2384" />
          <geom type="mesh" contype="0" conaffinity="0" group="1" density="0" rgba="0.6 0.8 0.9 1" mesh="left_finger5_link3" />
          <geom type="capsule" size="0.0101586 0.00992035" pos="0 0 0.0146523" rgba="0.6 0.8 0.9 1" contype="1" conaffinity="1" />
          <body name="left_finger5_link4" pos="0 0 0.0295">
            <inertial pos="-0.000906048 1.84282e-05 0.0122759" quat="0.995635 -0.00653716 -0.0926302 -0.00932836" mass="0.01718" diaginertia="1.1763e-06 1.07011e-06 4.03591e-07" />
            <joint name="left_finger5_joint4" pos="0 0 0" axis="0 1 0" range="-0.4683 1.5735" actuatorfrcrange="-0.1866 0.1866" />
            <geom type="mesh" contype="0" conaffinity="0" group="1" density="0" rgba="0.6 0.8 0.9 1" mesh="left_finger5_link4" />
            <geom type="mesh" rgba="0.6 0.8 0.9 1" mesh="left_finger5_link4_simplified" contype="1" conaffinity="1" />
            <geom pos="0 0 0.026" quat="1 0 0 0" type="mesh" contype="0" conaffinity="0" group="1" density="0" rgba="0.6 0.8 0.9 1" mesh="left_finger5_tip_link" />
            
          </body>
        </body>
      </body>
    </body>
  </body></worldbody>
  <actuator>
    <position name="left_finger1_joint1_actuator" joint="left_finger1_joint1" kp="0.40844710645048043" kv="0.020882010257063675" ctrlrange="0.0475 1.6033" forcerange="-0.4452 0.4452" />
    <position name="left_finger1_joint2_actuator" joint="left_finger1_joint2" kp="0.6858601063643346" kv="0.030610939996373314" ctrlrange="-0.1387 0.9324" forcerange="-0.4259 0.4259" />
    <position name="left_finger1_joint3_actuator" joint="left_finger1_joint3" kp="0.2391112196099482" kv="0.010181475050560962" ctrlrange="-0.4642 1.5623" forcerange="-0.1888 0.1888" />
    <position name="left_finger1_joint4_actuator" joint="left_finger1_joint4" kp="0.20736128319711747" kv="0.00909698844675045" ctrlrange="-0.4699 1.5568" forcerange="-0.1468 0.1468" />
    <position name="left_finger2_joint1_actuator" joint="left_finger2_joint1" kp="0.37352218155860073" kv="0.01882274330029718" ctrlrange="-0.1585 1.5604" forcerange="-0.6188 0.6188" />
    <position name="left_finger2_joint2_actuator" joint="left_finger2_joint2" kp="0.45592448909027794" kv="0.019798167597016643" ctrlrange="-0.37 0.37" forcerange="-0.1822 0.1822" />
    <position name="left_finger2_joint3_actuator" joint="left_finger2_joint3" kp="0.24368366649522863" kv="0.010477031953162727" ctrlrange="-0.4777 1.5485" forcerange="-0.2251 0.2251" />
    <position name="left_finger2_joint4_actuator" joint="left_finger2_joint4" kp="0.18026971340925335" kv="0.008240212147903584" ctrlrange="-0.4683 1.5753" forcerange="-0.217 0.217" />
    <position name="left_finger3_joint1_actuator" joint="left_finger3_joint1" kp="0.3687093483646485" kv="0.01848622487024593" ctrlrange="-0.1644 1.5516" forcerange="-0.6494 0.6494" />
    <position name="left_finger3_joint2_actuator" joint="left_finger3_joint2" kp="0.4164253443634641" kv="0.018032947229953678" ctrlrange="-0.37 0.37" forcerange="-0.1827 0.1827" />
    <position name="left_finger3_joint3_actuator" joint="left_finger3_joint3" kp="0.22218607502059182" kv="0.009592200014076666" ctrlrange="-0.4739 1.5512" forcerange="-0.2078 0.2078" />
    <position name="left_finger3_joint4_actuator" joint="left_finger3_joint4" kp="0.19427606072023446" kv="0.009152994605972402" ctrlrange="-0.4684 1.5745" forcerange="-0.2018 0.2018" />
    <position name="left_finger4_joint1_actuator" joint="left_finger4_joint1" kp="0.35718151495111794" kv="0.018376606800780005" ctrlrange="-0.1554 1.5585" forcerange="-0.6389 0.6389" />
    <position name="left_finger4_joint2_actuator" joint="left_finger4_joint2" kp="0.42977315313086895" kv="0.01867700966212433" ctrlrange="-0.37 0.37" forcerange="-0.1832 0.1832" />
    <position name="left_finger4_joint3_actuator" joint="left_finger4_joint3" kp="0.24930151196247122" kv="0.01059512121009555" ctrlrange="-0.4765 1.5487" forcerange="-0.2249 0.2249" />
    <position name="left_finger4_joint4_actuator" joint="left_finger4_joint4" kp="0.2285032688178066" kv="0.009917602877441107" ctrlrange="-0.4777 1.5634" forcerange="-0.2044 0.2044" />
    <position name="left_finger5_joint1_actuator" joint="left_finger5_joint1" kp="0.3655325975433942" kv="0.018616960278988272" ctrlrange="-0.1626 1.5585" forcerange="-0.6441 0.6441" />
    <position name="left_finger5_joint2_actuator" joint="left_finger5_joint2" kp="0.41393113081120425" kv="0.018732177029667153" ctrlrange="-0.37 0.37" forcerange="-0.1798 0.1798" />
    <position name="left_finger5_joint3_actuator" joint="left_finger5_joint3" kp="0.22729367621965954" kv="0.00951005441616486" ctrlrange="-0.4768 1.549" forcerange="-0.2384 0.2384" />
    <position name="left_finger5_joint4_actuator" joint="left_finger5_joint4" kp="0.1964723550341816" kv="0.009017295241756363" ctrlrange="-0.4683 1.5735" forcerange="-0.1866 0.1866" />
  </actuator>
</mujoco>