<mujoco model="wujihand-right">
  <compiler angle="radian" />

  <option jacobian="sparse" integrator="RK4" timestep="0.002" solver="Newton" iterations="50" tolerance="1e-10" /><default><joint armature="0.0002" damping="0.0" /></default><asset>
    <mesh name="right_palm_link" content_type="model/stl" file="../meshes/right/right_palm_link.STL" />
    <mesh name="right_finger1_link1" content_type="model/stl" file="../meshes/right/right_finger1_link1.STL" />
    <mesh name="right_finger1_link2" content_type="model/stl" file="../meshes/right/right_finger1_link2.STL" />
    <mesh name="right_finger1_link3" content_type="model/stl" file="../meshes/right/right_finger1_link3.STL" />
    <mesh name="right_finger1_link4" content_type="model/stl" file="../meshes/right/right_finger1_link4.STL" />
    <mesh name="right_finger1_tip_link" content_type="model/stl" file="../meshes/right/right_finger1_tip_link.STL" />
    <mesh name="right_finger1_link2_softbody" content_type="model/stl" file="../meshes/right/right_finger1_link2_softbody.STL" />
    <mesh name="right_finger2_link1" content_type="model/stl" file="../meshes/right/right_finger2_link1.STL" />
    <mesh name="right_finger2_link2" content_type="model/stl" file="../meshes/right/right_finger2_link2.STL" />
    <mesh name="right_finger2_link3" content_type="model/stl" file="../meshes/right/right_finger2_link3.STL" />
    <mesh name="right_finger2_link4" content_type="model/stl" file="../meshes/right/right_finger2_link4.STL" />
    <mesh name="right_finger2_tip_link" content_type="model/stl" file="../meshes/right/right_finger2_tip_link.STL" />
    <mesh name="right_finger3_link1" content_type="model/stl" file="../meshes/right/right_finger3_link1.STL" />
    <mesh name="right_finger3_link2" content_type="model/stl" file="../meshes/right/right_finger3_link2.STL" />
    <mesh name="right_finger3_link3" content_type="model/stl" file="../meshes/right/right_finger3_link3.STL" />
    <mesh name="right_finger3_link4" content_type="model/stl" file="../meshes/right/right_finger3_link4.STL" />
    <mesh name="right_finger3_tip_link" content_type="model/stl" file="../meshes/right/right_finger3_tip_link.STL" />
    <mesh name="right_finger4_link1" content_type="model/stl" file="../meshes/right/right_finger4_link1.STL" />
    <mesh name="right_finger4_link2" content_type="model/stl" file="../meshes/right/right_finger4_link2.STL" />
    <mesh name="right_finger4_link3" content_type="model/stl" file="../meshes/right/right_finger4_link3.STL" />
    <mesh name="right_finger4_link4" content_type="model/stl" file="../meshes/right/right_finger4_link4.STL" />
    <mesh name="right_finger4_tip_link" content_type="model/stl" file="../meshes/right/right_finger4_tip_link.STL" />
    <mesh name="right_finger5_link1" content_type="model/stl" file="../meshes/right/right_finger5_link1.STL" />
    <mesh name="right_finger5_link2" content_type="model/stl" file="../meshes/right/right_finger5_link2.STL" />
    <mesh name="right_finger5_link3" content_type="model/stl" file="../meshes/right/right_finger5_link3.STL" />
    <mesh name="right_finger5_link4" content_type="model/stl" file="../meshes/right/right_finger5_link4.STL" />
    <mesh name="right_finger5_tip_link" content_type="model/stl" file="../meshes/right/right_finger5_tip_link.STL" />
  </asset>

  <worldbody>
    <body name="right_palm_link"><inertial pos="0.0015244526948108 0.0026423462207805 0.0376699164153404" mass="0.16914" quat="-0.01772809 -0.04274722 0.09308295 0.99458230" diaginertia="1.40677446e-04 9.58896475e-05 5.81329061e-05" /><geom type="mesh" contype="0" conaffinity="0" group="1" density="0" rgba="0.6 0.8 0.9 1" mesh="right_palm_link" />
    <geom type="mesh" rgba="0.6 0.8 0.9 1" mesh="right_palm_link" contype="1" conaffinity="1" />
    <body name="right_finger1_link1" pos="0.0085244 0.020575 0.028712" quat="0.682219 -0.617669 0.0805047 -0.382859">
      <inertial pos="-0.0099171 -0.0059845 0.00152324" quat="0.904243 0.21652 0.0443878 -0.365368" mass="0.0075" diaginertia="3.37599e-07 3.01198e-07 2.11203e-07" />
      <joint name="right_finger1_joint1" pos="0 0 0" axis="0 1 0" range="0.0475 1.6033" actuatorfrcrange="-0.4452 0.4452" armature="0.0005" />
      <geom type="mesh" contype="0" conaffinity="0" group="1" density="0" rgba="0.7 0.7 0.7 1" mesh="right_finger1_link1" />
      <geom type="mesh" rgba="0.7 0.7 0.7 1" mesh="right_finger1_link1" contype="0" conaffinity="0" />
      <body name="right_finger1_link2" pos="-0.0047549 -0.0060191 0.014132" quat="0.726252 0.290851 -0.0855912 -0.616958">
        <inertial pos="-0.00136057 -8.49029e-05 0.0150056" quat="0.922053 0.00470413 0.0434721 0.384585" mass="0.0333532" diaginertia="4.2114e-06 4.06368e-06 2.19943e-06" />
        <joint name="right_finger1_joint2" pos="0 0 0" axis="0 1 0" range="-0.1387 0.9324" actuatorfrcrange="-0.4259 0.4259" armature="0.0005" />
        <geom type="mesh" contype="0" conaffinity="0" group="1" density="0" rgba="0.9 0.8 0.6 1" mesh="right_finger1_link2" />
        <geom type="mesh" rgba="0.9 0.8 0.6 1" mesh="right_finger1_link2" contype="2" conaffinity="2" />
        <geom type="mesh" contype="0" conaffinity="0" group="1" density="0" rgba="0.9 0.8 0.6 1" mesh="right_finger1_link2_softbody" />
        <geom type="mesh" rgba="0.9 0.8 0.6 1" mesh="right_finger1_link2_softbody" contype="2" conaffinity="2" />
        <body name="right_finger1_link3" pos="-0.00037714 0.001058 0.034673" quat="0.815725 0.015003 0.0212383 0.577855">
          <inertial pos="0.000775215 -0.000210057 0.0127726" quat="0.999951 0 0.00989566 0" mass="0.0165" diaginertia="1.4604e-06 1.42e-06 4.49604e-07" />
          <joint name="right_finger1_joint3" pos="0 0 0" axis="0 1 0" range="-0.4642 1.5623" actuatorfrcrange="-0.1888 0.1888" />
          <geom type="mesh" contype="0" conaffinity="0" group="1" density="0" rgba="0.6 0.8 0.9 1" mesh="right_finger1_link3" />
          <geom type="mesh" rgba="0.6 0.8 0.9 1" mesh="right_finger1_link3" contype="1" conaffinity="1" />
          <body name="right_finger1_link4" pos="0 0 0.0295">
            <inertial pos="3.12489e-05 -0.0001544 0.0148945" quat="0.705239 -0.0513648 -0.0513648 0.705239" mass="0.0206" diaginertia="1.78779e-06 1.75044e-06 7.77343e-07" />
            <joint name="right_finger1_joint4" pos="0 0 0" axis="0 1 0" range="-0.4699 1.5568" actuatorfrcrange="-0.1468 0.1468" />
            <geom type="mesh" contype="0" conaffinity="0" group="1" density="0" rgba="0.6 0.8 0.9 1" mesh="right_finger1_link4" />
            <geom type="mesh" rgba="0.6 0.8 0.9 1" mesh="right_finger1_link4" contype="1" conaffinity="1" />
            <geom pos="0.00026399 -0.00020119 0.032808" type="mesh" contype="0" conaffinity="0" group="1" density="0" rgba="0.6 0.8 0.9 1" mesh="right_finger1_tip_link" />
            <geom pos="0.00026399 -0.00020119 0.032808" type="mesh" rgba="0.6 0.8 0.9 1" mesh="right_finger1_tip_link" contype="1" conaffinity="1" />
          </body>
        </body>
      </body>
    </body>
    <body name="right_finger2_link1" pos="-0.0058701 0.029434 0.091917" quat="0.991689 -0.0588295 -0.0292755 -0.110614">
      <inertial pos="-0.00132914 -2.06891e-08 0.000319815" quat="0.92388 0 0.382683 0" mass="0.0032" diaginertia="1.1e-07 7e-08 5e-08" />
      <joint name="right_finger2_joint1" pos="0 0 0" axis="0 1 0" range="-0.1585 1.5604" actuatorfrcrange="-0.6188 0.6188" armature="0.0005" />
      <geom type="mesh" contype="0" conaffinity="0" group="1" density="0" rgba="0.7 0.7 0.7 1" mesh="right_finger2_link1" />
      <geom type="mesh" rgba="0.7 0.7 0.7 1" mesh="right_finger2_link1" contype="0" conaffinity="0" />
      <body name="right_finger2_link2" pos="0.0022 0 0.00400001" quat="0.707107 0 0 0.707107">
        <inertial pos="1.85614e-06 0.00370979 0.0184837" quat="0.70703 0.0104245 0.0104245 0.70703" mass="0.033" diaginertia="6.34e-06 6.31472e-06 8.85281e-07" />
        <joint name="right_finger2_joint2" pos="0 0 0" axis="0 1 0" range="-0.37 0.37" actuatorfrcrange="-0.1822 0.1822" />
        <geom type="mesh" contype="0" conaffinity="0" group="1" density="0" rgba="0.9 0.8 0.6 1" mesh="right_finger2_link2" />
        <geom type="mesh" rgba="0.9 0.8 0.6 1" mesh="right_finger2_link2" contype="2" conaffinity="2" />
        <body name="right_finger2_link3" pos="0 0.00475028 0.0436177" quat="0.707012 0 0 -0.707202">
          <inertial pos="0.000342045 1.41767e-05 0.0134814" quat="0.999892 0 -0.0146884 0" mass="0.0165" diaginertia="1.47088e-06 1.44e-06 4.49118e-07" />
          <joint name="right_finger2_joint3" pos="0 0 0" axis="0 1 0" range="-0.4777 1.5485" actuatorfrcrange="-0.2251 0.2251" />
          <geom type="mesh" contype="0" conaffinity="0" group="1" density="0" rgba="0.6 0.8 0.9 1" mesh="right_finger2_link3" />
          <geom type="mesh" rgba="0.6 0.8 0.9 1" mesh="right_finger2_link3" contype="1" conaffinity="1" />
          <body name="right_finger2_link4" pos="0 0 0.0295">
            <inertial pos="-0.000676323 -0.000125288 0.0107855" quat="0.995657 -0.0073755 -0.0927682 -0.00265853" mass="0.01718" diaginertia="1.17777e-06 1.07161e-06 4.06444e-07" />
            <joint name="right_finger2_joint4" pos="0 0 0" axis="0 1 0" range="-0.4683 1.5753" actuatorfrcrange="-0.217 0.217" />
            <geom type="mesh" contype="0" conaffinity="0" group="1" density="0" rgba="0.6 0.8 0.9 1" mesh="right_finger2_link4" />
            <geom type="mesh" rgba="0.6 0.8 0.9 1" mesh="right_finger2_link4" contype="1" conaffinity="1" />
            <geom pos="-0.000749345 0 0.024" quat="1 0 0 0" type="mesh" contype="0" conaffinity="0" group="1" density="0" rgba="0.6 0.8 0.9 1" mesh="right_finger2_tip_link" />
            <geom pos="-0.000749345 0 0.024" quat="1 0 0 0" type="mesh" rgba="0.6 0.8 0.9 1" mesh="right_finger2_tip_link" contype="1" conaffinity="1" />
          </body>
        </body>
      </body>
    </body>
    <body name="right_finger3_link1" pos="-0.01046 0.0074615 0.089544" quat="0.999048 -1.26848e-05 -0.0436192 0.000290547">
      <inertial pos="-0.00132908 3.41333e-09 0.000319983" quat="0.92388 0 0.382683 0" mass="0.0032" diaginertia="1.1e-07 7e-08 5e-08" />
      <joint name="right_finger3_joint1" pos="0 0 0" axis="0 1 0" range="-0.1644 1.5516" actuatorfrcrange="-0.6494 0.6494" armature="0.0005" />
      <geom type="mesh" contype="0" conaffinity="0" group="1" density="0" rgba="0.7 0.7 0.7 1" mesh="right_finger3_link1" />
      <geom type="mesh" rgba="0.7 0.7 0.7 1" mesh="right_finger3_link1" contype="0" conaffinity="0" />
      <body name="right_finger3_link2" pos="0.0022 0 0.00400001" quat="0.707107 0 0 0.707107">
        <inertial pos="1.86459e-06 0.0037098 0.0184837" quat="0.70703 0.0104245 0.0104245 0.70703" mass="0.033" diaginertia="6.34e-06 6.31472e-06 8.85281e-07" />
        <joint name="right_finger3_joint2" pos="0 0 0" axis="0 1 0" range="-0.37 0.37" actuatorfrcrange="-0.1827 0.1827" />
        <geom type="mesh" contype="0" conaffinity="0" group="1" density="0" rgba="0.9 0.8 0.6 1" mesh="right_finger3_link2" />
        <geom type="mesh" rgba="0.9 0.8 0.6 1" mesh="right_finger3_link2" contype="2" conaffinity="2" />
        <body name="right_finger3_link3" pos="0 0.00475 0.0436177" quat="0.707012 0 0 -0.707202">
          <inertial pos="0.00033388 1.06802e-05 0.0134865" quat="0.999892 0 -0.0146884 0" mass="0.0165" diaginertia="1.47088e-06 1.44e-06 4.49118e-07" />
          <joint name="right_finger3_joint3" pos="0 0 0" axis="0 1 0" range="-0.4739 1.5512" actuatorfrcrange="-0.2078 0.2078" />
          <geom type="mesh" contype="0" conaffinity="0" group="1" density="0" rgba="0.6 0.8 0.9 1" mesh="right_finger3_link3" />
          <geom type="mesh" rgba="0.6 0.8 0.9 1" mesh="right_finger3_link3" contype="1" conaffinity="1" />
          <body name="right_finger3_link4" pos="0 0 0.0295">
            <inertial pos="-0.000676528 -0.00012547 0.0107852" quat="0.995657 -0.00737867 -0.0927683 -0.00263311" mass="0.01718" diaginertia="1.17777e-06 1.07161e-06 4.06449e-07" />
            <joint name="right_finger3_joint4" pos="0 0 0" axis="0 1 0" range="-0.4684 1.5745" actuatorfrcrange="-0.2018 0.2018" />
            <geom type="mesh" contype="0" conaffinity="0" group="1" density="0" rgba="0.6 0.8 0.9 1" mesh="right_finger3_link4" />
            <geom type="mesh" rgba="0.6 0.8 0.9 1" mesh="right_finger3_link4" contype="1" conaffinity="1" />
            <geom pos="-0.00075 0 0.024" quat="1 0 0 -0.000156524" type="mesh" contype="0" conaffinity="0" group="1" density="0" rgba="0.6 0.8 0.9 1" mesh="right_finger3_tip_link" />
            <geom pos="-0.00075 0 0.024" quat="1 0 0 -0.000156524" type="mesh" rgba="0.6 0.8 0.9 1" mesh="right_finger3_tip_link" contype="1" conaffinity="1" />
          </body>
        </body>
      </body>
    </body>
    <body name="right_finger4_link1" pos="-0.0076649 -0.013712 0.084429" quat="0.997789 0.0461019 -0.0405884 0.0254002">
      <inertial pos="-0.00132912 1.24361e-09 0.000319884" quat="0.92388 0 0.382683 0" mass="0.0032" diaginertia="1.1e-07 7e-08 5e-08" />
      <joint name="right_finger4_joint1" pos="0 0 0" axis="0 1 0" range="-0.1554 1.5585" actuatorfrcrange="-0.6389 0.6389" armature="0.0005" />
      <geom type="mesh" contype="0" conaffinity="0" group="1" density="0" rgba="0.7 0.7 0.7 1" mesh="right_finger4_link1" />
      <geom type="mesh" rgba="0.7 0.7 0.7 1" mesh="right_finger4_link1" contype="0" conaffinity="0" />
      <body name="right_finger4_link2" pos="0.0022 0 0.00400001" quat="0.707107 -0.000213851 -0.000213851 0.707107">
        <inertial pos="1.84945e-06 0.00370375 0.0185161" quat="0.70703 0.0104245 0.0104245 0.70703" mass="0.033" diaginertia="6.34e-06 6.31472e-06 8.85281e-07" />
        <joint name="right_finger4_joint2" pos="0 0 0" axis="0 1 0" range="-0.37 0.37" actuatorfrcrange="-0.1832 0.1832" />
        <geom type="mesh" contype="0" conaffinity="0" group="1" density="0" rgba="0.9 0.8 0.6 1" mesh="right_finger4_link2" />
        <geom type="mesh" rgba="0.9 0.8 0.6 1" mesh="right_finger4_link2" contype="2" conaffinity="2" />
        <body name="right_finger4_link3" pos="0 0.00472362 0.0436206" quat="0.707012 0.00021388 0.000213823 -0.707202">
          <inertial pos="0.000319082 1.04411e-05 0.0135409" quat="0.999892 0 -0.0146884 0" mass="0.0165" diaginertia="1.47088e-06 1.44e-06 4.49118e-07" />
          <joint name="right_finger4_joint3" pos="0 0 0" axis="0 1 0" range="-0.4765 1.5487" actuatorfrcrange="-0.2249 0.2249" />
          <geom type="mesh" contype="0" conaffinity="0" group="1" density="0" rgba="0.6 0.8 0.9 1" mesh="right_finger4_link3" />
          <geom type="mesh" rgba="0.6 0.8 0.9 1" mesh="right_finger4_link3" contype="1" conaffinity="1" />
          <body name="right_finger4_link4" pos="0 0 0.0295">
            <inertial pos="-0.000714949 -0.000139909 0.0108406" quat="0.995656 -0.00751973 -0.0927913 -0.00151388" mass="0.01718" diaginertia="1.17803e-06 1.07186e-06 4.06933e-07" />
            <joint name="right_finger4_joint4" pos="0 0 0" axis="0 1 0" range="-0.4777 1.5634" actuatorfrcrange="-0.2044 0.2044" />
            <geom type="mesh" contype="0" conaffinity="0" group="1" density="0" rgba="0.6 0.8 0.9 1" mesh="right_finger4_link4" />
            <geom type="mesh" rgba="0.6 0.8 0.9 1" mesh="right_finger4_link4" contype="1" conaffinity="1" />
            <geom pos="-0.000811164 0 0.0239995" quat="1 0 0 0" type="mesh" contype="0" conaffinity="0" group="1" density="0" rgba="0.6 0.8 0.9 1" mesh="right_finger4_tip_link" />
            <geom pos="-0.000811164 0 0.0239995" quat="1 0 0 0" type="mesh" rgba="0.6 0.8 0.9 1" mesh="right_finger4_tip_link" contype="1" conaffinity="1" />
          </body>
        </body>
      </body>
    </body>
    <body name="right_finger5_link1" pos="-0.00226865 -0.0340011 0.0742813" quat="0.990869 0.0993173 -0.0383255 0.0827362">
      <inertial pos="-0.00132913 1.08611e-08 0.000319899" quat="0.92388 0 0.382683 0" mass="0.0032" diaginertia="1.1e-07 7e-08 5e-08" />
      <joint name="right_finger5_joint1" pos="0 0 0" axis="0 1 0" range="-0.1626 1.5585" actuatorfrcrange="-0.6441 0.6441" armature="0.0005" />
      <geom type="mesh" contype="0" conaffinity="0" group="1" density="0" rgba="0.7 0.7 0.7 1" mesh="right_finger5_link1" />
      <geom type="mesh" rgba="0.7 0.7 0.7 1" mesh="right_finger5_link1" contype="0" conaffinity="0" />
      <body name="right_finger5_link2" pos="0.0022 0 0.00400001" quat="0.707107 -0.00026748 -0.00026748 0.707107">
        <inertial pos="1.84966e-06 0.0037023 0.0193362" quat="0.70703 0.0104245 0.0104245 0.70703" mass="0.033" diaginertia="6.34e-06 6.31472e-06 8.85281e-07" />
        <joint name="right_finger5_joint2" pos="0 0 0" axis="0 1 0" range="-0.37 0.37" actuatorfrcrange="-0.1798 0.1798" />
        <geom type="mesh" contype="0" conaffinity="0" group="1" density="0" rgba="0.9 0.8 0.6 1" mesh="right_finger5_link2" />
        <geom type="mesh" rgba="0.9 0.8 0.6 1" mesh="right_finger5_link2" contype="2" conaffinity="2" />
        <body name="right_finger5_link3" pos="0 0.004717 0.0436213" quat="0.707012 0.000267516 0.000267444 -0.707202">
          <inertial pos="0.000328501 5.05492e-06 0.0142853" quat="0.999892 0 -0.0146884 0" mass="0.0165" diaginertia="1.47088e-06 1.44e-06 4.49118e-07" />
          <joint name="right_finger5_joint3" pos="0 0 0" axis="0 1 0" range="-0.4768 1.549" actuatorfrcrange="-0.2384 0.2384" />
          <geom type="mesh" contype="0" conaffinity="0" group="1" density="0" rgba="0.6 0.8 0.9 1" mesh="right_finger5_link3" />
          <geom type="mesh" rgba="0.6 0.8 0.9 1" mesh="right_finger5_link3" contype="1" conaffinity="1" />
          <body name="right_finger5_link4" pos="0 0 0.0295">
            <inertial pos="-0.000754828 -0.000172322 0.0122784" quat="0.995656 -0.00756106 -0.0927979 -0.00118593" mass="0.01718" diaginertia="1.1781e-06 1.07193e-06 4.07074e-07" />
            <joint name="right_finger5_joint4" pos="0 0 0" axis="0 1 0" range="-0.4683 1.5735" actuatorfrcrange="-0.1866 0.1866" />
            <geom type="mesh" contype="0" conaffinity="0" group="1" density="0" rgba="0.6 0.8 0.9 1" mesh="right_finger5_link4" />
            <geom type="mesh" rgba="0.6 0.8 0.9 1" mesh="right_finger5_link4" contype="1" conaffinity="1" />
            <geom pos="-0.000828016 0 0.0259994" quat="1 0 0 0" type="mesh" contype="0" conaffinity="0" group="1" density="0" rgba="0.6 0.8 0.9 1" mesh="right_finger5_tip_link" />
            <geom pos="-0.000828016 0 0.0259994" quat="1 0 0 0" type="mesh" rgba="0.6 0.8 0.9 1" mesh="right_finger5_tip_link" contype="1" conaffinity="1" />
          </body>
        </body>
      </body>
    </body>
  </body></worldbody>
  <actuator>
    <position name="right_finger1_joint1_actuator" joint="right_finger1_joint1" kp="0.40844710645048043" kv="0.020882010257063675" ctrlrange="0.0475 1.6033" forcerange="-0.4452 0.4452" />
    <position name="right_finger1_joint2_actuator" joint="right_finger1_joint2" kp="0.6858601063643346" kv="0.030610939996373314" ctrlrange="-0.1387 0.9324" forcerange="-0.4259 0.4259" />
    <position name="right_finger1_joint3_actuator" joint="right_finger1_joint3" kp="0.2391112196099482" kv="0.010181475050560962" ctrlrange="-0.4642 1.5623" forcerange="-0.1888 0.1888" />
    <position name="right_finger1_joint4_actuator" joint="right_finger1_joint4" kp="0.20736128319711747" kv="0.00909698844675045" ctrlrange="-0.4699 1.5568" forcerange="-0.1468 0.1468" />
    <position name="right_finger2_joint1_actuator" joint="right_finger2_joint1" kp="0.37352218155860073" kv="0.01882274330029718" ctrlrange="-0.1585 1.5604" forcerange="-0.6188 0.6188" />
    <position name="right_finger2_joint2_actuator" joint="right_finger2_joint2" kp="0.45592448909027794" kv="0.019798167597016643" ctrlrange="-0.37 0.37" forcerange="-0.1822 0.1822" />
    <position name="right_finger2_joint3_actuator" joint="right_finger2_joint3" kp="0.24368366649522863" kv="0.010477031953162727" ctrlrange="-0.4777 1.5485" forcerange="-0.2251 0.2251" />
    <position name="right_finger2_joint4_actuator" joint="right_finger2_joint4" kp="0.18026971340925335" kv="0.008240212147903584" ctrlrange="-0.4683 1.5753" forcerange="-0.217 0.217" />
    <position name="right_finger3_joint1_actuator" joint="right_finger3_joint1" kp="0.3687093483646485" kv="0.01848622487024593" ctrlrange="-0.1644 1.5516" forcerange="-0.6494 0.6494" />
    <position name="right_finger3_joint2_actuator" joint="right_finger3_joint2" kp="0.4164253443634641" kv="0.018032947229953678" ctrlrange="-0.37 0.37" forcerange="-0.1827 0.1827" />
    <position name="right_finger3_joint3_actuator" joint="right_finger3_joint3" kp="0.22218607502059182" kv="0.009592200014076666" ctrlrange="-0.4739 1.5512" forcerange="-0.2078 0.2078" />
    <position name="right_finger3_joint4_actuator" joint="right_finger3_joint4" kp="0.19427606072023446" kv="0.009152994605972402" ctrlrange="-0.4684 1.5745" forcerange="-0.2018 0.2018" />
    <position name="right_finger4_joint1_actuator" joint="right_finger4_joint1" kp="0.35718151495111794" kv="0.018376606800780005" ctrlrange="-0.1554 1.5585" forcerange="-0.6389 0.6389" />
    <position name="right_finger4_joint2_actuator" joint="right_finger4_joint2" kp="0.42977315313086895" kv="0.01867700966212433" ctrlrange="-0.37 0.37" forcerange="-0.1832 0.1832" />
    <position name="right_finger4_joint3_actuator" joint="right_finger4_joint3" kp="0.24930151196247122" kv="0.01059512121009555" ctrlrange="-0.4765 1.5487" forcerange="-0.2249 0.2249" />
    <position name="right_finger4_joint4_actuator" joint="right_finger4_joint4" kp="0.2285032688178066" kv="0.009917602877441107" ctrlrange="-0.4777 1.5634" forcerange="-0.2044 0.2044" />
    <position name="right_finger5_joint1_actuator" joint="right_finger5_joint1" kp="0.3655325975433942" kv="0.018616960278988272" ctrlrange="-0.1626 1.5585" forcerange="-0.6441 0.6441" />
    <position name="right_finger5_joint2_actuator" joint="right_finger5_joint2" kp="0.41393113081120425" kv="0.018732177029667153" ctrlrange="-0.37 0.37" forcerange="-0.1798 0.1798" />
    <position name="right_finger5_joint3_actuator" joint="right_finger5_joint3" kp="0.22729367621965954" kv="0.00951005441616486" ctrlrange="-0.4768 1.549" forcerange="-0.2384 0.2384" />
    <position name="right_finger5_joint4_actuator" joint="right_finger5_joint4" kp="0.1964723550341816" kv="0.009017295241756363" ctrlrange="-0.4683 1.5735" forcerange="-0.1866 0.1866" />
  </actuator>
</mujoco>